Workbook

Sheet Data
B1: Cell proportions (a2/a4) | D1: 99.8/0.2
B2: Treatment | D2: No treatment | AH2: MTD | BL2: Red Calibration MTD | CA2: Red Calibration No treatment | CP2: AT 100 | EN2: AT 80 | GL2: AT 50
B3: Well | D3: A7 | I3: B7 | N3: C7 | S3: D7 | X3: E7 | AC3: F7 | AH3: F1 | AM3: F2 | AR3: F3 | AW3: F4 | BB3: F5 | BG3: F6 | BL3: A8 | BQ3: B8 | BV3: C8 | CA3: D8 | CF3: E8 | CK3: F8 | CP3: A1 | CU3: B1 | CZ3: C1 | DE3: D1 | DJ3: E1 | DO3: A2 | DT3: B2 | DY3: C2 | ED3: D2 | EI3: E2 | EN3: A3 | ES3: B3 | EX3: C3 | FC3: D3 | FH3: E3 | FM3: A4 | FR3: B4 | FW3: C4 | GB3: D4 | GG3: E4 | GL3: A5 | GQ3: B5 | GV3: C5 | HA3: D5 | HF3: E5 | HK3: A6 | HP3: B6 | HU3: C6 | HZ3: D6 | IE3: E6
A4: d | B4: colour | D4: g | E4: r | F4: r' | G4: t | I4: g | J4: r | K4: r' | L4: t | N4: g | O4: r | P4: r' | Q4: t | S4: g | T4: r | U4: r' | V4: t | X4: g | Y4: r | Z4: r' | AA4: t | AC4: g | AD4: r | AE4: r' | AF4: t | AH4: g | AI4: r | AJ4: r' | AK4: t | AM4: g | AN4: r | AO4: r' | AP4: t | AR4: g | AS4: r | AT4: r' | AU4: t | AW4: g | AX4: r | AY4: r' | AZ4: t | BB4: g | BC4: r | BD4: r' | BE4: t | BG4: g | BH4: r | BI4: r' | BJ4: t | BL4: g | BM4: r | BN4: r' | BO4: t | BQ4: g | BR4: r | BS4: r' | BT4: t | BV4: g | BW4: r | BX4: r' | BY4: t | CA4: g | CB4: r | CC4: r' | CD4: t | CF4: g | CG4: r | CH4: r' | CI4: t | CK4: g | CL4: r | CM4: r' | CN4: t | CP4: g | CQ4: r | CR4: r' | CS4: t | CU4: g | CV4: r | CW4: r' | CX4: t | CZ4: g | DA4: r | DB4: r' | DC4: t | DE4: g | DF4: r | DG4: r' | DH4: t | DJ4: g | DK4: r | DL4: r' | DM4: t | DO4: g | DP4: r | DQ4: r' | DR4: t | DT4: g | DU4: r | DV4: r' | DW4: t | DY4: g | DZ4: r | EA4: r' | EB4: t | ED4: g | EE4: r | EF4: r' | EG4: t | EI4: g | EJ4: r | EK4: r' | EL4: t | EN4: g | EO4: r | EP4: r' | EQ4: t | ES4: g | ET4: r | EU4: r' | EV4: t | EX4: g | EY4: r | EZ4: r' | FA4: t | FC4: g | FD4: r | FE4: r' | FF4: t | FH4: g | FI4: r | FJ4: r' | FK4: t | FM4: g | FN4: r | FO4: r' | FP4: t | FR4: g | FS4: r | FT4: r' | FU4: t | FW4: g | FX4: r | FY4: r' | FZ4: t | GB4: g | GC4: r | GD4: r' | GE4: t | GG4: g | GH4: r | GI4: r' | GJ4: t | GL4: g | GM4: r | GN4: r' | GO4: t | GQ4: g | GR4: r | GS4: r' | GT4: t | GV4: g | GW4: r | GX4: r' | GY4: t | HA4: g | HB4: r | HC4: r' | HD4: t | HF4: g | HG4: r | HH4: r' | HI4: t | HK4: g | HL4: r | HM4: r' | HN4: t | HP4: g | HQ4: r | HR4: r' | HS4: t | HU4: g | HV4: r | HW4: r' | HX4: t | HZ4: g | IA4: r | IB4: r' | IC4: t | IE4: g | IF4: r | IG4: r' | IH4: t
A5: 1 | B5: 45492 | C5: Friday | D5: 1159300039 | E5: 8141338 | F5: =INDIRECT("ZS(-1)",0) * 'Correction factor'!$C$13 -> 11290920 | G5: =INDIRECT("ZS(-1)",0) + INDIRECT("ZS(-3)",0) -> 1.170591e+09 | H5: =INDIRECT("ZS(-1)",0) / INDIRECT("Z6S(-1)",0) -> 0.84662681 | I5: 1309688332 | J5: 9235404 | K5: =INDIRECT("ZS(-1)",0) * 'Correction factor'!$C$13 -> 12808240 | L5: =INDIRECT("ZS(-1)",0) + INDIRECT("ZS(-3)",0) -> 1.3224966e+09 | M5: =INDIRECT("ZS(-1)",0) / INDIRECT("Z6S(-1)",0) -> 0.86690106 | N5: 1056157805 | O5: 7237061 | P5: =INDIRECT("ZS(-1)",0) * 'Correction factor'!$C$13 -> 10036812 | Q5: =INDIRECT("ZS(-1)",0) + INDIRECT("ZS(-3)",0) -> 1.0661946e+09 | R5: =INDIRECT("ZS(-1)",0) / INDIRECT("Z6S(-1)",0) -> 0.83003625 | S5: 1237492985 | T5: 6991024 | U5: =INDIRECT("ZS(-1)",0) * 'Correction factor'!$C$13 -> 9695592.3 | V5: =INDIRECT("ZS(-1)",0) + INDIRECT("ZS(-3)",0) -> 1.2471886e+09 | W5: =INDIRECT("ZS(-1)",0) / INDIRECT("Z6S(-1)",0) -> 0.85139397 | X5: 1177989337 | Y5: 7897495 | Z5: =INDIRECT("ZS(-1)",0) * 'Correction factor'!$C$13 -> 10952743 | AA5: =INDIRECT("ZS(-1)",0) + INDIRECT("ZS(-3)",0) -> 1.1889421e+09 | AB5: =INDIRECT("ZS(-1)",0) / INDIRECT("Z6S(-1)",0) -> 0.82920309 | AC5: 1101287616 | AD5: 10198352 | AE5: =INDIRECT("ZS(-1)",0) * 'Correction factor'!$C$13 -> 14143717 | AF5: =INDIRECT("ZS(-1)",0) + INDIRECT("ZS(-3)",0) -> 1.1154313e+09 | AG5: =INDIRECT("ZS(-1)",0) / INDIRECT("Z6S(-1)",0) -> 0.7195805 | AH5: 1302457871 | AI5: 8575971 | AJ5: =INDIRECT("ZS(-1)",0) * 'Correction factor'!$C$13 -> 11893697 | AK5: =INDIRECT("ZS(-1)",0) + INDIRECT("ZS(-3)",0) -> 1.3143516e+09 | AL5: =INDIRECT("ZS(-1)",0) / INDIRECT("Z6S(-1)",0) -> 0.74594188 | AM5: 1216740256 | AN5: 13156257 | AO5: =INDIRECT("ZS(-1)",0) * 'Correction factor'!$C$13 -> 18245926 | AP5: =INDIRECT("ZS(-1)",0) + INDIRECT("ZS(-3)",0) -> 1.2349862e+09 | AQ5: =INDIRECT("ZS(-1)",0) / INDIRECT("Z6S(-1)",0) -> 0.80201652 | AR5: 1106458840 | AS5: 7324191 | AT5: =INDIRECT("ZS(-1)",0) * 'Correction factor'!$C$13 -> 10157649 | AU5: =INDIRECT("ZS(-1)",0) + INDIRECT("ZS(-3)",0) -> 1.1166165e+09 | AV5: =INDIRECT("ZS(-1)",0) / INDIRECT("Z6S(-1)",0) -> 0.79908029 | AW5: 1172890722 | AX5: 10747573 | AY5: =INDIRECT("ZS(-1)",0) * 'Correction factor'!$C$13 -> 14905411 | AZ5: =INDIRECT("ZS(-1)",0) + INDIRECT("ZS(-3)",0) -> 1.1877961e+09 | BA5: =INDIRECT("ZS(-1)",0) / INDIRECT("Z6S(-1)",0) -> 0.816066 | BB5: 1176451019 | BC5: 7932972 | BD5: =INDIRECT("ZS(-1)",0) * 'Correction factor'!$C$13 -> 11001945 | BE5: =INDIRECT("ZS(-1)",0) + INDIRECT("ZS(-3)",0) -> 1.187453e+09 | BF5: =INDIRECT("ZS(-1)",0) / INDIRECT("Z6S(-1)",0) -> 0.80600447 | BG5: 1274891314 | BH5: 8683776 | BI5: =INDIRECT("ZS(-1)",0) * 'Correction factor'!$C$13 -> 12043207 | BJ5: =INDIRECT("ZS(-1)",0) + INDIRECT("ZS(-3)",0) -> 1.2869345e+09 | BK5: =INDIRECT("ZS(-1)",0) / INDIRECT("Z6S(-1)",0) -> 0.78386859 | BL5: 24898417 | BM5: 99696349 | BN5: =INDIRECT("ZS(-1)",0) * 'Correction factor'!$C$13 -> 1.3826517e+08 | BO5: =INDIRECT("ZS(-1)",0) + INDIRECT("ZS(-3)",0) -> 1.6316359e+08 | BP5: =INDIRECT("ZS(-1)",0) / INDIRECT("Z6S(-1)",0) -> 0.78253736 | BQ5: 14730104 | BR5: 90891739 | BS5: =INDIRECT("ZS(-1)",0) * 'Correction factor'!$C$13 -> 1.2605439e+08 | BT5: =INDIRECT("ZS(-1)",0) + INDIRECT("ZS(-3)",0) -> 1.4078449e+08 | BU5: =INDIRECT("ZS(-1)",0) / INDIRECT("Z6S(-1)",0) -> 0.82652597 | BV5: 16438772 | BW5: 84685348 | BX5: =INDIRECT("ZS(-1)",0) * 'Correction factor'!$C$13 -> 1.1744697e+08 | BY5: =INDIRECT("ZS(-1)",0) + INDIRECT("ZS(-3)",0) -> 1.3388574e+08 | BZ5: =INDIRECT("ZS(-1)",0) / INDIRECT("Z6S(-1)",0) -> 0.85211897 | CA5: 11942616 | CB5: 98347705 | CC5: =INDIRECT("ZS(-1)",0) * 'Correction factor'!$C$13 -> 1.3639479e+08 | CD5: =INDIRECT("ZS(-1)",0) + INDIRECT("ZS(-3)",0) -> 1.4833741e+08 | CE5: =INDIRECT("ZS(-1)",0) / INDIRECT("Z6S(-1)",0) -> 0.83962701 | CF5: 19521800 | CG5: 70507177 | CH5: =INDIRECT("ZS(-1)",0) * 'Correction factor'!$C$13 -> 97783793 | CI5: =INDIRECT("ZS(-1)",0) + INDIRECT("ZS(-3)",0) -> 1.1730559e+08 | CJ5: =INDIRECT("ZS(-1)",0) / INDIRECT("Z6S(-1)",0) -> 0.85216093 | CK5: 12300134 | CL5: 74334687 | CM5: =INDIRECT("ZS(-1)",0) * 'Correction factor'!$C$13 -> 1.0309202e+08 | CN5: =INDIRECT("ZS(-1)",0) + INDIRECT("ZS(-3)",0) -> 1.1539216e+08 | CO5: =INDIRECT("ZS(-1)",0) / INDIRECT("Z6S(-1)",0) -> 0.82425207 | CP5: 1213655883 | CQ5: 7404181 | CR5: =INDIRECT("ZS(-1)",0) * 'Correction factor'!$C$13 -> 10268584 | CS5: =INDIRECT("ZS(-1)",0) + INDIRECT("ZS(-3)",0) -> 1.2239245e+09 | CT5: =INDIRECT("ZS(-1)",0) / INDIRECT("Z6S(-1)",0) -> 0.83377385 | CU5: 1043841178 | CV5: 7583144 | CW5: =INDIRECT("ZS(-1)",0) * 'Correction factor'!$C$13 -> 10516782 | CX5: =INDIRECT("ZS(-1)",0) + INDIRECT("ZS(-3)",0) -> 1.054358e+09 | CY5: =INDIRECT("ZS(-1)",0) / INDIRECT("Z6S(-1)",0) -> 0.80670717 | CZ5: 1234053743 | DA5: 8244930 | DB5: =INDIRECT("ZS(-1)",0) * 'Correction factor'!$C$13 -> 11434588 | DC5: =INDIRECT("ZS(-1)",0) + INDIRECT("ZS(-3)",0) -> 1.2454883e+09 | DD5: =INDIRECT("ZS(-1)",0) / INDIRECT("Z6S(-1)",0) -> 0.81749255 | DE5: 1090332111 | DF5: 11132442 | DG5: =INDIRECT("ZS(-1)",0) * 'Correction factor'!$C$13 -> 15439172 | DH5: =INDIRECT("ZS(-1)",0) + INDIRECT("ZS(-3)",0) -> 1.1057713e+09 | DI5: =INDIRECT("ZS(-1)",0) / INDIRECT("Z6S(-1)",0) -> 0.80515364 | DJ5: 950964939 | DK5: 8623505 | DL5: =INDIRECT("ZS(-1)",0) * 'Correction factor'!$C$13 -> 11959620 | DM5: =INDIRECT("ZS(-1)",0) + INDIRECT("ZS(-3)",0) -> 9.6292456e+08 | DN5: =INDIRECT("ZS(-1)",0) / INDIRECT("Z6S(-1)",0) -> 0.7936812 | DO5: 1114730374 | DP5: 9059902 | DQ5: =INDIRECT("ZS(-1)",0) * 'Correction factor'!$C$13 -> 12564843 | DR5: =INDIRECT("ZS(-1)",0) + INDIRECT("ZS(-3)",0) -> 1.1272952e+09 | DS5: =INDIRECT("ZS(-1)",0) / INDIRECT("Z6S(-1)",0) -> 0.84930333 | DT5: 1122586898 | DU5: 10270853 | DV5: =INDIRECT("ZS(-1)",0) * 'Correction factor'!$C$13 -> 14244266 | DW5: =INDIRECT("ZS(-1)",0) + INDIRECT("ZS(-3)",0) -> 1.1368312e+09 | DX5: =INDIRECT("ZS(-1)",0) / INDIRECT("Z6S(-1)",0) -> 0.83713379 | DY5: 1175857738 | DZ5: 10432623 | EA5: =INDIRECT("ZS(-1)",0) * 'Correction factor'!$C$13 -> 14468618 | EB5: =INDIRECT("ZS(-1)",0) + INDIRECT("ZS(-3)",0) -> 1.1903264e+09 | EC5: =INDIRECT("ZS(-1)",0) / INDIRECT("Z6S(-1)",0) -> 0.84179896 | ED5: 1098101432 | EE5: 11588447 | EF5: =INDIRECT("ZS(-1)",0) * 'Correction factor'!$C$13 -> 16071588 | EG5: =INDIRECT("ZS(-1)",0) + INDIRECT("ZS(-3)",0) -> 1.114173e+09 | EH5: =INDIRECT("ZS(-1)",0) / INDIRECT("Z6S(-1)",0) -> 0.85180351 | EI5: 1080733154 | EJ5: 12223988 | EK5: =INDIRECT("ZS(-1)",0) * 'Correction factor'!$C$13 -> 16952996 | EL5: =INDIRECT("ZS(-1)",0) + INDIRECT("ZS(-3)",0) -> 1.0976862e+09 | EM5: =INDIRECT("ZS(-1)",0) / INDIRECT("Z6S(-1)",0) -> 0.83408076 | EN5: 1208781725 | EO5: 9348307 | EP5: =INDIRECT("ZS(-1)",0) * 'Correction factor'!$C$13 -> 12964821 | EQ5: =INDIRECT("ZS(-1)",0) + INDIRECT("ZS(-3)",0) -> 1.2217465e+09 | ER5: =INDIRECT("ZS(-1)",0) / INDIRECT("Z6S(-1)",0) -> 0.83068616 | ES5: 1221034822 | ET5: 7891486 | EU5: =INDIRECT("ZS(-1)",0) * 'Correction factor'!$C$13 -> 10944410 | EV5: =INDIRECT("ZS(-1)",0) + INDIRECT("ZS(-3)",0) -> 1.2319792e+09 | EW5: =INDIRECT("ZS(-1)",0) / INDIRECT("Z6S(-1)",0) -> 0.8421349 | EX5: 1140959184 | EY5: 7987613 | EZ5: =INDIRECT("ZS(-1)",0) * 'Correction factor'!$C$13 -> 11077725 | FA5: =INDIRECT("ZS(-1)",0) + INDIRECT("ZS(-3)",0) -> 1.1520369e+09 | FB5: =INDIRECT("ZS(-1)",0) / INDIRECT("Z6S(-1)",0) -> 0.82136745 | FC5: 1093988652 | FD5: 9985159 | FE5: =INDIRECT("ZS(-1)",0) * 'Correction factor'!$C$13 -> 13848047 | FF5: =INDIRECT("ZS(-1)",0) + INDIRECT("ZS(-3)",0) -> 1.1078367e+09 | FG5: =INDIRECT("ZS(-1)",0) / INDIRECT("Z6S(-1)",0) -> 0.854967 | FH5: 1485331872 | FI5: 11084726 | FJ5: =INDIRECT("ZS(-1)",0) * 'Correction factor'!$C$13 -> 15372996 | FK5: =INDIRECT("ZS(-1)",0) + INDIRECT("ZS(-3)",0) -> 1.5007049e+09 | FL5: =INDIRECT("ZS(-1)",0) / INDIRECT("Z6S(-1)",0) -> 0.84542063 | FM5: 1121039696 | FN5: 8031275 | FO5: =INDIRECT("ZS(-1)",0) * 'Correction factor'!$C$13 -> 11138278 | FP5: =INDIRECT("ZS(-1)",0) + INDIRECT("ZS(-3)",0) -> 1.132178e+09 | FQ5: =INDIRECT("ZS(-1)",0) / INDIRECT("Z6S(-1)",0) -> 0.80012339 | FR5: 1200588868 | FS5: 8039373 | FT5: =INDIRECT("ZS(-1)",0) * 'Correction factor'!$C$13 -> 11149509 | FU5: =INDIRECT("ZS(-1)",0) + INDIRECT("ZS(-3)",0) -> 1.2117384e+09 | FV5: =INDIRECT("ZS(-1)",0) / INDIRECT("Z6S(-1)",0) -> 0.84531433 | FW5: 1039372058 | FX5: 11087867 | FY5: =INDIRECT("ZS(-1)",0) * 'Correction factor'!$C$13 -> 15377352 | FZ5: =INDIRECT("ZS(-1)",0) + INDIRECT("ZS(-3)",0) -> 1.0547494e+09 | GA5: =INDIRECT("ZS(-1)",0) / INDIRECT("Z6S(-1)",0) -> 0.84643553 | GB5: 1173907040 | GC5: 7926037 | GD5: =INDIRECT("ZS(-1)",0) * 'Correction factor'!$C$13 -> 10992327 | GE5: =INDIRECT("ZS(-1)",0) + INDIRECT("ZS(-3)",0) -> 1.1848994e+09 | GF5: =INDIRECT("ZS(-1)",0) / INDIRECT("Z6S(-1)",0) -> 0.82628397 | GG5: 1165681755 | GH5: 9851387 | GI5: =INDIRECT("ZS(-1)",0) * 'Correction factor'!$C$13 -> 13662524 | GJ5: =INDIRECT("ZS(-1)",0) + INDIRECT("ZS(-3)",0) -> 1.1793443e+09 | GK5: =INDIRECT("ZS(-1)",0) / INDIRECT("Z6S(-1)",0) -> 0.82235169 | GL5: 1194933820 | GM5: 8446852 | GN5: =INDIRECT("ZS(-1)",0) * 'Correction factor'!$C$13 -> 11714626 | GO5: =INDIRECT("ZS(-1)",0) + INDIRECT("ZS(-3)",0) -> 1.2066484e+09 | GP5: =INDIRECT("ZS(-1)",0) / INDIRECT("Z6S(-1)",0) -> 0.83240874 | GQ5: 849348495 | GR5: 7993136 | GS5: =INDIRECT("ZS(-1)",0) * 'Correction factor'!$C$13 -> 11085384 | GT5: =INDIRECT("ZS(-1)",0) + INDIRECT("ZS(-3)",0) -> 8.6043388e+08 | GU5: =INDIRECT("ZS(-1)",0) / INDIRECT("Z6S(-1)",0) -> 0.89217015 | GV5: 1125288715 | GW5: 9778502 | GX5: =INDIRECT("ZS(-1)",0) * 'Correction factor'!$C$13 -> 13561442 | GY5: =INDIRECT("ZS(-1)",0) + INDIRECT("ZS(-3)",0) -> 1.1388502e+09 | GZ5: =INDIRECT("ZS(-1)",0) / INDIRECT("Z6S(-1)",0) -> 0.80847704 | HA5: 1117686011 | HB5: 8690479 | HC5: =INDIRECT("ZS(-1)",0) * 'Correction factor'!$C$13 -> 12052503 | HD5: =INDIRECT("ZS(-1)",0) + INDIRECT("ZS(-3)",0) -> 1.1297385e+09 | HE5: =INDIRECT("ZS(-1)",0) / INDIRECT("Z6S(-1)",0) -> 0.82739395 | HF5: 1104006144 | HG5: 10593841 | HH5: =INDIRECT("ZS(-1)",0) * 'Correction factor'!$C$13 -> 14692206 | HI5: =INDIRECT("ZS(-1)",0) + INDIRECT("ZS(-3)",0) -> 1.1186983e+09 | HJ5: =INDIRECT("ZS(-1)",0) / INDIRECT("Z6S(-1)",0) -> 0.82406669 | HK5: 1084579963 | HL5: 12404759 | HM5: =INDIRECT("ZS(-1)",0) * 'Correction factor'!$C$13 -> 17203701 | HN5: =INDIRECT("ZS(-1)",0) + INDIRECT("ZS(-3)",0) -> 1.1017837e+09 | HO5: =INDIRECT("ZS(-1)",0) / INDIRECT("Z6S(-1)",0) -> 0.82021656 | HP5: 1273183380 | HQ5: 8519612 | HR5: =INDIRECT("ZS(-1)",0) * 'Correction factor'!$C$13 -> 11815534 | HS5: =INDIRECT("ZS(-1)",0) + INDIRECT("ZS(-3)",0) -> 1.2849989e+09 | HT5: =INDIRECT("ZS(-1)",0) / INDIRECT("Z6S(-1)",0) -> 0.83305511 | HU5: 1077042576 | HV5: 9025382 | HW5: =INDIRECT("ZS(-1)",0) * 'Correction factor'!$C$13 -> 12516968 | HX5: =INDIRECT("ZS(-1)",0) + INDIRECT("ZS(-3)",0) -> 1.0895595e+09 | HY5: =INDIRECT("ZS(-1)",0) / INDIRECT("Z6S(-1)",0) -> 0.85498092 | HZ5: 1077400263 | IA5: 10317927 | IB5: =INDIRECT("ZS(-1)",0) * 'Correction factor'!$C$13 -> 14309551 | IC5: =INDIRECT("ZS(-1)",0) + INDIRECT("ZS(-3)",0) -> 1.0917098e+09 | ID5: =INDIRECT("ZS(-1)",0) / INDIRECT("Z6S(-1)",0) -> 0.84654762 | IE5: 1068812969 | IF5: 8046869 | IG5: =INDIRECT("ZS(-1)",0) * 'Correction factor'!$C$13 -> 11159905 | IH5: =INDIRECT("ZS(-1)",0) + INDIRECT("ZS(-3)",0) -> 1.0799729e+09 | II5: =INDIRECT("ZS(-1)",0) / INDIRECT("Z6S(-1)",0) -> 0.82640785
A6: 2 | B6: 45493 | C6: Saturday | D6: 1370130511 | E6: 9029242 | F6: =INDIRECT("ZS(-1)",0) * 'Correction factor'!$C$13 -> 12522321 | G6: =INDIRECT("ZS(-1)",0) + INDIRECT("ZS(-3)",0) -> 1.3826528e+09 | H6: =INDIRECT("ZS(-1)",0) / INDIRECT("Z6S(-1)",0) -> 1 | I6: 1511095115 | J6: 10419106 | K6: =INDIRECT("ZS(-1)",0) * 'Correction factor'!$C$13 -> 14449872 | L6: =INDIRECT("ZS(-1)",0) + INDIRECT("ZS(-3)",0) -> 1.525545e+09 | M6: =INDIRECT("ZS(-1)",0) / INDIRECT("Z6S(-1)",0) -> 1 | N6: 1273473078 | O6: 7962316 | P6: =INDIRECT("ZS(-1)",0) * 'Correction factor'!$C$13 -> 11042641 | Q6: =INDIRECT("ZS(-1)",0) + INDIRECT("ZS(-3)",0) -> 1.2845157e+09 | R6: =INDIRECT("ZS(-1)",0) / INDIRECT("Z6S(-1)",0) -> 1 | S6: 1454164391 | T6: 7725300 | U6: =INDIRECT("ZS(-1)",0) * 'Correction factor'!$C$13 -> 10713932 | V6: =INDIRECT("ZS(-1)",0) + INDIRECT("ZS(-3)",0) -> 1.4648783e+09 | W6: =INDIRECT("ZS(-1)",0) / INDIRECT("Z6S(-1)",0) -> 1 | X6: 1421096596 | Y6: 9186500 | Z6: =INDIRECT("ZS(-1)",0) * 'Correction factor'!$C$13 -> 12740417 | AA6: =INDIRECT("ZS(-1)",0) + INDIRECT("ZS(-3)",0) -> 1.433837e+09 | AB6: =INDIRECT("ZS(-1)",0) / INDIRECT("Z6S(-1)",0) -> 1 | AC6: 1534180564 | AD6: 11488353 | AE6: =INDIRECT("ZS(-1)",0) * 'Correction factor'!$C$13 -> 15932771 | AF6: =INDIRECT("ZS(-1)",0) + INDIRECT("ZS(-3)",0) -> 1.5501133e+09 | AG6: =INDIRECT("ZS(-1)",0) / INDIRECT("Z6S(-1)",0) -> 1 | AH6: 1748890653 | AI6: 9454426 | AJ6: =INDIRECT("ZS(-1)",0) * 'Correction factor'!$C$13 -> 13111993 | AK6: =INDIRECT("ZS(-1)",0) + INDIRECT("ZS(-3)",0) -> 1.7620026e+09 | AL6: =INDIRECT("ZS(-1)",0) / INDIRECT("Z6S(-1)",0) -> 1 | AM6: 1517532969 | AN6: 16092676 | AO6: =INDIRECT("ZS(-1)",0) * 'Correction factor'!$C$13 -> 22318336 | AP6: =INDIRECT("ZS(-1)",0) + INDIRECT("ZS(-3)",0) -> 1.5398513e+09 | AQ6: =INDIRECT("ZS(-1)",0) / INDIRECT("Z6S(-1)",0) -> 1 | AR6: 1386101074 | AS6: 8130588 | AT6: =INDIRECT("ZS(-1)",0) * 'Correction factor'!$C$13 -> 11276011 | AU6: =INDIRECT("ZS(-1)",0) + INDIRECT("ZS(-3)",0) -> 1.3973771e+09 | AV6: =INDIRECT("ZS(-1)",0) / INDIRECT("Z6S(-1)",0) -> 1 | AW6: 1440584019 | AX6: 10765863 | AY6: =INDIRECT("ZS(-1)",0) * 'Correction factor'!$C$13 -> 14930777 | AZ6: =INDIRECT("ZS(-1)",0) + INDIRECT("ZS(-3)",0) -> 1.4555148e+09 | BA6: =INDIRECT("ZS(-1)",0) / INDIRECT("Z6S(-1)",0) -> 1 | BB6: 1460631536 | BC6: 9104719 | BD6: =INDIRECT("ZS(-1)",0) * 'Correction factor'!$C$13 -> 12626998 | BE6: =INDIRECT("ZS(-1)",0) + INDIRECT("ZS(-3)",0) -> 1.4732585e+09 | BF6: =INDIRECT("ZS(-1)",0) / INDIRECT("Z6S(-1)",0) -> 1 | BG6: 1628994271 | BH6: 9214345 | BI6: =INDIRECT("ZS(-1)",0) * 'Correction factor'!$C$13 -> 12779034 | BJ6: =INDIRECT("ZS(-1)",0) + INDIRECT("ZS(-3)",0) -> 1.6417733e+09 | BK6: =INDIRECT("ZS(-1)",0) / INDIRECT("Z6S(-1)",0) -> 1 | BL6: 30078311 | BM6: 128655469 | BN6: =INDIRECT("ZS(-1)",0) * 'Correction factor'!$C$13 -> 1.7842751e+08 | BO6: =INDIRECT("ZS(-1)",0) + INDIRECT("ZS(-3)",0) -> 2.0850582e+08 | BP6: =INDIRECT("ZS(-1)",0) / INDIRECT("Z6S(-1)",0) -> 1 | BQ6: 11887396 | BR6: 114247346 | BS6: =INDIRECT("ZS(-1)",0) * 'Correction factor'!$C$13 -> 1.5844541e+08 | BT6: =INDIRECT("ZS(-1)",0) + INDIRECT("ZS(-3)",0) -> 1.7033281e+08 | BU6: =INDIRECT("ZS(-1)",0) / INDIRECT("Z6S(-1)",0) -> 1 | BV6: 10874827 | BW6: 105451029 | BX6: =INDIRECT("ZS(-1)",0) * 'Correction factor'!$C$13 -> 1.4624613e+08 | BY6: =INDIRECT("ZS(-1)",0) + INDIRECT("ZS(-3)",0) -> 1.5712095e+08 | BZ6: =INDIRECT("ZS(-1)",0) / INDIRECT("Z6S(-1)",0) -> 1 | CA6: 8706137 | CB6: 121111073 | CC6: =INDIRECT("ZS(-1)",0) * 'Correction factor'!$C$13 -> 1.6796446e+08 | CD6: =INDIRECT("ZS(-1)",0) + INDIRECT("ZS(-3)",0) -> 1.766706e+08 | CE6: =INDIRECT("ZS(-1)",0) / INDIRECT("Z6S(-1)",0) -> 1 | CF6: 22193066 | CG6: 83255200 | CH6: =INDIRECT("ZS(-1)",0) * 'Correction factor'!$C$13 -> 1.1546355e+08 | CI6: =INDIRECT("ZS(-1)",0) + INDIRECT("ZS(-3)",0) -> 1.3765662e+08 | CJ6: =INDIRECT("ZS(-1)",0) / INDIRECT("Z6S(-1)",0) -> 1 | CK6: 11827025 | CL6: 92416612 | CM6: =INDIRECT("ZS(-1)",0) * 'Correction factor'!$C$13 -> 1.2816918e+08 | CN6: =INDIRECT("ZS(-1)",0) + INDIRECT("ZS(-3)",0) -> 1.399962e+08 | CO6: =INDIRECT("ZS(-1)",0) / INDIRECT("Z6S(-1)",0) -> 1 | CP6: 1455957100 | CQ6: 8635523 | CR6: =INDIRECT("ZS(-1)",0) * 'Correction factor'!$C$13 -> 11976287 | CS6: =INDIRECT("ZS(-1)",0) + INDIRECT("ZS(-3)",0) -> 1.4679334e+09 | CT6: =INDIRECT("ZS(-1)",0) / INDIRECT("Z6S(-1)",0) -> 1 | CU6: 1295332290 | CV6: 8405591 | CW6: =INDIRECT("ZS(-1)",0) * 'Correction factor'!$C$13 -> 11657403 | CX6: =INDIRECT("ZS(-1)",0) + INDIRECT("ZS(-3)",0) -> 1.3069897e+09 | CY6: =INDIRECT("ZS(-1)",0) / INDIRECT("Z6S(-1)",0) -> 1 | CZ6: 1509760852 | DA6: 9940537 | DB6: =INDIRECT("ZS(-1)",0) * 'Correction factor'!$C$13 -> 13786163 | DC6: =INDIRECT("ZS(-1)",0) + INDIRECT("ZS(-3)",0) -> 1.523547e+09 | DD6: =INDIRECT("ZS(-1)",0) / INDIRECT("Z6S(-1)",0) -> 1 | DE6: 1354658830 | DF6: 13489422 | DG6: =INDIRECT("ZS(-1)",0) * 'Correction factor'!$C$13 -> 18707980 | DH6: =INDIRECT("ZS(-1)",0) + INDIRECT("ZS(-3)",0) -> 1.3733668e+09 | DI6: =INDIRECT("ZS(-1)",0) / INDIRECT("Z6S(-1)",0) -> 1 | DJ6: 1199829144 | DK6: 9668815 | DL6: =INDIRECT("ZS(-1)",0) * 'Correction factor'!$C$13 -> 13409321 | DM6: =INDIRECT("ZS(-1)",0) + INDIRECT("ZS(-3)",0) -> 1.2132385e+09 | DN6: =INDIRECT("ZS(-1)",0) / INDIRECT("Z6S(-1)",0) -> 1 | DO6: 1313086635 | DP6: 10261228 | DQ6: =INDIRECT("ZS(-1)",0) * 'Correction factor'!$C$13 -> 14230917 | DR6: =INDIRECT("ZS(-1)",0) + INDIRECT("ZS(-3)",0) -> 1.3273176e+09 | DS6: =INDIRECT("ZS(-1)",0) / INDIRECT("Z6S(-1)",0) -> 1 | DT6: 1342166921 | DU6: 11419469 | DV6: =INDIRECT("ZS(-1)",0) * 'Correction factor'!$C$13 -> 15837239 | DW6: =INDIRECT("ZS(-1)",0) + INDIRECT("ZS(-3)",0) -> 1.3580042e+09 | DX6: =INDIRECT("ZS(-1)",0) / INDIRECT("Z6S(-1)",0) -> 1 | DY6: 1397219239 | DZ6: 12119176 | EA6: =INDIRECT("ZS(-1)",0) * 'Correction factor'!$C$13 -> 16807636 | EB6: =INDIRECT("ZS(-1)",0) + INDIRECT("ZS(-3)",0) -> 1.4140269e+09 | EC6: =INDIRECT("ZS(-1)",0) / INDIRECT("Z6S(-1)",0) -> 1 | ED6: 1289849590 | EE6: 13099260 | EF6: =INDIRECT("ZS(-1)",0) * 'Correction factor'!$C$13 -> 18166879 | EG6: =INDIRECT("ZS(-1)",0) + INDIRECT("ZS(-3)",0) -> 1.3080165e+09 | EH6: =INDIRECT("ZS(-1)",0) / INDIRECT("Z6S(-1)",0) -> 1 | EI6: 1296181403 | EJ6: 14321249 | EK6: =INDIRECT("ZS(-1)",0) * 'Correction factor'!$C$13 -> 19861610 | EL6: =INDIRECT("ZS(-1)",0) + INDIRECT("ZS(-3)",0) -> 1.316043e+09 | EM6: =INDIRECT("ZS(-1)",0) / INDIRECT("Z6S(-1)",0) -> 1 | EN6: 1456012695 | EO6: 10639278 | EP6: =INDIRECT("ZS(-1)",0) * 'Correction factor'!$C$13 -> 14755221 | EQ6: =INDIRECT("ZS(-1)",0) + INDIRECT("ZS(-3)",0) -> 1.4707679e+09 | ER6: =INDIRECT("ZS(-1)",0) / INDIRECT("Z6S(-1)",0) -> 1 | ES6: 1450735058 | ET6: 8788757 | EU6: =INDIRECT("ZS(-1)",0) * 'Correction factor'!$C$13 -> 12188802 | EV6: =INDIRECT("ZS(-1)",0) + INDIRECT("ZS(-3)",0) -> 1.4629239e+09 | EW6: =INDIRECT("ZS(-1)",0) / INDIRECT("Z6S(-1)",0) -> 1 | EX6: 1389595582 | EY6: 9365377 | EZ6: =INDIRECT("ZS(-1)",0) * 'Correction factor'!$C$13 -> 12988495 | FA6: =INDIRECT("ZS(-1)",0) + INDIRECT("ZS(-3)",0) -> 1.4025841e+09 | FB6: =INDIRECT("ZS(-1)",0) / INDIRECT("Z6S(-1)",0) -> 1 | FC6: 1280146353 | FD6: 11262173 | FE6: =INDIRECT("ZS(-1)",0) * 'Correction factor'!$C$13 -> 15619091 | FF6: =INDIRECT("ZS(-1)",0) + INDIRECT("ZS(-3)",0) -> 1.2957654e+09 | FG6: =INDIRECT("ZS(-1)",0) / INDIRECT("Z6S(-1)",0) -> 1 | FH6: 1757840844 | FI6: 12443642 | FJ6: =INDIRECT("ZS(-1)",0) * 'Correction factor'!$C$13 -> 17257626 | FK6: =INDIRECT("ZS(-1)",0) + INDIRECT("ZS(-3)",0) -> 1.7750985e+09 | FL6: =INDIRECT("ZS(-1)",0) / INDIRECT("Z6S(-1)",0) -> 1 | FM6: 1402755464 | FN6: 8831986 | FO6: =INDIRECT("ZS(-1)",0) * 'Correction factor'!$C$13 -> 12248754 | FP6: =INDIRECT("ZS(-1)",0) + INDIRECT("ZS(-3)",0) -> 1.4150042e+09 | FQ6: =INDIRECT("ZS(-1)",0) / INDIRECT("Z6S(-1)",0) -> 1 | FR6: 1420534295 | FS6: 9332133 | FT6: =INDIRECT("ZS(-1)",0) * 'Correction factor'!$C$13 -> 12942390 | FU6: =INDIRECT("ZS(-1)",0) + INDIRECT("ZS(-3)",0) -> 1.4334767e+09 | FV6: =INDIRECT("ZS(-1)",0) / INDIRECT("Z6S(-1)",0) -> 1 | FW6: 1228353052 | FX6: 12801661 | FY6: =INDIRECT("ZS(-1)",0) * 'Correction factor'!$C$13 -> 17754150 | FZ6: =INDIRECT("ZS(-1)",0) + INDIRECT("ZS(-3)",0) -> 1.2461072e+09 | GA6: =INDIRECT("ZS(-1)",0) / INDIRECT("Z6S(-1)",0) -> 1 | GB6: 1421396204 | GC6: 9095111 | GD6: =INDIRECT("ZS(-1)",0) * 'Correction factor'!$C$13 -> 12613673 | GE6: =INDIRECT("ZS(-1)",0) + INDIRECT("ZS(-3)",0) -> 1.4340099e+09 | GF6: =INDIRECT("ZS(-1)",0) / INDIRECT("Z6S(-1)",0) -> 1 | GG6: 1418816506 | GH6: 11028712 | GI6: =INDIRECT("ZS(-1)",0) * 'Correction factor'!$C$13 -> 15295312 | GJ6: =INDIRECT("ZS(-1)",0) + INDIRECT("ZS(-3)",0) -> 1.4341118e+09 | GK6: =INDIRECT("ZS(-1)",0) / INDIRECT("Z6S(-1)",0) -> 1 | GL6: 1436501977 | GM6: 9434602 | GN6: =INDIRECT("ZS(-1)",0) * 'Correction factor'!$C$13 -> 13084500 | GO6: =INDIRECT("ZS(-1)",0) + INDIRECT("ZS(-3)",0) -> 1.4495865e+09 | GP6: =INDIRECT("ZS(-1)",0) / INDIRECT("Z6S(-1)",0) -> 1 | GQ6: 951626166 | GR6: 9230790 | GS6: =INDIRECT("ZS(-1)",0) * 'Correction factor'!$C$13 -> 12801841 | GT6: =INDIRECT("ZS(-1)",0) + INDIRECT("ZS(-3)",0) -> 9.6442801e+08 | GU6: =INDIRECT("ZS(-1)",0) / INDIRECT("Z6S(-1)",0) -> 1 | GV6: 1394694685 | GW6: 10052668 | GX6: =INDIRECT("ZS(-1)",0) * 'Correction factor'!$C$13 -> 13941673 | GY6: =INDIRECT("ZS(-1)",0) + INDIRECT("ZS(-3)",0) -> 1.4086364e+09 | GZ6: =INDIRECT("ZS(-1)",0) / INDIRECT("Z6S(-1)",0) -> 1 | HA6: 1351678348 | HB6: 9906938 | HC6: =INDIRECT("ZS(-1)",0) * 'Correction factor'!$C$13 -> 13739565 | HD6: =INDIRECT("ZS(-1)",0) + INDIRECT("ZS(-3)",0) -> 1.3654179e+09 | HE6: =INDIRECT("ZS(-1)",0) / INDIRECT("Z6S(-1)",0) -> 1 | HF6: 1340785434 | HG6: 12076403 | HH6: =INDIRECT("ZS(-1)",0) * 'Correction factor'!$C$13 -> 16748316 | HI6: =INDIRECT("ZS(-1)",0) + INDIRECT("ZS(-3)",0) -> 1.3575338e+09 | HJ6: =INDIRECT("ZS(-1)",0) / INDIRECT("Z6S(-1)",0) -> 1 | HK6: 1324253781 | HL6: 13721670 | HM6: =INDIRECT("ZS(-1)",0) * 'Correction factor'!$C$13 -> 19030076 | HN6: =INDIRECT("ZS(-1)",0) + INDIRECT("ZS(-3)",0) -> 1.3432839e+09 | HO6: =INDIRECT("ZS(-1)",0) / INDIRECT("Z6S(-1)",0) -> 1 | HP6: 1529245379 | HQ6: 9567148 | HR6: =INDIRECT("ZS(-1)",0) * 'Correction factor'!$C$13 -> 13268323 | HS6: =INDIRECT("ZS(-1)",0) + INDIRECT("ZS(-3)",0) -> 1.5425137e+09 | HT6: =INDIRECT("ZS(-1)",0) / INDIRECT("Z6S(-1)",0) -> 1 | HU6: 1260221853 | HV6: 10199442 | HW6: =INDIRECT("ZS(-1)",0) * 'Correction factor'!$C$13 -> 14145228 | HX6: =INDIRECT("ZS(-1)",0) + INDIRECT("ZS(-3)",0) -> 1.2743671e+09 | HY6: =INDIRECT("ZS(-1)",0) / INDIRECT("Z6S(-1)",0) -> 1 | HZ6: 1272182052 | IA6: 12560946 | IB6: =INDIRECT("ZS(-1)",0) * 'Correction factor'!$C$13 -> 17420311 | IC6: =INDIRECT("ZS(-1)",0) + INDIRECT("ZS(-3)",0) -> 1.2896024e+09 | ID6: =INDIRECT("ZS(-1)",0) / INDIRECT("Z6S(-1)",0) -> 1 | IE6: 1294444792 | IF6: 8928894 | IG6: =INDIRECT("ZS(-1)",0) * 'Correction factor'!$C$13 -> 12383152 | IH6: =INDIRECT("ZS(-1)",0) + INDIRECT("ZS(-3)",0) -> 1.3068279e+09 | II6: =INDIRECT("ZS(-1)",0) / INDIRECT("Z6S(-1)",0) -> 1
A7: 3 | B7: 45494 | C7: Sunday | D7: 1549830112 | E7: 7808635 | F7: =INDIRECT("ZS(-1)",0) * 'Correction factor'!$C$13 -> 10829507 | G7: =INDIRECT("ZS(-1)",0) + INDIRECT("ZS(-3)",0) -> 1.5606596e+09 | H7: =INDIRECT("ZS(-1)",0) / INDIRECT("Z6S(-1)",0) -> 1.1287429 | I7: 1724129151 | J7: 9388587 | K7: =INDIRECT("ZS(-1)",0) * 'Correction factor'!$C$13 -> 13020684 | L7: =INDIRECT("ZS(-1)",0) + INDIRECT("ZS(-3)",0) -> 1.7371498e+09 | M7: =INDIRECT("ZS(-1)",0) / INDIRECT("Z6S(-1)",0) -> 1.1387077 | N7: 1503849956 | O7: 6618873 | P7: =INDIRECT("ZS(-1)",0) * 'Correction factor'!$C$13 -> 9179469.8 | Q7: =INDIRECT("ZS(-1)",0) + INDIRECT("ZS(-3)",0) -> 1.5130294e+09 | R7: =INDIRECT("ZS(-1)",0) / INDIRECT("Z6S(-1)",0) -> 1.1778987 | S7: 1626364043 | T7: 6447086 | U7: =INDIRECT("ZS(-1)",0) * 'Correction factor'!$C$13 -> 8941224.8 | V7: =INDIRECT("ZS(-1)",0) + INDIRECT("ZS(-3)",0) -> 1.6353053e+09 | W7: =INDIRECT("ZS(-1)",0) / INDIRECT("Z6S(-1)",0) -> 1.116342 | X7: 1686039252 | Y7: 7825031 | Z7: =INDIRECT("ZS(-1)",0) * 'Correction factor'!$C$13 -> 10852246 | AA7: =INDIRECT("ZS(-1)",0) + INDIRECT("ZS(-3)",0) -> 1.6968915e+09 | AB7: =INDIRECT("ZS(-1)",0) / INDIRECT("Z6S(-1)",0) -> 1.1834619 | AC7: 1964363333 | AD7: 11048359 | AE7: =INDIRECT("ZS(-1)",0) * 'Correction factor'!$C$13 -> 15322560 | AF7: =INDIRECT("ZS(-1)",0) + INDIRECT("ZS(-3)",0) -> 1.9796859e+09 | AG7: =INDIRECT("ZS(-1)",0) / INDIRECT("Z6S(-1)",0) -> 1.2771233 | AH7: 1578514262 | AI7: 7875049 | AJ7: =INDIRECT("ZS(-1)",0) * 'Correction factor'!$C$13 -> 10921614 | AK7: =INDIRECT("ZS(-1)",0) + INDIRECT("ZS(-3)",0) -> 1.5894359e+09 | AL7: =INDIRECT("ZS(-1)",0) / INDIRECT("Z6S(-1)",0) -> 0.90206214 | AM7: 1466390320 | AN7: 17421025 | AO7: =INDIRECT("ZS(-1)",0) * 'Correction factor'!$C$13 -> 24160574 | AP7: =INDIRECT("ZS(-1)",0) + INDIRECT("ZS(-3)",0) -> 1.4905509e+09 | AQ7: =INDIRECT("ZS(-1)",0) / INDIRECT("Z6S(-1)",0) -> 0.96798365 | AR7: 1307935159 | AS7: 6648965 | AT7: =INDIRECT("ZS(-1)",0) * 'Correction factor'!$C$13 -> 9221203.3 | AU7: =INDIRECT("ZS(-1)",0) + INDIRECT("ZS(-3)",0) -> 1.3171564e+09 | AV7: =INDIRECT("ZS(-1)",0) / INDIRECT("Z6S(-1)",0) -> 0.94259193 | AW7: 1306711049 | AX7: 9099608 | AY7: =INDIRECT("ZS(-1)",0) * 'Correction factor'!$C$13 -> 12619909 | AZ7: =INDIRECT("ZS(-1)",0) + INDIRECT("ZS(-3)",0) -> 1.319331e+09 | BA7: =INDIRECT("ZS(-1)",0) / INDIRECT("Z6S(-1)",0) -> 0.90643596 | BB7: 1310566078 | BC7: 7224683 | BD7: =INDIRECT("ZS(-1)",0) * 'Correction factor'!$C$13 -> 10019645 | BE7: =INDIRECT("ZS(-1)",0) + INDIRECT("ZS(-3)",0) -> 1.3205857e+09 | BF7: =INDIRECT("ZS(-1)",0) / INDIRECT("Z6S(-1)",0) -> 0.89637066 | BG7: 1629258664 | BH7: 7242441 | BI7: =INDIRECT("ZS(-1)",0) * 'Correction factor'!$C$13 -> 10044273 | BJ7: =INDIRECT("ZS(-1)",0) + INDIRECT("ZS(-3)",0) -> 1.6393029e+09 | BK7: =INDIRECT("ZS(-1)",0) / INDIRECT("Z6S(-1)",0) -> 0.99849531 | BL7: 36861887 | BM7: 175236902 | BN7: =INDIRECT("ZS(-1)",0) * 'Correction factor'!$C$13 -> 2.4302957e+08 | BO7: =INDIRECT("ZS(-1)",0) + INDIRECT("ZS(-3)",0) -> 2.7989146e+08 | BP7: =INDIRECT("ZS(-1)",0) / INDIRECT("Z6S(-1)",0) -> 1.3423676 | BQ7: 8744821 | BR7: 135389730 | BS7: =INDIRECT("ZS(-1)",0) * 'Correction factor'!$C$13 -> 1.87767e+08 | BT7: =INDIRECT("ZS(-1)",0) + INDIRECT("ZS(-3)",0) -> 1.9651182e+08 | BU7: =INDIRECT("ZS(-1)",0) / INDIRECT("Z6S(-1)",0) -> 1.1536933 | BV7: 7156354 | BW7: 140712498 | BX7: =INDIRECT("ZS(-1)",0) * 'Correction factor'!$C$13 -> 1.9514895e+08 | BY7: =INDIRECT("ZS(-1)",0) + INDIRECT("ZS(-3)",0) -> 2.0230531e+08 | BZ7: =INDIRECT("ZS(-1)",0) / INDIRECT("Z6S(-1)",0) -> 1.2875769 | CA7: 7640325 | CB7: 153477112 | CC7: =INDIRECT("ZS(-1)",0) * 'Correction factor'!$C$13 -> 2.1285172e+08 | CD7: =INDIRECT("ZS(-1)",0) + INDIRECT("ZS(-3)",0) -> 2.2049205e+08 | CE7: =INDIRECT("ZS(-1)",0) / INDIRECT("Z6S(-1)",0) -> 1.2480404 | CF7: 29996992 | CG7: 98630859 | CH7: =INDIRECT("ZS(-1)",0) * 'Correction factor'!$C$13 -> 1.3678749e+08 | CI7: =INDIRECT("ZS(-1)",0) + INDIRECT("ZS(-3)",0) -> 1.6678448e+08 | CJ7: =INDIRECT("ZS(-1)",0) / INDIRECT("Z6S(-1)",0) -> 1.2115979 | CK7: 20234497 | CL7: 117685670 | CM7: =INDIRECT("ZS(-1)",0) * 'Correction factor'!$C$13 -> 1.632139e+08 | CN7: =INDIRECT("ZS(-1)",0) + INDIRECT("ZS(-3)",0) -> 1.8344839e+08 | CO7: =INDIRECT("ZS(-1)",0) / INDIRECT("Z6S(-1)",0) -> 1.3103812 | CP7: 1318114622 | CQ7: 7134118 | CR7: =INDIRECT("ZS(-1)",0) * 'Correction factor'!$C$13 -> 9894044 | CS7: =INDIRECT("ZS(-1)",0) + INDIRECT("ZS(-3)",0) -> 1.3280087e+09 | CT7: =INDIRECT("ZS(-1)",0) / INDIRECT("Z6S(-1)",0) -> 0.90467911 | CU7: 1117594272 | CV7: 6951748 | CW7: =INDIRECT("ZS(-1)",0) * 'Correction factor'!$C$13 -> 9641121.8 | CX7: =INDIRECT("ZS(-1)",0) + INDIRECT("ZS(-3)",0) -> 1.1272354e+09 | CY7: =INDIRECT("ZS(-1)",0) / INDIRECT("Z6S(-1)",0) -> 0.86246693 | CZ7: 1340269901 | DA7: 8597167 | DB7: =INDIRECT("ZS(-1)",0) * 'Correction factor'!$C$13 -> 11923093 | DC7: =INDIRECT("ZS(-1)",0) + INDIRECT("ZS(-3)",0) -> 1.352193e+09 | DD7: =INDIRECT("ZS(-1)",0) / INDIRECT("Z6S(-1)",0) -> 0.88752955 | DE7: 1199237184 | DF7: 17873214 | DG7: =INDIRECT("ZS(-1)",0) * 'Correction factor'!$C$13 -> 24787699 | DH7: =INDIRECT("ZS(-1)",0) + INDIRECT("ZS(-3)",0) -> 1.2240249e+09 | DI7: =INDIRECT("ZS(-1)",0) / INDIRECT("Z6S(-1)",0) -> 0.89125853 | DJ7: 1038480667 | DK7: 8517936 | DL7: =INDIRECT("ZS(-1)",0) * 'Correction factor'!$C$13 -> 11813210 | DM7: =INDIRECT("ZS(-1)",0) + INDIRECT("ZS(-3)",0) -> 1.0502939e+09 | DN7: =INDIRECT("ZS(-1)",0) / INDIRECT("Z6S(-1)",0) -> 0.86569451 | DO7: 1051363331 | DP7: 8467950 | DQ7: =INDIRECT("ZS(-1)",0) * 'Correction factor'!$C$13 -> 11743886 | DR7: =INDIRECT("ZS(-1)",0) + INDIRECT("ZS(-3)",0) -> 1.0631072e+09 | DS7: =INDIRECT("ZS(-1)",0) / INDIRECT("Z6S(-1)",0) -> 0.80094414 | DT7: 1186011944 | DU7: 10453619 | DV7: =INDIRECT("ZS(-1)",0) * 'Correction factor'!$C$13 -> 14497737 | DW7: =INDIRECT("ZS(-1)",0) + INDIRECT("ZS(-3)",0) -> 1.2005097e+09 | DX7: =INDIRECT("ZS(-1)",0) / INDIRECT("Z6S(-1)",0) -> 0.88402504 | DY7: 1260114983 | DZ7: 11339632 | EA7: =INDIRECT("ZS(-1)",0) * 'Correction factor'!$C$13 -> 15726516 | EB7: =INDIRECT("ZS(-1)",0) + INDIRECT("ZS(-3)",0) -> 1.2758415e+09 | EC7: =INDIRECT("ZS(-1)",0) / INDIRECT("Z6S(-1)",0) -> 0.90227528 | ED7: 1125802303 | EE7: 14101226 | EF7: =INDIRECT("ZS(-1)",0) * 'Correction factor'!$C$13 -> 19556468 | EG7: =INDIRECT("ZS(-1)",0) + INDIRECT("ZS(-3)",0) -> 1.1453588e+09 | EH7: =INDIRECT("ZS(-1)",0) / INDIRECT("Z6S(-1)",0) -> 0.87564553 | EI7: 1150968529 | EJ7: 13714920 | EK7: =INDIRECT("ZS(-1)",0) * 'Correction factor'!$C$13 -> 19020715 | EL7: =INDIRECT("ZS(-1)",0) + INDIRECT("ZS(-3)",0) -> 1.1699892e+09 | EM7: =INDIRECT("ZS(-1)",0) / INDIRECT("Z6S(-1)",0) -> 0.88902052 | EN7: 1230575740 | EO7: 8912360 | EP7: =INDIRECT("ZS(-1)",0) * 'Correction factor'!$C$13 -> 12360222 | EQ7: =INDIRECT("ZS(-1)",0) + INDIRECT("ZS(-3)",0) -> 1.242936e+09 | ER7: =INDIRECT("ZS(-1)",0) / INDIRECT("Z6S(-1)",0) -> 0.8450932 | ES7: 1319943048 | ET7: 7375617 | EU7: =INDIRECT("ZS(-1)",0) * 'Correction factor'!$C$13 -> 10228970 | EV7: =INDIRECT("ZS(-1)",0) + INDIRECT("ZS(-3)",0) -> 1.330172e+09 | EW7: =INDIRECT("ZS(-1)",0) / INDIRECT("Z6S(-1)",0) -> 0.90925581 | EX7: 1306407759 | EY7: 7353735 | EZ7: =INDIRECT("ZS(-1)",0) * 'Correction factor'!$C$13 -> 10198623 | FA7: =INDIRECT("ZS(-1)",0) + INDIRECT("ZS(-3)",0) -> 1.3166064e+09 | FB7: =INDIRECT("ZS(-1)",0) / INDIRECT("Z6S(-1)",0) -> 0.93870051 | FC7: 1050335689 | FD7: 9644346 | FE7: =INDIRECT("ZS(-1)",0) * 'Correction factor'!$C$13 -> 13375386 | FF7: =INDIRECT("ZS(-1)",0) + INDIRECT("ZS(-3)",0) -> 1.0637111e+09 | FG7: =INDIRECT("ZS(-1)",0) / INDIRECT("Z6S(-1)",0) -> 0.82091329 | FH7: 1673319491 | FI7: 10507969 | FJ7: =INDIRECT("ZS(-1)",0) * 'Correction factor'!$C$13 -> 14573113 | FK7: =INDIRECT("ZS(-1)",0) + INDIRECT("ZS(-3)",0) -> 1.6878926e+09 | FL7: =INDIRECT("ZS(-1)",0) / INDIRECT("Z6S(-1)",0) -> 0.95087266 | FM7: 1276837302 | FN7: 7260724 | FO7: =INDIRECT("ZS(-1)",0) * 'Correction factor'!$C$13 -> 10069629 | FP7: =INDIRECT("ZS(-1)",0) + INDIRECT("ZS(-3)",0) -> 1.2869069e+09 | FQ7: =INDIRECT("ZS(-1)",0) / INDIRECT("Z6S(-1)",0) -> 0.90947215 | FR7: 1259099849 | FS7: 7796515 | FT7: =INDIRECT("ZS(-1)",0) * 'Correction factor'!$C$13 -> 10812698 | FU7: =INDIRECT("ZS(-1)",0) + INDIRECT("ZS(-3)",0) -> 1.2699125e+09 | FV7: =INDIRECT("ZS(-1)",0) / INDIRECT("Z6S(-1)",0) -> 0.8858969 | FW7: 1096360288 | FX7: 12364852 | FY7: =INDIRECT("ZS(-1)",0) * 'Correction factor'!$C$13 -> 17148355 | FZ7: =INDIRECT("ZS(-1)",0) + INDIRECT("ZS(-3)",0) -> 1.1135086e+09 | GA7: =INDIRECT("ZS(-1)",0) / INDIRECT("Z6S(-1)",0) -> 0.89358977 | GB7: 1253407224 | GC7: 7478906 | GD7: =INDIRECT("ZS(-1)",0) * 'Correction factor'!$C$13 -> 10372218 | GE7: =INDIRECT("ZS(-1)",0) + INDIRECT("ZS(-3)",0) -> 1.2637794e+09 | GF7: =INDIRECT("ZS(-1)",0) / INDIRECT("Z6S(-1)",0) -> 0.88129061 | GG7: 1185333323 | GH7: 8983858 | GI7: =INDIRECT("ZS(-1)",0) * 'Correction factor'!$C$13 -> 12459380 | GJ7: =INDIRECT("ZS(-1)",0) + INDIRECT("ZS(-3)",0) -> 1.1977927e+09 | GK7: =INDIRECT("ZS(-1)",0) / INDIRECT("Z6S(-1)",0) -> 0.8352157 | GL7: 1224862753 | GM7: 7914068 | GN7: =INDIRECT("ZS(-1)",0) * 'Correction factor'!$C$13 -> 10975728 | GO7: =INDIRECT("ZS(-1)",0) + INDIRECT("ZS(-3)",0) -> 1.2358385e+09 | GP7: =INDIRECT("ZS(-1)",0) / INDIRECT("Z6S(-1)",0) -> 0.85254554 | GQ7: 900183168 | GR7: 7080993 | GS7: =INDIRECT("ZS(-1)",0) * 'Correction factor'!$C$13 -> 9820366.9 | GT7: =INDIRECT("ZS(-1)",0) + INDIRECT("ZS(-3)",0) -> 9.1000353e+08 | GU7: =INDIRECT("ZS(-1)",0) / INDIRECT("Z6S(-1)",0) -> 0.94356813 | GV7: 1278773664 | GW7: 8818691 | GX7: =INDIRECT("ZS(-1)",0) * 'Correction factor'!$C$13 -> 12230316 | GY7: =INDIRECT("ZS(-1)",0) + INDIRECT("ZS(-3)",0) -> 1.291004e+09 | GZ7: =INDIRECT("ZS(-1)",0) / INDIRECT("Z6S(-1)",0) -> 0.91649202 | HA7: 1172601286 | HB7: 8283100 | HC7: =INDIRECT("ZS(-1)",0) * 'Correction factor'!$C$13 -> 11487525 | HD7: =INDIRECT("ZS(-1)",0) + INDIRECT("ZS(-3)",0) -> 1.1840888e+09 | HE7: =INDIRECT("ZS(-1)",0) / INDIRECT("Z6S(-1)",0) -> 0.86719883 | HF7: 1250750536 | HG7: 11979786 | HH7: =INDIRECT("ZS(-1)",0) * 'Correction factor'!$C$13 -> 16614322 | HI7: =INDIRECT("ZS(-1)",0) + INDIRECT("ZS(-3)",0) -> 1.2673649e+09 | HJ7: =INDIRECT("ZS(-1)",0) / INDIRECT("Z6S(-1)",0) -> 0.93357889 | HK7: 1095587823 | HL7: 13798848 | HM7: =INDIRECT("ZS(-1)",0) * 'Correction factor'!$C$13 -> 19137111 | HN7: =INDIRECT("ZS(-1)",0) + INDIRECT("ZS(-3)",0) -> 1.1147249e+09 | HO7: =INDIRECT("ZS(-1)",0) / INDIRECT("Z6S(-1)",0) -> 0.82985061 | HP7: 1341501400 | HQ7: 7008248 | HR7: =INDIRECT("ZS(-1)",0) * 'Correction factor'!$C$13 -> 9719479.6 | HS7: =INDIRECT("ZS(-1)",0) + INDIRECT("ZS(-3)",0) -> 1.3512209e+09 | HT7: =INDIRECT("ZS(-1)",0) / INDIRECT("Z6S(-1)",0) -> 0.87598631 | HU7: 1186498532 | HV7: 7949779 | HW7: =INDIRECT("ZS(-1)",0) * 'Correction factor'!$C$13 -> 11025254 | HX7: =INDIRECT("ZS(-1)",0) + INDIRECT("ZS(-3)",0) -> 1.1975238e+09 | HY7: =INDIRECT("ZS(-1)",0) / INDIRECT("Z6S(-1)",0) -> 0.93970082 | HZ7: 1098935058 | IA7: 13253272 | IB7: =INDIRECT("ZS(-1)",0) * 'Correction factor'!$C$13 -> 18380472 | IC7: =INDIRECT("ZS(-1)",0) + INDIRECT("ZS(-3)",0) -> 1.1173155e+09 | ID7: =INDIRECT("ZS(-1)",0) / INDIRECT("Z6S(-1)",0) -> 0.86640314 | IE7: 1125174999 | IF7: 6902104 | IG7: =INDIRECT("ZS(-1)",0) * 'Correction factor'!$C$13 -> 9572272.4 | IH7: =INDIRECT("ZS(-1)",0) + INDIRECT("ZS(-3)",0) -> 1.1347473e+09 | II7: =INDIRECT("ZS(-1)",0) / INDIRECT("Z6S(-1)",0) -> 0.86832186
A8: 4 | B8: 45495 | C8: Monday | D8: 1745964514 | E8: 8818614 | F8: =INDIRECT("ZS(-1)",0) * 'Correction factor'!$C$13 -> 12230209 | G8: =INDIRECT("ZS(-1)",0) + INDIRECT("ZS(-3)",0) -> 1.7581947e+09 | H8: =INDIRECT("ZS(-1)",0) / INDIRECT("Z6S(-1)",0) -> 1.2716097 | I8: 1933199939 | J8: 10812002 | K8: =INDIRECT("ZS(-1)",0) * 'Correction factor'!$C$13 -> 14994765 | L8: =INDIRECT("ZS(-1)",0) + INDIRECT("ZS(-3)",0) -> 1.9481947e+09 | M8: =INDIRECT("ZS(-1)",0) / INDIRECT("Z6S(-1)",0) -> 1.2770483 | N8: 1790249855 | O8: 8034895 | P8: =INDIRECT("ZS(-1)",0) * 'Correction factor'!$C$13 -> 11143298 | Q8: =INDIRECT("ZS(-1)",0) + INDIRECT("ZS(-3)",0) -> 1.8013932e+09 | R8: =INDIRECT("ZS(-1)",0) / INDIRECT("Z6S(-1)",0) -> 1.4023909 | S8: 1852078510 | T8: 7224203 | U8: =INDIRECT("ZS(-1)",0) * 'Correction factor'!$C$13 -> 10018980 | V8: =INDIRECT("ZS(-1)",0) + INDIRECT("ZS(-3)",0) -> 1.8620975e+09 | W8: =INDIRECT("ZS(-1)",0) / INDIRECT("Z6S(-1)",0) -> 1.2711619 | X8: 2003050974 | Y8: 8809699 | Z8: =INDIRECT("ZS(-1)",0) * 'Correction factor'!$C$13 -> 12217845 | AA8: =INDIRECT("ZS(-1)",0) + INDIRECT("ZS(-3)",0) -> 2.0152688e+09 | AB8: =INDIRECT("ZS(-1)",0) / INDIRECT("Z6S(-1)",0) -> 1.4055076 | AC8: 2368534041 | AD8: 12659188 | AE8: =INDIRECT("ZS(-1)",0) * 'Correction factor'!$C$13 -> 17556559 | AF8: =INDIRECT("ZS(-1)",0) + INDIRECT("ZS(-3)",0) -> 2.3860906e+09 | AG8: =INDIRECT("ZS(-1)",0) / INDIRECT("Z6S(-1)",0) -> 1.5393007 | AH8: 1152710707 | AI8: 8819543 | AJ8: =INDIRECT("ZS(-1)",0) * 'Correction factor'!$C$13 -> 12231498 | AK8: =INDIRECT("ZS(-1)",0) + INDIRECT("ZS(-3)",0) -> 1.1649422e+09 | AL8: =INDIRECT("ZS(-1)",0) / INDIRECT("Z6S(-1)",0) -> 0.66114668 | AM8: 1218735993 | AN8: 20519792 | AO8: =INDIRECT("ZS(-1)",0) * 'Correction factor'!$C$13 -> 28458140 | AP8: =INDIRECT("ZS(-1)",0) + INDIRECT("ZS(-3)",0) -> 1.2471941e+09 | AQ8: =INDIRECT("ZS(-1)",0) / INDIRECT("Z6S(-1)",0) -> 0.80994452 | AR8: 1080537262 | AS8: 7217414 | AT8: =INDIRECT("ZS(-1)",0) * 'Correction factor'!$C$13 -> 10009564 | AU8: =INDIRECT("ZS(-1)",0) + INDIRECT("ZS(-3)",0) -> 1.0905468e+09 | AV8: =INDIRECT("ZS(-1)",0) / INDIRECT("Z6S(-1)",0) -> 0.78042415 | AW8: 1041470709 | AX8: 11005206 | AY8: =INDIRECT("ZS(-1)",0) * 'Correction factor'!$C$13 -> 15262713 | AZ8: =INDIRECT("ZS(-1)",0) + INDIRECT("ZS(-3)",0) -> 1.0567334e+09 | BA8: =INDIRECT("ZS(-1)",0) / INDIRECT("Z6S(-1)",0) -> 0.72602039 | BB8: 973848831 | BC8: 7532688 | BD8: =INDIRECT("ZS(-1)",0) * 'Correction factor'!$C$13 -> 10446806 | BE8: =INDIRECT("ZS(-1)",0) + INDIRECT("ZS(-3)",0) -> 9.8429564e+08 | BF8: =INDIRECT("ZS(-1)",0) / INDIRECT("Z6S(-1)",0) -> 0.66810788 | BG8: 1457747550 | BH8: 7981363 | BI8: =INDIRECT("ZS(-1)",0) * 'Correction factor'!$C$13 -> 11069057 | BJ8: =INDIRECT("ZS(-1)",0) + INDIRECT("ZS(-3)",0) -> 1.4688166e+09 | BK8: =INDIRECT("ZS(-1)",0) / INDIRECT("Z6S(-1)",0) -> 0.89465251 | BL8: 40442625 | BM8: 241448259 | BN8: =INDIRECT("ZS(-1)",0) * 'Correction factor'!$C$13 -> 3.3485565e+08 | BO8: =INDIRECT("ZS(-1)",0) + INDIRECT("ZS(-3)",0) -> 3.7529827e+08 | BP8: =INDIRECT("ZS(-1)",0) / INDIRECT("Z6S(-1)",0) -> 1.7999415 | BQ8: 9287122 | BR8: 171783621 | BS8: =INDIRECT("ZS(-1)",0) * 'Correction factor'!$C$13 -> 2.3824034e+08 | BT8: =INDIRECT("ZS(-1)",0) + INDIRECT("ZS(-3)",0) -> 2.4752746e+08 | BU8: =INDIRECT("ZS(-1)",0) / INDIRECT("Z6S(-1)",0) -> 1.453199 | BV8: 13423677 | BW8: 190410809 | BX8: =INDIRECT("ZS(-1)",0) * 'Correction factor'!$C$13 -> 2.640737e+08 | BY8: =INDIRECT("ZS(-1)",0) + INDIRECT("ZS(-3)",0) -> 2.7749738e+08 | BZ8: =INDIRECT("ZS(-1)",0) / INDIRECT("Z6S(-1)",0) -> 1.7661386 | CA8: 10766516 | CB8: 204367980 | CC8: =INDIRECT("ZS(-1)",0) * 'Correction factor'!$C$13 -> 2.8343038e+08 | CD8: =INDIRECT("ZS(-1)",0) + INDIRECT("ZS(-3)",0) -> 2.941969e+08 | CE8: =INDIRECT("ZS(-1)",0) / INDIRECT("Z6S(-1)",0) -> 1.6652284 | CF8: 35926148 | CG8: 120454603 | CH8: =INDIRECT("ZS(-1)",0) * 'Correction factor'!$C$13 -> 1.6705403e+08 | CI8: =INDIRECT("ZS(-1)",0) + INDIRECT("ZS(-3)",0) -> 2.0298018e+08 | CJ8: =INDIRECT("ZS(-1)",0) / INDIRECT("Z6S(-1)",0) -> 1.4745399 | CK8: 28151635 | CL8: 150093226 | CM8: =INDIRECT("ZS(-1)",0) * 'Correction factor'!$C$13 -> 2.0815874e+08 | CN8: =INDIRECT("ZS(-1)",0) + INDIRECT("ZS(-3)",0) -> 2.3631037e+08 | CO8: =INDIRECT("ZS(-1)",0) / INDIRECT("Z6S(-1)",0) -> 1.687977 | CP8: 1086147530 | CQ8: 7592099 | CR8: =INDIRECT("ZS(-1)",0) * 'Correction factor'!$C$13 -> 10529201 | CS8: =INDIRECT("ZS(-1)",0) + INDIRECT("ZS(-3)",0) -> 1.0966767e+09 | CT8: =INDIRECT("ZS(-1)",0) / INDIRECT("Z6S(-1)",0) -> 0.74708889 | CU8: 954855980 | CV8: 7583324 | CW8: =INDIRECT("ZS(-1)",0) * 'Correction factor'!$C$13 -> 10517031 | CX8: =INDIRECT("ZS(-1)",0) + INDIRECT("ZS(-3)",0) -> 9.6537301e+08 | CY8: =INDIRECT("ZS(-1)",0) / INDIRECT("Z6S(-1)",0) -> 0.73862328 | CZ8: 985248044 | DA8: 9839675 | DB8: =INDIRECT("ZS(-1)",0) * 'Correction factor'!$C$13 -> 13646281 | DC8: =INDIRECT("ZS(-1)",0) + INDIRECT("ZS(-3)",0) -> 9.9889432e+08 | DD8: =INDIRECT("ZS(-1)",0) / INDIRECT("Z6S(-1)",0) -> 0.65563735 | DE8: 999430196 | DF8: 20983333 | DG8: =INDIRECT("ZS(-1)",0) * 'Correction factor'!$C$13 -> 29101007 | DH8: =INDIRECT("ZS(-1)",0) + INDIRECT("ZS(-3)",0) -> 1.0285312e+09 | DI8: =INDIRECT("ZS(-1)",0) / INDIRECT("Z6S(-1)",0) -> 0.74891223 | DJ8: 842185051 | DK8: 9888608 | DL8: =INDIRECT("ZS(-1)",0) * 'Correction factor'!$C$13 -> 13714144 | DM8: =INDIRECT("ZS(-1)",0) + INDIRECT("ZS(-3)",0) -> 8.558992e+08 | DN8: =INDIRECT("ZS(-1)",0) / INDIRECT("Z6S(-1)",0) -> 0.70546658 | DO8: 748386288 | DP8: 9614544 | DQ8: =INDIRECT("ZS(-1)",0) * 'Correction factor'!$C$13 -> 13334055 | DR8: =INDIRECT("ZS(-1)",0) + INDIRECT("ZS(-3)",0) -> 7.6172034e+08 | DS8: =INDIRECT("ZS(-1)",0) / INDIRECT("Z6S(-1)",0) -> 0.57387951 | DT8: 922631532 | DU8: 11853455 | DV8: =INDIRECT("ZS(-1)",0) * 'Correction factor'!$C$13 -> 16439118 | DW8: =INDIRECT("ZS(-1)",0) + INDIRECT("ZS(-3)",0) -> 9.3907065e+08 | DX8: =INDIRECT("ZS(-1)",0) / INDIRECT("Z6S(-1)",0) -> 0.69150793 | DY8: 1036201632 | DZ8: 14886645 | EA8: =INDIRECT("ZS(-1)",0) * 'Correction factor'!$C$13 -> 20645737 | EB8: =INDIRECT("ZS(-1)",0) + INDIRECT("ZS(-3)",0) -> 1.0568474e+09 | EC8: =INDIRECT("ZS(-1)",0) / INDIRECT("Z6S(-1)",0) -> 0.7474026 | ED8: 936711428 | EE8: 17899560 | EF8: =INDIRECT("ZS(-1)",0) * 'Correction factor'!$C$13 -> 24824237 | EG8: =INDIRECT("ZS(-1)",0) + INDIRECT("ZS(-3)",0) -> 9.6153566e+08 | EH8: =INDIRECT("ZS(-1)",0) / INDIRECT("Z6S(-1)",0) -> 0.73510975 | EI8: 898601394 | EJ8: 16750009 | EK8: =INDIRECT("ZS(-1)",0) * 'Correction factor'!$C$13 -> 23229967 | EL8: =INDIRECT("ZS(-1)",0) + INDIRECT("ZS(-3)",0) -> 9.2183136e+08 | EM8: =INDIRECT("ZS(-1)",0) / INDIRECT("Z6S(-1)",0) -> 0.70045686 | EN8: 988878603 | EO8: 10408914 | EP8: =INDIRECT("ZS(-1)",0) * 'Correction factor'!$C$13 -> 14435737 | EQ8: =INDIRECT("ZS(-1)",0) + INDIRECT("ZS(-3)",0) -> 1.0033143e+09 | ER8: =INDIRECT("ZS(-1)",0) / INDIRECT("Z6S(-1)",0) -> 0.6821704 | ES8: 1089008693 | ET8: 7971868 | EU8: =INDIRECT("ZS(-1)",0) * 'Correction factor'!$C$13 -> 11055888 | EV8: =INDIRECT("ZS(-1)",0) + INDIRECT("ZS(-3)",0) -> 1.1000646e+09 | EW8: =INDIRECT("ZS(-1)",0) / INDIRECT("Z6S(-1)",0) -> 0.75196298 | EX8: 1115991581 | EY8: 8075904 | EZ8: =INDIRECT("ZS(-1)",0) * 'Correction factor'!$C$13 -> 11200172 | FA8: =INDIRECT("ZS(-1)",0) + INDIRECT("ZS(-3)",0) -> 1.1271918e+09 | FB8: =INDIRECT("ZS(-1)",0) / INDIRECT("Z6S(-1)",0) -> 0.80365361 | FC8: 824711482 | FD8: 11052403 | FE8: =INDIRECT("ZS(-1)",0) * 'Correction factor'!$C$13 -> 15328168 | FF8: =INDIRECT("ZS(-1)",0) + INDIRECT("ZS(-3)",0) -> 8.4003965e+08 | FG8: =INDIRECT("ZS(-1)",0) / INDIRECT("Z6S(-1)",0) -> 0.64829607 | FH8: 1306889387 | FI8: 11265814 | FJ8: =INDIRECT("ZS(-1)",0) * 'Correction factor'!$C$13 -> 15624140 | FK8: =INDIRECT("ZS(-1)",0) + INDIRECT("ZS(-3)",0) -> 1.3225135e+09 | FL8: =INDIRECT("ZS(-1)",0) / INDIRECT("Z6S(-1)",0) -> 0.74503671 | FM8: 1101203266 | FN8: 7905057 | FO8: =INDIRECT("ZS(-1)",0) * 'Correction factor'!$C$13 -> 10963231 | FP8: =INDIRECT("ZS(-1)",0) + INDIRECT("ZS(-3)",0) -> 1.1121665e+09 | FQ8: =INDIRECT("ZS(-1)",0) / INDIRECT("Z6S(-1)",0) -> 0.78598105 | FR8: 1001351548 | FS8: 8566068 | FT8: =INDIRECT("ZS(-1)",0) * 'Correction factor'!$C$13 -> 11879962 | FU8: =INDIRECT("ZS(-1)",0) + INDIRECT("ZS(-3)",0) -> 1.0132315e+09 | FV8: =INDIRECT("ZS(-1)",0) / INDIRECT("Z6S(-1)",0) -> 0.70683501 | FW8: 872367731 | FX8: 17545904 | FY8: =INDIRECT("ZS(-1)",0) * 'Correction factor'!$C$13 -> 24333764 | FZ8: =INDIRECT("ZS(-1)",0) + INDIRECT("ZS(-3)",0) -> 8.967015e+08 | GA8: =INDIRECT("ZS(-1)",0) / INDIRECT("Z6S(-1)",0) -> 0.71960221 | GB8: 1004750799 | GC8: 7902171 | GD8: =INDIRECT("ZS(-1)",0) * 'Correction factor'!$C$13 -> 10959228 | GE8: =INDIRECT("ZS(-1)",0) + INDIRECT("ZS(-3)",0) -> 1.01571e+09 | GF8: =INDIRECT("ZS(-1)",0) / INDIRECT("Z6S(-1)",0) -> 0.70830058 | GG8: 848808601 | GH8: 9682317 | GI8: =INDIRECT("ZS(-1)",0) * 'Correction factor'!$C$13 -> 13428047 | GJ8: =INDIRECT("ZS(-1)",0) + INDIRECT("ZS(-3)",0) -> 8.6223665e+08 | GK8: =INDIRECT("ZS(-1)",0) / INDIRECT("Z6S(-1)",0) -> 0.6012339 | GL8: 989223798 | GM8: 9062582 | GN8: =INDIRECT("ZS(-1)",0) * 'Correction factor'!$C$13 -> 12568559 | GO8: =INDIRECT("ZS(-1)",0) + INDIRECT("ZS(-3)",0) -> 1.0017924e+09 | GP8: =INDIRECT("ZS(-1)",0) / INDIRECT("Z6S(-1)",0) -> 0.69108837 | GQ8: 696144676 | GR8: 7838703 | GS8: =INDIRECT("ZS(-1)",0) * 'Correction factor'!$C$13 -> 10871207 | GT8: =INDIRECT("ZS(-1)",0) + INDIRECT("ZS(-3)",0) -> 7.0701588e+08 | GU8: =INDIRECT("ZS(-1)",0) / INDIRECT("Z6S(-1)",0) -> 0.73309348 | GV8: 1010689635 | GW8: 9850428 | GX8: =INDIRECT("ZS(-1)",0) * 'Correction factor'!$C$13 -> 13661194 | GY8: =INDIRECT("ZS(-1)",0) + INDIRECT("ZS(-3)",0) -> 1.0243508e+09 | GZ8: =INDIRECT("ZS(-1)",0) / INDIRECT("Z6S(-1)",0) -> 0.72719323 | HA8: 942583244 | HB8: 9785933 | HC8: =INDIRECT("ZS(-1)",0) * 'Correction factor'!$C$13 -> 13571748 | HD8: =INDIRECT("ZS(-1)",0) + INDIRECT("ZS(-3)",0) -> 9.5615499e+08 | HE8: =INDIRECT("ZS(-1)",0) / INDIRECT("Z6S(-1)",0) -> 0.70026545 | HF8: 1056090065 | HG8: 15727772 | HH8: =INDIRECT("ZS(-1)",0) * 'Correction factor'!$C$13 -> 21812265 | HI8: =INDIRECT("ZS(-1)",0) + INDIRECT("ZS(-3)",0) -> 1.0779023e+09 | HJ8: =INDIRECT("ZS(-1)",0) / INDIRECT("Z6S(-1)",0) -> 0.79401512 | HK8: 861559711 | HL8: 17792015 | HM8: =INDIRECT("ZS(-1)",0) * 'Correction factor'!$C$13 -> 24675087 | HN8: =INDIRECT("ZS(-1)",0) + INDIRECT("ZS(-3)",0) -> 8.862348e+08 | HO8: =INDIRECT("ZS(-1)",0) / INDIRECT("Z6S(-1)",0) -> 0.65975244 | HP8: 1079200244 | HQ8: 7511423 | HR8: =INDIRECT("ZS(-1)",0) * 'Correction factor'!$C$13 -> 10417314 | HS8: =INDIRECT("ZS(-1)",0) + INDIRECT("ZS(-3)",0) -> 1.0896176e+09 | HT8: =INDIRECT("ZS(-1)",0) / INDIRECT("Z6S(-1)",0) -> 0.70639085 | HU8: 1025421020 | HV8: 8653011 | HW8: =INDIRECT("ZS(-1)",0) * 'Correction factor'!$C$13 -> 12000540 | HX8: =INDIRECT("ZS(-1)",0) + INDIRECT("ZS(-3)",0) -> 1.0374216e+09 | HY8: =INDIRECT("ZS(-1)",0) / INDIRECT("Z6S(-1)",0) -> 0.81406808 | HZ8: 866896158 | IA8: 15300757 | IB8: =INDIRECT("ZS(-1)",0) * 'Correction factor'!$C$13 -> 21220053 | IC8: =INDIRECT("ZS(-1)",0) + INDIRECT("ZS(-3)",0) -> 8.8811621e+08 | ID8: =INDIRECT("ZS(-1)",0) / INDIRECT("Z6S(-1)",0) -> 0.68867446 | IE8: 878196700 | IF8: 7577978 | IG8: =INDIRECT("ZS(-1)",0) * 'Correction factor'!$C$13 -> 10509617 | IH8: =INDIRECT("ZS(-1)",0) + INDIRECT("ZS(-3)",0) -> 8.8870632e+08 | II8: =INDIRECT("ZS(-1)",0) / INDIRECT("Z6S(-1)",0) -> 0.68004845
A9: 5 | B9: 45496 | C9: Tuesday | D9: 2181207661 | E9: 9615573 | F9: =INDIRECT("ZS(-1)",0) * 'Correction factor'!$C$13 -> 13335482 | G9: =INDIRECT("ZS(-1)",0) + INDIRECT("ZS(-3)",0) -> 2.1945431e+09 | H9: =INDIRECT("ZS(-1)",0) / INDIRECT("Z6S(-1)",0) -> 1.5871975 | I9: 2123135102 | J9: 11245161 | K9: =INDIRECT("ZS(-1)",0) * 'Correction factor'!$C$13 -> 15595497 | L9: =INDIRECT("ZS(-1)",0) + INDIRECT("ZS(-3)",0) -> 2.1387306e+09 | M9: =INDIRECT("ZS(-1)",0) / INDIRECT("Z6S(-1)",0) -> 1.4019453 | N9: 1986219034 | O9: 7792191 | P9: =INDIRECT("ZS(-1)",0) * 'Correction factor'!$C$13 -> 10806701 | Q9: =INDIRECT("ZS(-1)",0) + INDIRECT("ZS(-3)",0) -> 1.9970257e+09 | R9: =INDIRECT("ZS(-1)",0) / INDIRECT("Z6S(-1)",0) -> 1.5546916 | S9: 2049296652 | T9: 7200698 | U9: =INDIRECT("ZS(-1)",0) * 'Correction factor'!$C$13 -> 9986381.4 | V9: =INDIRECT("ZS(-1)",0) + INDIRECT("ZS(-3)",0) -> 2.059283e+09 | W9: =INDIRECT("ZS(-1)",0) / INDIRECT("Z6S(-1)",0) -> 1.4057707 | X9: 2314445272 | Y9: 8888008 | Z9: =INDIRECT("ZS(-1)",0) * 'Correction factor'!$C$13 -> 12326449 | AA9: =INDIRECT("ZS(-1)",0) + INDIRECT("ZS(-3)",0) -> 2.3267717e+09 | AB9: =INDIRECT("ZS(-1)",0) / INDIRECT("Z6S(-1)",0) -> 1.6227589 | AC9: 2761607239 | AD9: 13098537 | AE9: =INDIRECT("ZS(-1)",0) * 'Correction factor'!$C$13 -> 18165876 | AF9: =INDIRECT("ZS(-1)",0) + INDIRECT("ZS(-3)",0) -> 2.7797731e+09 | AG9: =INDIRECT("ZS(-1)",0) / INDIRECT("Z6S(-1)",0) -> 1.7932709 | AH9: 924371438 | AI9: 8542388 | AJ9: =INDIRECT("ZS(-1)",0) * 'Correction factor'!$C$13 -> 11847122 | AK9: =INDIRECT("ZS(-1)",0) + INDIRECT("ZS(-3)",0) -> 9.3621856e+08 | AL9: =INDIRECT("ZS(-1)",0) / INDIRECT("Z6S(-1)",0) -> 0.53133777 | AM9: 1162204860 | AN9: 27704696 | AO9: =INDIRECT("ZS(-1)",0) * 'Correction factor'!$C$13 -> 38422617 | AP9: =INDIRECT("ZS(-1)",0) + INDIRECT("ZS(-3)",0) -> 1.2006275e+09 | AQ9: =INDIRECT("ZS(-1)",0) / INDIRECT("Z6S(-1)",0) -> 0.77970352 | AR9: 971610548 | AS9: 7492931 | AT9: =INDIRECT("ZS(-1)",0) * 'Correction factor'!$C$13 -> 10391669 | AU9: =INDIRECT("ZS(-1)",0) + INDIRECT("ZS(-3)",0) -> 9.8200222e+08 | AV9: =INDIRECT("ZS(-1)",0) / INDIRECT("Z6S(-1)",0) -> 0.70274676 | AW9: 1019647984 | AX9: 10877298 | AY9: =INDIRECT("ZS(-1)",0) * 'Correction factor'!$C$13 -> 15085322 | AZ9: =INDIRECT("ZS(-1)",0) + INDIRECT("ZS(-3)",0) -> 1.0347333e+09 | BA9: =INDIRECT("ZS(-1)",0) / INDIRECT("Z6S(-1)",0) -> 0.71090538 | BB9: 877949869 | BC9: 7958379 | BD9: =INDIRECT("ZS(-1)",0) * 'Correction factor'!$C$13 -> 11037181 | BE9: =INDIRECT("ZS(-1)",0) + INDIRECT("ZS(-3)",0) -> 8.8898705e+08 | BF9: =INDIRECT("ZS(-1)",0) / INDIRECT("Z6S(-1)",0) -> 0.60341551 | BG9: 1408587536 | BH9: 8644166 | BI9: =INDIRECT("ZS(-1)",0) * 'Correction factor'!$C$13 -> 11988274 | BJ9: =INDIRECT("ZS(-1)",0) + INDIRECT("ZS(-3)",0) -> 1.4205758e+09 | BK9: =INDIRECT("ZS(-1)",0) / INDIRECT("Z6S(-1)",0) -> 0.86526916 | BL9: 42409598 | BM9: 321681493 | BN9: =INDIRECT("ZS(-1)",0) * 'Correction factor'!$C$13 -> 4.4612815e+08 | BO9: =INDIRECT("ZS(-1)",0) + INDIRECT("ZS(-3)",0) -> 4.8853775e+08 | BP9: =INDIRECT("ZS(-1)",0) / INDIRECT("Z6S(-1)",0) -> 2.3430413 | BQ9: 10634900 | BR9: 211726835 | BS9: =INDIRECT("ZS(-1)",0) * 'Correction factor'!$C$13 -> 2.9363611e+08 | BT9: =INDIRECT("ZS(-1)",0) + INDIRECT("ZS(-3)",0) -> 3.0427101e+08 | BU9: =INDIRECT("ZS(-1)",0) / INDIRECT("Z6S(-1)",0) -> 1.7863323 | BV9: 15049128 | BW9: 249213541 | BX9: =INDIRECT("ZS(-1)",0) * 'Correction factor'!$C$13 -> 3.4562503e+08 | BY9: =INDIRECT("ZS(-1)",0) + INDIRECT("ZS(-3)",0) -> 3.6067416e+08 | BZ9: =INDIRECT("ZS(-1)",0) / INDIRECT("Z6S(-1)",0) -> 2.2955192 | CA9: 10967323 | CB9: 269717160 | CC9: =INDIRECT("ZS(-1)",0) * 'Correction factor'!$C$13 -> 3.7406074e+08 | CD9: =INDIRECT("ZS(-1)",0) + INDIRECT("ZS(-3)",0) -> 3.8502806e+08 | CE9: =INDIRECT("ZS(-1)",0) / INDIRECT("Z6S(-1)",0) -> 2.1793556 | CF9: 24646176 | CG9: 11837039 | CH9: =INDIRECT("ZS(-1)",0) * 'Correction factor'!$C$13 -> 16416351 | CI9: =INDIRECT("ZS(-1)",0) + INDIRECT("ZS(-3)",0) -> 41062527 | CJ9: =INDIRECT("ZS(-1)",0) / INDIRECT("Z6S(-1)",0) -> 0.29829678 | CK9: 6109336 | CL9: 25725683 | CM9: =INDIRECT("ZS(-1)",0) * 'Correction factor'!$C$13 -> 35677997 | CN9: =INDIRECT("ZS(-1)",0) + INDIRECT("ZS(-3)",0) -> 41787333 | CO9: =INDIRECT("ZS(-1)",0) / INDIRECT("Z6S(-1)",0) -> 0.29848905 | CP9: 1102252590 | CQ9: 8189177 | CR9: =INDIRECT("ZS(-1)",0) * 'Correction factor'!$C$13 -> 11357266 | CS9: =INDIRECT("ZS(-1)",0) + INDIRECT("ZS(-3)",0) -> 1.1136099e+09 | CT9: =INDIRECT("ZS(-1)",0) / INDIRECT("Z6S(-1)",0) -> 0.75862424 | CU9: 957464522 | CV9: 7848909 | CW9: =INDIRECT("ZS(-1)",0) * 'Correction factor'!$C$13 -> 10885361 | CX9: =INDIRECT("ZS(-1)",0) + INDIRECT("ZS(-3)",0) -> 9.6834988e+08 | CY9: =INDIRECT("ZS(-1)",0) / INDIRECT("Z6S(-1)",0) -> 0.74090093 | CZ9: 912439205 | DA9: 10803110 | DB9: =INDIRECT("ZS(-1)",0) * 'Correction factor'!$C$13 -> 14982433 | DC9: =INDIRECT("ZS(-1)",0) + INDIRECT("ZS(-3)",0) -> 9.2742164e+08 | DD9: =INDIRECT("ZS(-1)",0) / INDIRECT("Z6S(-1)",0) -> 0.60872532 | DE9: 913892022 | DF9: 23121120 | DG9: =INDIRECT("ZS(-1)",0) * 'Correction factor'!$C$13 -> 32065825 | DH9: =INDIRECT("ZS(-1)",0) + INDIRECT("ZS(-3)",0) -> 9.4595785e+08 | DI9: =INDIRECT("ZS(-1)",0) / INDIRECT("Z6S(-1)",0) -> 0.68878747 | DJ9: 784556222 | DK9: 10793015 | DL9: =INDIRECT("ZS(-1)",0) * 'Correction factor'!$C$13 -> 14968433 | DM9: =INDIRECT("ZS(-1)",0) + INDIRECT("ZS(-3)",0) -> 7.9952465e+08 | DN9: =INDIRECT("ZS(-1)",0) / INDIRECT("Z6S(-1)",0) -> 0.65900042 | DO9: 726536944 | DP9: 10570035 | DQ9: =INDIRECT("ZS(-1)",0) * 'Correction factor'!$C$13 -> 14659190 | DR9: =INDIRECT("ZS(-1)",0) + INDIRECT("ZS(-3)",0) -> 7.4119613e+08 | DS9: =INDIRECT("ZS(-1)",0) / INDIRECT("Z6S(-1)",0) -> 0.55841658 | DT9: 864407054 | DU9: 13694241 | DV9: =INDIRECT("ZS(-1)",0) * 'Correction factor'!$C$13 -> 18992036 | DW9: =INDIRECT("ZS(-1)",0) + INDIRECT("ZS(-3)",0) -> 8.8339909e+08 | DX9: =INDIRECT("ZS(-1)",0) / INDIRECT("Z6S(-1)",0) -> 0.6505128 | DY9: 1040582729 | DZ9: 17894726 | EA9: =INDIRECT("ZS(-1)",0) * 'Correction factor'!$C$13 -> 24817533 | EB9: =INDIRECT("ZS(-1)",0) + INDIRECT("ZS(-3)",0) -> 1.0654003e+09 | EC9: =INDIRECT("ZS(-1)",0) / INDIRECT("Z6S(-1)",0) -> 0.75345121 | ED9: 886132409 | EE9: 22160374 | EF9: =INDIRECT("ZS(-1)",0) * 'Correction factor'!$C$13 -> 30733402 | EG9: =INDIRECT("ZS(-1)",0) + INDIRECT("ZS(-3)",0) -> 9.1686581e+08 | EH9: =INDIRECT("ZS(-1)",0) / INDIRECT("Z6S(-1)",0) -> 0.70095892 | EI9: 840406442 | EJ9: 19919545 | EK9: =INDIRECT("ZS(-1)",0) * 'Correction factor'!$C$13 -> 27625679 | EL9: =INDIRECT("ZS(-1)",0) + INDIRECT("ZS(-3)",0) -> 8.6803212e+08 | EM9: =INDIRECT("ZS(-1)",0) / INDIRECT("Z6S(-1)",0) -> 0.65957732 | EN9: 1006797661 | EO9: 10800682 | EP9: =INDIRECT("ZS(-1)",0) * 'Correction factor'!$C$13 -> 14979066 | EQ9: =INDIRECT("ZS(-1)",0) + INDIRECT("ZS(-3)",0) -> 1.0217767e+09 | ER9: =INDIRECT("ZS(-1)",0) / INDIRECT("Z6S(-1)",0) -> 0.69472329 | ES9: 1029234005 | ET9: 8286166 | EU9: =INDIRECT("ZS(-1)",0) * 'Correction factor'!$C$13 -> 11491777 | EV9: =INDIRECT("ZS(-1)",0) + INDIRECT("ZS(-3)",0) -> 1.0407258e+09 | EW9: =INDIRECT("ZS(-1)",0) / INDIRECT("Z6S(-1)",0) -> 0.71140119 | EX9: 1054165829 | EY9: 8060862 | EZ9: =INDIRECT("ZS(-1)",0) * 'Correction factor'!$C$13 -> 11179311 | FA9: =INDIRECT("ZS(-1)",0) + INDIRECT("ZS(-3)",0) -> 1.0653451e+09 | FB9: =INDIRECT("ZS(-1)",0) / INDIRECT("Z6S(-1)",0) -> 0.75955884 | FC9: 814280744 | FD9: 13570921 | FE9: =INDIRECT("ZS(-1)",0) * 'Correction factor'!$C$13 -> 18821008 | FF9: =INDIRECT("ZS(-1)",0) + INDIRECT("ZS(-3)",0) -> 8.3310175e+08 | FG9: =INDIRECT("ZS(-1)",0) / INDIRECT("Z6S(-1)",0) -> 0.64294179 | FH9: 1314883428 | FI9: 12894317 | FJ9: =INDIRECT("ZS(-1)",0) * 'Correction factor'!$C$13 -> 17882651 | FK9: =INDIRECT("ZS(-1)",0) + INDIRECT("ZS(-3)",0) -> 1.3327661e+09 | FL9: =INDIRECT("ZS(-1)",0) / INDIRECT("Z6S(-1)",0) -> 0.75081248 | FM9: 1048557925 | FN9: 8147498 | FO9: =INDIRECT("ZS(-1)",0) * 'Correction factor'!$C$13 -> 11299463 | FP9: =INDIRECT("ZS(-1)",0) + INDIRECT("ZS(-3)",0) -> 1.0598574e+09 | FQ9: =INDIRECT("ZS(-1)",0) / INDIRECT("Z6S(-1)",0) -> 0.74901359 | FR9: 1002389886 | FS9: 8700896 | FT9: =INDIRECT("ZS(-1)",0) * 'Correction factor'!$C$13 -> 12066950 | FU9: =INDIRECT("ZS(-1)",0) + INDIRECT("ZS(-3)",0) -> 1.0144568e+09 | FV9: =INDIRECT("ZS(-1)",0) / INDIRECT("Z6S(-1)",0) -> 0.70768981 | FW9: 812412444 | FX9: 25185825 | FY9: =INDIRECT("ZS(-1)",0) * 'Correction factor'!$C$13 -> 34929288 | FZ9: =INDIRECT("ZS(-1)",0) + INDIRECT("ZS(-3)",0) -> 8.4734173e+08 | GA9: =INDIRECT("ZS(-1)",0) / INDIRECT("Z6S(-1)",0) -> 0.67999104 | GB9: 913494709 | GC9: 7992426 | GD9: =INDIRECT("ZS(-1)",0) * 'Correction factor'!$C$13 -> 11084400 | GE9: =INDIRECT("ZS(-1)",0) + INDIRECT("ZS(-3)",0) -> 9.2457911e+08 | GF9: =INDIRECT("ZS(-1)",0) / INDIRECT("Z6S(-1)",0) -> 0.64475087 | GG9: 793209919 | GH9: 9507853 | GI9: =INDIRECT("ZS(-1)",0) * 'Correction factor'!$C$13 -> 13186089 | GJ9: =INDIRECT("ZS(-1)",0) + INDIRECT("ZS(-3)",0) -> 8.0639601e+08 | GK9: =INDIRECT("ZS(-1)",0) / INDIRECT("Z6S(-1)",0) -> 0.56229647 | GL9: 941887640 | GM9: 9402168 | GN9: =INDIRECT("ZS(-1)",0) * 'Correction factor'!$C$13 -> 13039519 | GO9: =INDIRECT("ZS(-1)",0) + INDIRECT("ZS(-3)",0) -> 9.5492716e+08 | GP9: =INDIRECT("ZS(-1)",0) / INDIRECT("Z6S(-1)",0) -> 0.65875832 | GQ9: 565295842 | GR9: 7938872 | GS9: =INDIRECT("ZS(-1)",0) * 'Correction factor'!$C$13 -> 11010128 | GT9: =INDIRECT("ZS(-1)",0) + INDIRECT("ZS(-3)",0) -> 5.7630597e+08 | GU9: =INDIRECT("ZS(-1)",0) / INDIRECT("Z6S(-1)",0) -> 0.59756246 | GV9: 934801845 | GW9: 9988261 | GX9: =INDIRECT("ZS(-1)",0) * 'Correction factor'!$C$13 -> 13852349 | GY9: =INDIRECT("ZS(-1)",0) + INDIRECT("ZS(-3)",0) -> 9.4865419e+08 | GZ9: =INDIRECT("ZS(-1)",0) / INDIRECT("Z6S(-1)",0) -> 0.67345571 | HA9: 869053518 | HB9: 11265840 | HC9: =INDIRECT("ZS(-1)",0) * 'Correction factor'!$C$13 -> 15624176 | HD9: =INDIRECT("ZS(-1)",0) + INDIRECT("ZS(-3)",0) -> 8.8467769e+08 | HE9: =INDIRECT("ZS(-1)",0) / INDIRECT("Z6S(-1)",0) -> 0.64791716 | HF9: 1007790161 | HG9: 20288749 | HH9: =INDIRECT("ZS(-1)",0) * 'Correction factor'!$C$13 -> 28137715 | HI9: =INDIRECT("ZS(-1)",0) + INDIRECT("ZS(-3)",0) -> 1.0359279e+09 | HJ9: =INDIRECT("ZS(-1)",0) / INDIRECT("Z6S(-1)",0) -> 0.76309549 | HK9: 796484701 | HL9: 24293157 | HM9: =INDIRECT("ZS(-1)",0) * 'Correction factor'!$C$13 -> 33691280 | HN9: =INDIRECT("ZS(-1)",0) + INDIRECT("ZS(-3)",0) -> 8.3017598e+08 | HO9: =INDIRECT("ZS(-1)",0) / INDIRECT("Z6S(-1)",0) -> 0.61801977 | HP9: 1018332044 | HQ9: 7215959 | HR9: =INDIRECT("ZS(-1)",0) * 'Correction factor'!$C$13 -> 10007546 | HS9: =INDIRECT("ZS(-1)",0) + INDIRECT("ZS(-3)",0) -> 1.0283396e+09 | HT9: =INDIRECT("ZS(-1)",0) / INDIRECT("Z6S(-1)",0) -> 0.6666648 | HU9: 920901443 | HV9: 9561891 | HW9: =INDIRECT("ZS(-1)",0) * 'Correction factor'!$C$13 -> 13261033 | HX9: =INDIRECT("ZS(-1)",0) + INDIRECT("ZS(-3)",0) -> 9.3416248e+08 | HY9: =INDIRECT("ZS(-1)",0) / INDIRECT("Z6S(-1)",0) -> 0.73304034 | HZ9: 846016303 | IA9: 18269655 | IB9: =INDIRECT("ZS(-1)",0) * 'Correction factor'!$C$13 -> 25337508 | IC9: =INDIRECT("ZS(-1)",0) + INDIRECT("ZS(-3)",0) -> 8.7135381e+08 | ID9: =INDIRECT("ZS(-1)",0) / INDIRECT("Z6S(-1)",0) -> 0.67567634 | IE9: 1017327810 | IF9: 8197961 | IG9: =INDIRECT("ZS(-1)",0) * 'Correction factor'!$C$13 -> 11369448 | IH9: =INDIRECT("ZS(-1)",0) + INDIRECT("ZS(-3)",0) -> 1.0286973e+09 | II9: =INDIRECT("ZS(-1)",0) / INDIRECT("Z6S(-1)",0) -> 0.78717115
