Workbook

Sheet Plate 1
B1: Cell proportions (a2/a4)
B2: Treatment | D2: Mixed No treatment | AH2: Mixed MTD | BL2: Mixed AT100 | FR2: Mixed A80 | JX2: Mixed AT50 | OD2: Mixed Intermittent | PH2: Pure Red No treatment | QL2: Pure Red MTD
B3: Well | D3: A1 | I3: A2 | N3: A3 | S3: A4 | X3: A5 | AC3: A6 | AH3: A7 | AM3: A8 | AR3: A9 | AW3: A10 | BB3: A11 | BG3: A12 | BL3: B1 | BQ3: B2 | BV3: B3 | CA3: B4 | CF3: B5 | CK3: B6 | CP3: B7 | CU3: B8 | CZ3: B9 | DE3: B10 | DJ3: B11 | DO3: C1 | DT3: C2 | DY3: C3 | ED3: C4 | EI3: C5 | EN3: C6 | ES3: C7 | EX3: C8 | FC3: C9 | FH3: C10 | FM3: C11 | FR3: D1 | FW3: D2 | GB3: D3 | GG3: D4 | GL3: D5 | GQ3: D6 | GV3: D7 | HA3: D8 | HF3: D9 | HK3: D10 | HP3: D11 | HU3: E1 | HZ3: E2 | IE3: E3 | IJ3: E4 | IO3: E5 | IT3: E6 | IY3: E7 | JD3: E8 | JI3: E9 | JN3: E10 | JS3: E11 | JX3: F1 | KC3: F2 | KH3: F3 | KM3: F4 | KR3: F5 | KW3: F6 | LB3: F7 | LG3: F8 | LL3: F9 | LQ3: F10 | LV3: F11 | MA3: G1 | MF3: G2 | MK3: G3 | MP3: G4 | MU3: G5 | MZ3: G6 | NE3: G7 | NJ3: G8 | NO3: G9 | NT3: G10 | NY3: G11 | OD3: B12 | OI3: C12 | ON3: D12 | OS3: E12 | OX3: F12 | PC3: G12 | PH3: H1 | PM3: H2 | PR3: H3 | PW3: H4 | QB3: H5 | QG3: H6 | QL3: H7 | QQ3: H8 | QV3: H9 | RA3: H10 | RF3: H11 | RK3: H12
A4: d | B4: colour | D4: g | E4: r | F4: r' | G4: t | I4: g | J4: r | K4: r' | L4: t | N4: g | O4: r | P4: r' | Q4: t | S4: g | T4: r | U4: r' | V4: t | X4: g | Y4: r | Z4: r' | AA4: t | AC4: g | AD4: r | AE4: r' | AF4: t | AH4: g | AI4: r | AJ4: r' | AK4: t | AM4: g | AN4: r | AO4: r' | AP4: t | AR4: g | AS4: r | AT4: r' | AU4: t | AW4: g | AX4: r | AY4: r' | AZ4: t | BB4: g | BC4: r | BD4: r' | BE4: t | BG4: g | BH4: r | BI4: r' | BJ4: t | BL4: g | BM4: r | BN4: r' | BO4: t | BQ4: g | BR4: r | BS4: r' | BT4: t | BV4: g | BW4: r | BX4: r' | BY4: t | CA4: g | CB4: r | CC4: r' | CD4: t | CF4: g | CG4: r | CH4: r' | CI4: t | CK4: g | CL4: r | CM4: r' | CN4: t | CP4: g | CQ4: r | CR4: r' | CS4: t | CU4: g | CV4: r | CW4: r' | CX4: t | CZ4: g | DA4: r | DB4: r' | DC4: t | DE4: g | DF4: r | DG4: r' | DH4: t | DJ4: g | DK4: r | DL4: r' | DM4: t | DO4: g | DP4: r | DQ4: r' | DR4: t | DT4: g | DU4: r | DV4: r' | DW4: t | DY4: g | DZ4: r | EA4: r' | EB4: t | ED4: g | EE4: r | EF4: r' | EG4: t | EI4: g | EJ4: r | EK4: r' | EL4: t | EN4: g | EO4: r | EP4: r' | EQ4: t | ES4: g | ET4: r | EU4: r' | EV4: t | EX4: g | EY4: r | EZ4: r' | FA4: t | FC4: g | FD4: r | FE4: r' | FF4: t | FH4: g | FI4: r | FJ4: r' | FK4: t | FM4: g | FN4: r | FO4: r' | FP4: t | FR4: g | FS4: r | FT4: r' | FU4: t | FW4: g | FX4: r | FY4: r' | FZ4: t | GB4: g | GC4: r | GD4: r' | GE4: t | GG4: g | GH4: r | GI4: r' | GJ4: t | GL4: g | GM4: r | GN4: r' | GO4: t | GQ4: g | GR4: r | GS4: r' | GT4: t | GV4: g | GW4: r | GX4: r' | GY4: t | HA4: g | HB4: r | HC4: r' | HD4: t | HF4: g | HG4: r | HH4: r' | HI4: t | HK4: g | HL4: r | HM4: r' | HN4: t | HP4: g | HQ4: r | HR4: r' | HS4: t | HU4: g | HV4: r | HW4: r' | HX4: t | HZ4: g | IA4: r | IB4: r' | IC4: t | IE4: g | IF4: r | IG4: r' | IH4: t | IJ4: g | IK4: r | IL4: r' | IM4: t | IO4: g | IP4: r | IQ4: r' | IR4: t | IT4: g | IU4: r | IV4: r' | IW4: t | IY4: g | IZ4: r | JA4: r' | JB4: t | JD4: g | JE4: r | JF4: r' | JG4: t | JI4: g | JJ4: r | JK4: r' | JL4: t | JN4: g | JO4: r | JP4: r' | JQ4: t | JS4: g | JT4: r | JU4: r' | JV4: t | JX4: g | JY4: r | JZ4: r' | KA4: t | KC4: g | KD4: r | KE4: r' | KF4: t | KH4: g | KI4: r | KJ4: r' | KK4: t | KM4: g | KN4: r | KO4: r' | KP4: t | KR4: g | KS4: r | KT4: r' | KU4: t | KW4: g | KX4: r | KY4: r' | KZ4: t | LB4: g | LC4: r | LD4: r' | LE4: t | LG4: g | LH4: r | LI4: r' | LJ4: t | LL4: g | LM4: r | LN4: r' | LO4: t | LQ4: g | LR4: r | LS4: r' | LT4: t | LV4: g | LW4: r | LX4: r' | LY4: t | MA4: g | MB4: r | MC4: r' | MD4: t | MF4: g | MG4: r | MH4: r' | MI4: t | MK4: g | ML4: r | MM4: r' | MN4: t | MP4: g | MQ4: r | MR4: r' | MS4: t | MU4: g | MV4: r | MW4: r' | MX4: t | MZ4: g | NA4: r | NB4: r' | NC4: t | NE4: g | NF4: r | NG4: r' | NH4: t | NJ4: g | NK4: r | NL4: r' | NM4: t | NO4: g | NP4: r | NQ4: r' | NR4: t | NT4: g | NU4: r | NV4: r' | NW4: t | NY4: g | NZ4: r | OA4: r' | OB4: t | OD4: g | OE4: r | OF4: r' | OG4: t | OI4: g | OJ4: r | OK4: r' | OL4: t | ON4: g | OO4: r | OP4: r' | OQ4: t | OS4: g | OT4: r | OU4: r' | OV4: t | OX4: g | OY4: r | OZ4: r' | PA4: t | PC4: g | PD4: r | PE4: r' | PF4: t | PH4: g | PI4: r | PJ4: r' | PK4: t | PM4: g | PN4: r | PO4: r' | PP4: t | PR4: g | PS4: r | PT4: r' | PU4: t | PW4: g | PX4: r | PY4: r' | PZ4: t | QB4: g | QC4: r | QD4: r' | QE4: t | QG4: g | QH4: r | QI4: r' | QJ4: t | QL4: g | QM4: r | QN4: r' | QO4: t | QQ4: g | QR4: r | QS4: r' | QT4: t | QV4: g | QW4: r | QX4: r' | QY4: t | RA4: g | RB4: r | RC4: r' | RD4: t | RF4: g | RG4: r | RH4: r' | RI4: t | RK4: g | RL4: r | RM4: r' | RN4: t
A5: -2 | B5: 45467 | C5: Monday | D5: 884242256 | E5: 61803397 | F5: =INDIRECT("ZS(-1)",0) * 'Correction factor'!$C$13 -> 95653997 | G5: =INDIRECT("ZS(-1)",0) + INDIRECT("ZS(-3)",0) -> 9.7989625e+08 | H5: =INDIRECT("ZS(-1)",0) / INDIRECT("Z7S(-1)",0) -> 0.65550466 | I5: 886240217 | J5: 64265025 | K5: =INDIRECT("ZS(-1)",0) * 'Correction factor'!$C$13 -> 99463894 | L5: =INDIRECT("ZS(-1)",0) + INDIRECT("ZS(-3)",0) -> 9.8570411e+08 | M5: =INDIRECT("ZS(-1)",0) / INDIRECT("Z7S(-1)",0) -> 0.71671202 | N5: 903576841 | O5: 64996274 | P5: =INDIRECT("ZS(-1)",0) * 'Correction factor'!$C$13 -> 1.0059566e+08 | Q5: =INDIRECT("ZS(-1)",0) + INDIRECT("ZS(-3)",0) -> 1.0041725e+09 | R5: =INDIRECT("ZS(-1)",0) / INDIRECT("Z7S(-1)",0) -> 0.70182278 | S5: 786268876 | T5: 68469369 | U5: =INDIRECT("ZS(-1)",0) * 'Correction factor'!$C$13 -> 1.0597102e+08 | V5: =INDIRECT("ZS(-1)",0) + INDIRECT("ZS(-3)",0) -> 8.9223989e+08 | W5: =INDIRECT("ZS(-1)",0) / INDIRECT("Z7S(-1)",0) -> 0.63969467 | X5: 830034401 | Y5: 64758193 | Z5: =INDIRECT("ZS(-1)",0) * 'Correction factor'!$C$13 -> 1.0022718e+08 | AA5: =INDIRECT("ZS(-1)",0) + INDIRECT("ZS(-3)",0) -> 9.3026158e+08 | AB5: =INDIRECT("ZS(-1)",0) / INDIRECT("Z7S(-1)",0) -> 0.63839351 | AC5: 813649774 | AD5: 68642082 | AE5: =INDIRECT("ZS(-1)",0) * 'Correction factor'!$C$13 -> 1.0623833e+08 | AF5: =INDIRECT("ZS(-1)",0) + INDIRECT("ZS(-3)",0) -> 9.198881e+08 | AG5: =INDIRECT("ZS(-1)",0) / INDIRECT("Z7S(-1)",0) -> 0.6254288 | AH5: 906167595 | AI5: 65425629 | AJ5: =INDIRECT("ZS(-1)",0) * 'Correction factor'!$C$13 -> 1.0126018e+08 | AK5: =INDIRECT("ZS(-1)",0) + INDIRECT("ZS(-3)",0) -> 1.0074278e+09 | AL5: =INDIRECT("ZS(-1)",0) / INDIRECT("Z7S(-1)",0) -> 0.75109467 | AM5: 854683302 | AN5: 67568614 | AO5: =INDIRECT("ZS(-1)",0) * 'Correction factor'!$C$13 -> 1.0457691e+08 | AP5: =INDIRECT("ZS(-1)",0) + INDIRECT("ZS(-3)",0) -> 9.5926021e+08 | AQ5: =INDIRECT("ZS(-1)",0) / INDIRECT("Z7S(-1)",0) -> 0.67082125 | AR5: 827146490 | AS5: 69390660 | AT5: =INDIRECT("ZS(-1)",0) * 'Correction factor'!$C$13 -> 1.0739691e+08 | AU5: =INDIRECT("ZS(-1)",0) + INDIRECT("ZS(-3)",0) -> 9.345434e+08 | AV5: =INDIRECT("ZS(-1)",0) / INDIRECT("Z7S(-1)",0) -> 0.62579285 | AW5: 829157726 | AX5: 71170260 | AY5: =INDIRECT("ZS(-1)",0) * 'Correction factor'!$C$13 -> 1.1015122e+08 | AZ5: =INDIRECT("ZS(-1)",0) + INDIRECT("ZS(-3)",0) -> 9.3930895e+08 | BA5: =INDIRECT("ZS(-1)",0) / INDIRECT("Z7S(-1)",0) -> 0.69843275 | BB5: 879000523 | BC5: 63345841 | BD5: =INDIRECT("ZS(-1)",0) * 'Correction factor'!$C$13 -> 98041260 | BE5: =INDIRECT("ZS(-1)",0) + INDIRECT("ZS(-3)",0) -> 9.7704178e+08 | BF5: =INDIRECT("ZS(-1)",0) / INDIRECT("Z7S(-1)",0) -> 0.73162764 | BG5: 940216336 | BH5: 66468774 | BI5: =INDIRECT("ZS(-1)",0) * 'Correction factor'!$C$13 -> 1.0287467e+08 | BJ5: =INDIRECT("ZS(-1)",0) + INDIRECT("ZS(-3)",0) -> 1.043091e+09 | BK5: =INDIRECT("ZS(-1)",0) / INDIRECT("Z7S(-1)",0) -> 0.73473294 | BL5: 858699549 | BM5: 67459082 | BN5: =INDIRECT("ZS(-1)",0) * 'Correction factor'!$C$13 -> 1.0440738e+08 | BO5: =INDIRECT("ZS(-1)",0) + INDIRECT("ZS(-3)",0) -> 9.6310693e+08 | BP5: =INDIRECT("ZS(-1)",0) / INDIRECT("Z7S(-1)",0) -> 0.70011531 | BQ5: 896671553 | BR5: 65639269 | BS5: =INDIRECT("ZS(-1)",0) * 'Correction factor'!$C$13 -> 1.0159083e+08 | BT5: =INDIRECT("ZS(-1)",0) + INDIRECT("ZS(-3)",0) -> 9.9826238e+08 | BU5: =INDIRECT("ZS(-1)",0) / INDIRECT("Z7S(-1)",0) -> 0.73594405 | BV5: 854991426 | BW5: 65921306 | BX5: =INDIRECT("ZS(-1)",0) * 'Correction factor'!$C$13 -> 1.0202734e+08 | BY5: =INDIRECT("ZS(-1)",0) + INDIRECT("ZS(-3)",0) -> 9.5701877e+08 | BZ5: =INDIRECT("ZS(-1)",0) / INDIRECT("Z7S(-1)",0) -> 0.71048047 | CA5: 836277170 | CB5: 65625039 | CC5: =INDIRECT("ZS(-1)",0) * 'Correction factor'!$C$13 -> 1.0156881e+08 | CD5: =INDIRECT("ZS(-1)",0) + INDIRECT("ZS(-3)",0) -> 9.3784598e+08 | CE5: =INDIRECT("ZS(-1)",0) / INDIRECT("Z7S(-1)",0) -> 0.67264758 | CF5: 936307183 | CG5: 67347981 | CH5: =INDIRECT("ZS(-1)",0) * 'Correction factor'!$C$13 -> 1.0423543e+08 | CI5: =INDIRECT("ZS(-1)",0) + INDIRECT("ZS(-3)",0) -> 1.0405426e+09 | CJ5: =INDIRECT("ZS(-1)",0) / INDIRECT("Z7S(-1)",0) -> 0.71539219 | CK5: 817642625 | CL5: 65141768 | CM5: =INDIRECT("ZS(-1)",0) * 'Correction factor'!$C$13 -> 1.0082084e+08 | CN5: =INDIRECT("ZS(-1)",0) + INDIRECT("ZS(-3)",0) -> 9.1846347e+08 | CO5: =INDIRECT("ZS(-1)",0) / INDIRECT("Z7S(-1)",0) -> 0.69701771 | CP5: 820620088 | CQ5: 67368659 | CR5: =INDIRECT("ZS(-1)",0) * 'Correction factor'!$C$13 -> 1.0426743e+08 | CS5: =INDIRECT("ZS(-1)",0) + INDIRECT("ZS(-3)",0) -> 9.2488752e+08 | CT5: =INDIRECT("ZS(-1)",0) / INDIRECT("Z7S(-1)",0) -> 0.67975011 | CU5: 886411324 | CV5: 66583848 | CW5: =INDIRECT("ZS(-1)",0) * 'Correction factor'!$C$13 -> 1.0305277e+08 | CX5: =INDIRECT("ZS(-1)",0) + INDIRECT("ZS(-3)",0) -> 9.8946409e+08 | CY5: =INDIRECT("ZS(-1)",0) / INDIRECT("Z7S(-1)",0) -> 0.69160224 | CZ5: 848254040 | DA5: 69446194 | DB5: =INDIRECT("ZS(-1)",0) * 'Correction factor'!$C$13 -> 1.0748286e+08 | DC5: =INDIRECT("ZS(-1)",0) + INDIRECT("ZS(-3)",0) -> 9.557369e+08 | DD5: =INDIRECT("ZS(-1)",0) / INDIRECT("Z7S(-1)",0) -> 0.67181553 | DE5: 902390144 | DF5: 70599049 | DG5: =INDIRECT("ZS(-1)",0) * 'Correction factor'!$C$13 -> 1.0926715e+08 | DH5: =INDIRECT("ZS(-1)",0) + INDIRECT("ZS(-3)",0) -> 1.0116573e+09 | DI5: =INDIRECT("ZS(-1)",0) / INDIRECT("Z7S(-1)",0) -> 0.7430619 | DJ5: 942309002 | DK5: 65505446 | DL5: =INDIRECT("ZS(-1)",0) * 'Correction factor'!$C$13 -> 1.0138371e+08 | DM5: =INDIRECT("ZS(-1)",0) + INDIRECT("ZS(-3)",0) -> 1.0436927e+09 | DN5: =INDIRECT("ZS(-1)",0) / INDIRECT("Z7S(-1)",0) -> 0.67821328 | DO5: 845259955 | DP5: 67252782 | DQ5: =INDIRECT("ZS(-1)",0) * 'Correction factor'!$C$13 -> 1.0408809e+08 | DR5: =INDIRECT("ZS(-1)",0) + INDIRECT("ZS(-3)",0) -> 9.4934804e+08 | DS5: =INDIRECT("ZS(-1)",0) / INDIRECT("Z7S(-1)",0) -> 0.66347723 | DT5: 857370657 | DU5: 66981782 | DV5: =INDIRECT("ZS(-1)",0) * 'Correction factor'!$C$13 -> 1.0366866e+08 | DW5: =INDIRECT("ZS(-1)",0) + INDIRECT("ZS(-3)",0) -> 9.6103931e+08 | DX5: =INDIRECT("ZS(-1)",0) / INDIRECT("Z7S(-1)",0) -> 0.71478101 | DY5: 815334507 | DZ5: 62689223 | EA5: =INDIRECT("ZS(-1)",0) * 'Correction factor'!$C$13 -> 97025003 | EB5: =INDIRECT("ZS(-1)",0) + INDIRECT("ZS(-3)",0) -> 9.1235951e+08 | EC5: =INDIRECT("ZS(-1)",0) / INDIRECT("Z7S(-1)",0) -> 0.71334305 | ED5: 881331825 | EE5: 64579754 | EF5: =INDIRECT("ZS(-1)",0) * 'Correction factor'!$C$13 -> 99951004 | EG5: =INDIRECT("ZS(-1)",0) + INDIRECT("ZS(-3)",0) -> 9.8128283e+08 | EH5: =INDIRECT("ZS(-1)",0) / INDIRECT("Z7S(-1)",0) -> 0.69905065 | EI5: 829185115 | EJ5: 63440234 | EK5: =INDIRECT("ZS(-1)",0) * 'Correction factor'!$C$13 -> 98187353 | EL5: =INDIRECT("ZS(-1)",0) + INDIRECT("ZS(-3)",0) -> 9.2737247e+08 | EM5: =INDIRECT("ZS(-1)",0) / INDIRECT("Z7S(-1)",0) -> 0.72824177 | EN5: 909473729 | EO5: 63330877 | EP5: =INDIRECT("ZS(-1)",0) * 'Correction factor'!$C$13 -> 98018100 | EQ5: =INDIRECT("ZS(-1)",0) + INDIRECT("ZS(-3)",0) -> 1.0074918e+09 | ER5: =INDIRECT("ZS(-1)",0) / INDIRECT("Z7S(-1)",0) -> 0.71129067 | ES5: 924839594 | ET5: 61825302 | EU5: =INDIRECT("ZS(-1)",0) * 'Correction factor'!$C$13 -> 95687900 | EV5: =INDIRECT("ZS(-1)",0) + INDIRECT("ZS(-3)",0) -> 1.0205275e+09 | EW5: =INDIRECT("ZS(-1)",0) / INDIRECT("Z7S(-1)",0) -> 0.70805901 | EX5: 861876934 | EY5: 64933089 | EZ5: =INDIRECT("ZS(-1)",0) * 'Correction factor'!$C$13 -> 1.0049787e+08 | FA5: =INDIRECT("ZS(-1)",0) + INDIRECT("ZS(-3)",0) -> 9.623748e+08 | FB5: =INDIRECT("ZS(-1)",0) / INDIRECT("Z7S(-1)",0) -> 0.69782069 | FC5: 866429964 | FD5: 65664965 | FE5: =INDIRECT("ZS(-1)",0) * 'Correction factor'!$C$13 -> 1.016306e+08 | FF5: =INDIRECT("ZS(-1)",0) + INDIRECT("ZS(-3)",0) -> 9.6806056e+08 | FG5: =INDIRECT("ZS(-1)",0) / INDIRECT("Z7S(-1)",0) -> 0.73531217 | FH5: 895410183 | FI5: 65533358 | FJ5: =INDIRECT("ZS(-1)",0) * 'Correction factor'!$C$13 -> 1.0142691e+08 | FK5: =INDIRECT("ZS(-1)",0) + INDIRECT("ZS(-3)",0) -> 9.9683709e+08 | FL5: =INDIRECT("ZS(-1)",0) / INDIRECT("Z7S(-1)",0) -> 0.72512183 | FM5: 908737219 | FN5: 65151011 | FO5: =INDIRECT("ZS(-1)",0) * 'Correction factor'!$C$13 -> 1.0083515e+08 | FP5: =INDIRECT("ZS(-1)",0) + INDIRECT("ZS(-3)",0) -> 1.0095724e+09 | FQ5: =INDIRECT("ZS(-1)",0) / INDIRECT("Z7S(-1)",0) -> 0.72792517 | FR5: 814451431 | FS5: 64650031 | FT5: =INDIRECT("ZS(-1)",0) * 'Correction factor'!$C$13 -> 1.0005977e+08 | FU5: =INDIRECT("ZS(-1)",0) + INDIRECT("ZS(-3)",0) -> 9.145112e+08 | FV5: =INDIRECT("ZS(-1)",0) / INDIRECT("Z7S(-1)",0) -> 0.63385262 | FW5: 846276310 | FX5: 67408640 | FY5: =INDIRECT("ZS(-1)",0) * 'Correction factor'!$C$13 -> 1.0432931e+08 | FZ5: =INDIRECT("ZS(-1)",0) + INDIRECT("ZS(-3)",0) -> 9.5060562e+08 | GA5: =INDIRECT("ZS(-1)",0) / INDIRECT("Z7S(-1)",0) -> 0.71014403 | GB5: 842644199 | GC5: 63093704 | GD5: =INDIRECT("ZS(-1)",0) * 'Correction factor'!$C$13 -> 97651024 | GE5: =INDIRECT("ZS(-1)",0) + INDIRECT("ZS(-3)",0) -> 9.4029522e+08 | GF5: =INDIRECT("ZS(-1)",0) / INDIRECT("Z7S(-1)",0) -> 0.68863829 | GG5: 806935967 | GH5: 63533186 | GI5: =INDIRECT("ZS(-1)",0) * 'Correction factor'!$C$13 -> 98331216 | GJ5: =INDIRECT("ZS(-1)",0) + INDIRECT("ZS(-3)",0) -> 9.0526718e+08 | GK5: =INDIRECT("ZS(-1)",0) / INDIRECT("Z7S(-1)",0) -> 0.6898152 | GL5: 872088920 | GM5: 64697748 | GN5: =INDIRECT("ZS(-1)",0) * 'Correction factor'!$C$13 -> 1.0013363e+08 | GO5: =INDIRECT("ZS(-1)",0) + INDIRECT("ZS(-3)",0) -> 9.7222255e+08 | GP5: =INDIRECT("ZS(-1)",0) / INDIRECT("Z7S(-1)",0) -> 0.69861574 | GQ5: 850602730 | GR5: 65373839 | GS5: =INDIRECT("ZS(-1)",0) * 'Correction factor'!$C$13 -> 1.0118002e+08 | GT5: =INDIRECT("ZS(-1)",0) + INDIRECT("ZS(-3)",0) -> 9.5178275e+08 | GU5: =INDIRECT("ZS(-1)",0) / INDIRECT("Z7S(-1)",0) -> 0.73795081 | GV5: 838462679 | GW5: 63474182 | GX5: =INDIRECT("ZS(-1)",0) * 'Correction factor'!$C$13 -> 98239895 | GY5: =INDIRECT("ZS(-1)",0) + INDIRECT("ZS(-3)",0) -> 9.3670257e+08 | GZ5: =INDIRECT("ZS(-1)",0) / INDIRECT("Z7S(-1)",0) -> 0.68649509 | HA5: 840657682 | HB5: 64996544 | HC5: =INDIRECT("ZS(-1)",0) * 'Correction factor'!$C$13 -> 1.0059608e+08 | HD5: =INDIRECT("ZS(-1)",0) + INDIRECT("ZS(-3)",0) -> 9.4125376e+08 | HE5: =INDIRECT("ZS(-1)",0) / INDIRECT("Z7S(-1)",0) -> 0.70757223 | HF5: 867954730 | HG5: 64578704 | HH5: =INDIRECT("ZS(-1)",0) * 'Correction factor'!$C$13 -> 99949379 | HI5: =INDIRECT("ZS(-1)",0) + INDIRECT("ZS(-3)",0) -> 9.6790411e+08 | HJ5: =INDIRECT("ZS(-1)",0) / INDIRECT("Z7S(-1)",0) -> 0.69936823 | HK5: 841674217 | HL5: 64204143 | HM5: =INDIRECT("ZS(-1)",0) * 'Correction factor'!$C$13 -> 99369666 | HN5: =INDIRECT("ZS(-1)",0) + INDIRECT("ZS(-3)",0) -> 9.4104388e+08 | HO5: =INDIRECT("ZS(-1)",0) / INDIRECT("Z7S(-1)",0) -> 0.69626906 | HP5: 854069273 | HQ5: 64993423 | HR5: =INDIRECT("ZS(-1)",0) * 'Correction factor'!$C$13 -> 1.0059125e+08 | HS5: =INDIRECT("ZS(-1)",0) + INDIRECT("ZS(-3)",0) -> 9.5466052e+08 | HT5: =INDIRECT("ZS(-1)",0) / INDIRECT("Z7S(-1)",0) -> 0.71963132 | HU5: 880295813 | HV5: 64839484 | HW5: =INDIRECT("ZS(-1)",0) * 'Correction factor'!$C$13 -> 1.0035299e+08 | HX5: =INDIRECT("ZS(-1)",0) + INDIRECT("ZS(-3)",0) -> 9.8064881e+08 | HY5: =INDIRECT("ZS(-1)",0) / INDIRECT("Z7S(-1)",0) -> 0.66788558 | HZ5: 787259547 | IA5: 60945696 | IB5: =INDIRECT("ZS(-1)",0) * 'Correction factor'!$C$13 -> 94326521 | IC5: =INDIRECT("ZS(-1)",0) + INDIRECT("ZS(-3)",0) -> 8.8158607e+08 | ID5: =INDIRECT("ZS(-1)",0) / INDIRECT("Z7S(-1)",0) -> 0.68261703 | IE5: 836997165 | IF5: 62515402 | IG5: =INDIRECT("ZS(-1)",0) * 'Correction factor'!$C$13 -> 96755977 | IH5: =INDIRECT("ZS(-1)",0) + INDIRECT("ZS(-3)",0) -> 9.3375314e+08 | II5: =INDIRECT("ZS(-1)",0) / INDIRECT("Z7S(-1)",0) -> 0.66976153 | IJ5: 833623170 | IK5: 63887473 | IL5: =INDIRECT("ZS(-1)",0) * 'Correction factor'!$C$13 -> 98879551 | IM5: =INDIRECT("ZS(-1)",0) + INDIRECT("ZS(-3)",0) -> 9.3250272e+08 | IN5: =INDIRECT("ZS(-1)",0) / INDIRECT("Z7S(-1)",0) -> 0.69830036 | IO5: 827100127 | IP5: 65541343 | IQ5: =INDIRECT("ZS(-1)",0) * 'Correction factor'!$C$13 -> 1.0143927e+08 | IR5: =INDIRECT("ZS(-1)",0) + INDIRECT("ZS(-3)",0) -> 9.285394e+08 | IS5: =INDIRECT("ZS(-1)",0) / INDIRECT("Z7S(-1)",0) -> 0.69279123 | IT5: 790933067 | IU5: 64505356 | IV5: =INDIRECT("ZS(-1)",0) * 'Correction factor'!$C$13 -> 99835857 | IW5: =INDIRECT("ZS(-1)",0) + INDIRECT("ZS(-3)",0) -> 8.9076892e+08 | IX5: =INDIRECT("ZS(-1)",0) / INDIRECT("Z7S(-1)",0) -> 0.69537661 | IY5: 811303835 | IZ5: 63606269 | JA5: =INDIRECT("ZS(-1)",0) * 'Correction factor'!$C$13 -> 98444328 | JB5: =INDIRECT("ZS(-1)",0) + INDIRECT("ZS(-3)",0) -> 9.0974816e+08 | JC5: =INDIRECT("ZS(-1)",0) / INDIRECT("Z7S(-1)",0) -> 0.68037012 | JD5: 826579214 | JE5: 63632319 | JF5: =INDIRECT("ZS(-1)",0) * 'Correction factor'!$C$13 -> 98484646 | JG5: =INDIRECT("ZS(-1)",0) + INDIRECT("ZS(-3)",0) -> 9.2506386e+08 | JH5: =INDIRECT("ZS(-1)",0) / INDIRECT("Z7S(-1)",0) -> 0.65865022 | JI5: 759785851 | JJ5: 62473904 | JK5: =INDIRECT("ZS(-1)",0) * 'Correction factor'!$C$13 -> 96691750 | JL5: =INDIRECT("ZS(-1)",0) + INDIRECT("ZS(-3)",0) -> 8.564776e+08 | JM5: =INDIRECT("ZS(-1)",0) / INDIRECT("Z7S(-1)",0) -> 0.66717886 | JN5: 843387502 | JO5: 62728616 | JP5: =INDIRECT("ZS(-1)",0) * 'Correction factor'!$C$13 -> 97085972 | JQ5: =INDIRECT("ZS(-1)",0) + INDIRECT("ZS(-3)",0) -> 9.4047347e+08 | JR5: =INDIRECT("ZS(-1)",0) / INDIRECT("Z7S(-1)",0) -> 0.71475864 | JS5: 818088431 | JT5: 64303646 | JU5: =INDIRECT("ZS(-1)",0) * 'Correction factor'!$C$13 -> 99523668 | JV5: =INDIRECT("ZS(-1)",0) + INDIRECT("ZS(-3)",0) -> 9.176121e+08 | JW5: =INDIRECT("ZS(-1)",0) / INDIRECT("Z7S(-1)",0) -> 0.69799191 | JX5: 830460670 | JY5: 64198240 | JZ5: =INDIRECT("ZS(-1)",0) * 'Correction factor'!$C$13 -> 99360530 | KA5: =INDIRECT("ZS(-1)",0) + INDIRECT("ZS(-3)",0) -> 9.298212e+08 | KB5: =INDIRECT("ZS(-1)",0) / INDIRECT("Z7S(-1)",0) -> 0.63697815 | KC5: 825785550 | KD5: 56167111 | KE5: =INDIRECT("ZS(-1)",0) * 'Correction factor'!$C$13 -> 86930637 | KF5: =INDIRECT("ZS(-1)",0) + INDIRECT("ZS(-3)",0) -> 9.1271619e+08 | KG5: =INDIRECT("ZS(-1)",0) / INDIRECT("Z7S(-1)",0) -> 0.65938616 | KH5: 854072911 | KI5: 62626464 | KJ5: =INDIRECT("ZS(-1)",0) * 'Correction factor'!$C$13 -> 96927870 | KK5: =INDIRECT("ZS(-1)",0) + INDIRECT("ZS(-3)",0) -> 9.5100078e+08 | KL5: =INDIRECT("ZS(-1)",0) / INDIRECT("Z7S(-1)",0) -> 0.67561425 | KM5: 755465941 | KN5: 62012312 | KO5: =INDIRECT("ZS(-1)",0) * 'Correction factor'!$C$13 -> 95977338 | KP5: =INDIRECT("ZS(-1)",0) + INDIRECT("ZS(-3)",0) -> 8.5144328e+08 | KQ5: =INDIRECT("ZS(-1)",0) / INDIRECT("Z7S(-1)",0) -> 0.66438978 | KR5: 892298086 | KS5: 62708272 | KT5: =INDIRECT("ZS(-1)",0) * 'Correction factor'!$C$13 -> 97054485 | KU5: =INDIRECT("ZS(-1)",0) + INDIRECT("ZS(-3)",0) -> 9.8935257e+08 | KV5: =INDIRECT("ZS(-1)",0) / INDIRECT("Z7S(-1)",0) -> 0.68812395 | KW5: 855966243 | KX5: 61522387 | KY5: =INDIRECT("ZS(-1)",0) * 'Correction factor'!$C$13 -> 95219074 | KZ5: =INDIRECT("ZS(-1)",0) + INDIRECT("ZS(-3)",0) -> 9.5118532e+08 | LA5: =INDIRECT("ZS(-1)",0) / INDIRECT("Z7S(-1)",0) -> 0.66070799 | LB5: 819194153 | LC5: 65036422 | LD5: =INDIRECT("ZS(-1)",0) * 'Correction factor'!$C$13 -> 1.006578e+08 | LE5: =INDIRECT("ZS(-1)",0) + INDIRECT("ZS(-3)",0) -> 9.1985195e+08 | LF5: =INDIRECT("ZS(-1)",0) / INDIRECT("Z7S(-1)",0) -> 0.68972749 | LG5: 824137963 | LH5: 61480942 | LI5: =INDIRECT("ZS(-1)",0) * 'Correction factor'!$C$13 -> 95154929 | LJ5: =INDIRECT("ZS(-1)",0) + INDIRECT("ZS(-3)",0) -> 9.1929289e+08 | LK5: =INDIRECT("ZS(-1)",0) / INDIRECT("Z7S(-1)",0) -> 0.72162822 | LL5: 826214505 | LM5: 61054656 | LN5: =INDIRECT("ZS(-1)",0) * 'Correction factor'!$C$13 -> 94495160 | LO5: =INDIRECT("ZS(-1)",0) + INDIRECT("ZS(-3)",0) -> 9.2070966e+08 | LP5: =INDIRECT("ZS(-1)",0) / INDIRECT("Z7S(-1)",0) -> 0.65655253 | LQ5: 842489340 | LR5: 63698127 | LS5: =INDIRECT("ZS(-1)",0) * 'Correction factor'!$C$13 -> 98586498 | LT5: =INDIRECT("ZS(-1)",0) + INDIRECT("ZS(-3)",0) -> 9.4107584e+08 | LU5: =INDIRECT("ZS(-1)",0) / INDIRECT("Z7S(-1)",0) -> 0.66563175 | LV5: 818509403 | LW5: 64478511 | LX5: =INDIRECT("ZS(-1)",0) * 'Correction factor'!$C$13 -> 99794309 | LY5: =INDIRECT("ZS(-1)",0) + INDIRECT("ZS(-3)",0) -> 9.1830371e+08 | LZ5: =INDIRECT("ZS(-1)",0) / INDIRECT("Z7S(-1)",0) -> 0.66557701 | MA5: 843125139 | MB5: 65448736 | MC5: =INDIRECT("ZS(-1)",0) * 'Correction factor'!$C$13 -> 1.0129594e+08 | MD5: =INDIRECT("ZS(-1)",0) + INDIRECT("ZS(-3)",0) -> 9.4442108e+08 | ME5: =INDIRECT("ZS(-1)",0) / INDIRECT("Z7S(-1)",0) -> 0.67008636 | MF5: 919719736 | MG5: 63168412 | MH5: =INDIRECT("ZS(-1)",0) * 'Correction factor'!$C$13 -> 97766650 | MI5: =INDIRECT("ZS(-1)",0) + INDIRECT("ZS(-3)",0) -> 1.0174864e+09 | MJ5: =INDIRECT("ZS(-1)",0) / INDIRECT("Z7S(-1)",0) -> 0.6744545 | MK5: 812733656 | ML5: 63233355 | MM5: =INDIRECT("ZS(-1)",0) * 'Correction factor'!$C$13 -> 97867163 | MN5: =INDIRECT("ZS(-1)",0) + INDIRECT("ZS(-3)",0) -> 9.1060082e+08 | MO5: =INDIRECT("ZS(-1)",0) / INDIRECT("Z7S(-1)",0) -> 0.70894946 | MP5: 800137618 | MQ5: 65913928 | MR5: =INDIRECT("ZS(-1)",0) * 'Correction factor'!$C$13 -> 1.0201592e+08 | MS5: =INDIRECT("ZS(-1)",0) + INDIRECT("ZS(-3)",0) -> 9.0215354e+08 | MT5: =INDIRECT("ZS(-1)",0) / INDIRECT("Z7S(-1)",0) -> 0.65976276 | MU5: 827218356 | MV5: 62864145 | MW5: =INDIRECT("ZS(-1)",0) * 'Correction factor'!$C$13 -> 97295732 | MX5: =INDIRECT("ZS(-1)",0) + INDIRECT("ZS(-3)",0) -> 9.2451409e+08 | MY5: =INDIRECT("ZS(-1)",0) / INDIRECT("Z7S(-1)",0) -> 0.67027421 | MZ5: 851234774 | NA5: 65734953 | NB5: =INDIRECT("ZS(-1)",0) * 'Correction factor'!$C$13 -> 1.0173892e+08 | NC5: =INDIRECT("ZS(-1)",0) + INDIRECT("ZS(-3)",0) -> 9.529737e+08 | ND5: =INDIRECT("ZS(-1)",0) / INDIRECT("Z7S(-1)",0) -> 0.68056967 | NE5: 802008795 | NF5: 63760129 | NG5: =INDIRECT("ZS(-1)",0) * 'Correction factor'!$C$13 -> 98682459 | NH5: =INDIRECT("ZS(-1)",0) + INDIRECT("ZS(-3)",0) -> 9.0069125e+08 | NI5: =INDIRECT("ZS(-1)",0) / INDIRECT("Z7S(-1)",0) -> 0.7012627 | NJ5: 934413679 | NK5: 61683952 | NL5: =INDIRECT("ZS(-1)",0) * 'Correction factor'!$C$13 -> 95469130 | NM5: =INDIRECT("ZS(-1)",0) + INDIRECT("ZS(-3)",0) -> 1.0298828e+09 | NN5: =INDIRECT("ZS(-1)",0) / INDIRECT("Z7S(-1)",0) -> 0.71136352 | NO5: 881201242 | NP5: 64765347 | NQ5: =INDIRECT("ZS(-1)",0) * 'Correction factor'!$C$13 -> 1.0023825e+08 | NR5: =INDIRECT("ZS(-1)",0) + INDIRECT("ZS(-3)",0) -> 9.8143949e+08 | NS5: =INDIRECT("ZS(-1)",0) / INDIRECT("Z7S(-1)",0) -> 0.69446245 | NT5: 837316179 | NU5: 63511006 | NV5: =INDIRECT("ZS(-1)",0) * 'Correction factor'!$C$13 -> 98296888 | NW5: =INDIRECT("ZS(-1)",0) + INDIRECT("ZS(-3)",0) -> 9.3561307e+08 | NX5: =INDIRECT("ZS(-1)",0) / INDIRECT("Z7S(-1)",0) -> 0.69744474 | NY5: 882136797 | NZ5: 60545807 | OA5: =INDIRECT("ZS(-1)",0) * 'Correction factor'!$C$13 -> 93707607 | OB5: =INDIRECT("ZS(-1)",0) + INDIRECT("ZS(-3)",0) -> 9.758444e+08 | OC5: =INDIRECT("ZS(-1)",0) / INDIRECT("Z7S(-1)",0) -> 0.69507552 | OD5: 987252758 | OE5: 68392466 | OF5: =INDIRECT("ZS(-1)",0) * 'Correction factor'!$C$13 -> 1.0585199e+08 | OG5: =INDIRECT("ZS(-1)",0) + INDIRECT("ZS(-3)",0) -> 1.0931048e+09 | OH5: =INDIRECT("ZS(-1)",0) / INDIRECT("Z7S(-1)",0) -> 0.69154704 | OI5: 837092845 | OJ5: 67686463 | OK5: =INDIRECT("ZS(-1)",0) * 'Correction factor'!$C$13 -> 1.047593e+08 | OL5: =INDIRECT("ZS(-1)",0) + INDIRECT("ZS(-3)",0) -> 9.4185215e+08 | OM5: =INDIRECT("ZS(-1)",0) / INDIRECT("Z7S(-1)",0) -> 0.65041184 | ON5: 958571550 | OO5: 65728849 | OP5: =INDIRECT("ZS(-1)",0) * 'Correction factor'!$C$13 -> 1.0172948e+08 | OQ5: =INDIRECT("ZS(-1)",0) + INDIRECT("ZS(-3)",0) -> 1.060301e+09 | OR5: =INDIRECT("ZS(-1)",0) / INDIRECT("Z7S(-1)",0) -> 0.73966688 | OS5: 908479498 | OT5: 66235112 | OU5: =INDIRECT("ZS(-1)",0) * 'Correction factor'!$C$13 -> 1.0251303e+08 | OV5: =INDIRECT("ZS(-1)",0) + INDIRECT("ZS(-3)",0) -> 1.0109925e+09 | OW5: =INDIRECT("ZS(-1)",0) / INDIRECT("Z7S(-1)",0) -> 0.68935126 | OX5: 938207462 | OY5: 65203031 | OZ5: =INDIRECT("ZS(-1)",0) * 'Correction factor'!$C$13 -> 1.0091566e+08 | PA5: =INDIRECT("ZS(-1)",0) + INDIRECT("ZS(-3)",0) -> 1.0391231e+09 | PB5: =INDIRECT("ZS(-1)",0) / INDIRECT("Z7S(-1)",0) -> 0.67358056 | PC5: 834773614 | PD5: 65219659 | PE5: =INDIRECT("ZS(-1)",0) * 'Correction factor'!$C$13 -> 1.0094139e+08 | PF5: =INDIRECT("ZS(-1)",0) + INDIRECT("ZS(-3)",0) -> 9.3571501e+08 | PG5: =INDIRECT("ZS(-1)",0) / INDIRECT("Z7S(-1)",0) -> 0.64374593 | PH5: 260501255 | PI5: 598953621 | PJ5: =INDIRECT("ZS(-1)",0) * 'Correction factor'!$C$13 -> 9.2700904e+08 | PK5: =INDIRECT("ZS(-1)",0) + INDIRECT("ZS(-3)",0) -> 1.1875103e+09 | PL5: =INDIRECT("ZS(-1)",0) / INDIRECT("Z7S(-1)",0) -> 0.72810878 | PM5: 266768563 | PN5: 580853696 | PO5: =INDIRECT("ZS(-1)",0) * 'Correction factor'!$C$13 -> 8.9899553e+08 | PP5: =INDIRECT("ZS(-1)",0) + INDIRECT("ZS(-3)",0) -> 1.1657641e+09 | PQ5: =INDIRECT("ZS(-1)",0) / INDIRECT("Z7S(-1)",0) -> 0.74512136 | PR5: 251703265 | PS5: 554358765 | PT5: =INDIRECT("ZS(-1)",0) * 'Correction factor'!$C$13 -> 8.5798895e+08 | PU5: =INDIRECT("ZS(-1)",0) + INDIRECT("ZS(-3)",0) -> 1.1096922e+09 | PV5: =INDIRECT("ZS(-1)",0) / INDIRECT("Z7S(-1)",0) -> 0.70795992 | PW5: 281970722 | PX5: 586981015 | PY5: =INDIRECT("ZS(-1)",0) * 'Correction factor'!$C$13 -> 9.0847887e+08 | PZ5: =INDIRECT("ZS(-1)",0) + INDIRECT("ZS(-3)",0) -> 1.1904496e+09 | QA5: =INDIRECT("ZS(-1)",0) / INDIRECT("Z7S(-1)",0) -> 0.77315387 | QB5: 243002793 | QC5: 413087171 | QD5: =INDIRECT("ZS(-1)",0) * 'Correction factor'!$C$13 -> 6.3934089e+08 | QE5: =INDIRECT("ZS(-1)",0) + INDIRECT("ZS(-3)",0) -> 8.8234369e+08 | QF5: =INDIRECT("ZS(-1)",0) / INDIRECT("Z7S(-1)",0) -> 0.74268499 | QG5: 252408685 | QH5: 531790823 | QI5: =INDIRECT("ZS(-1)",0) * 'Correction factor'!$C$13 -> 8.2306022e+08 | QJ5: =INDIRECT("ZS(-1)",0) + INDIRECT("ZS(-3)",0) -> 1.0754689e+09 | QK5: =INDIRECT("ZS(-1)",0) / INDIRECT("Z7S(-1)",0) -> 0.77232618 | QL5: 264589912 | QM5: 589244215 | QN5: =INDIRECT("ZS(-1)",0) * 'Correction factor'!$C$13 -> 9.1198166e+08 | QO5: =INDIRECT("ZS(-1)",0) + INDIRECT("ZS(-3)",0) -> 1.1765716e+09 | QP5: =INDIRECT("ZS(-1)",0) / INDIRECT("Z7S(-1)",0) -> 0.74229325 | QQ5: 245003294 | QR5: 573692456 | QS5: =INDIRECT("ZS(-1)",0) * 'Correction factor'!$C$13 -> 8.8791198e+08 | QT5: =INDIRECT("ZS(-1)",0) + INDIRECT("ZS(-3)",0) -> 1.1329153e+09 | QU5: =INDIRECT("ZS(-1)",0) / INDIRECT("Z7S(-1)",0) -> 0.74494421 | QV5: 258331864 | QW5: 573609468 | QX5: =INDIRECT("ZS(-1)",0) * 'Correction factor'!$C$13 -> 8.8778354e+08 | QY5: =INDIRECT("ZS(-1)",0) + INDIRECT("ZS(-3)",0) -> 1.1461154e+09 | QZ5: =INDIRECT("ZS(-1)",0) / INDIRECT("Z7S(-1)",0) -> 0.71287456 | RA5: 254426743 | RB5: 572035218 | RC5: =INDIRECT("ZS(-1)",0) * 'Correction factor'!$C$13 -> 8.8534705e+08 | RD5: =INDIRECT("ZS(-1)",0) + INDIRECT("ZS(-3)",0) -> 1.1397738e+09 | RE5: =INDIRECT("ZS(-1)",0) / INDIRECT("Z7S(-1)",0) -> 0.76496789 | RF5: 256867118 | RG5: 548814399 | RH5: =INDIRECT("ZS(-1)",0) * 'Correction factor'!$C$13 -> 8.4940786e+08 | RI5: =INDIRECT("ZS(-1)",0) + INDIRECT("ZS(-3)",0) -> 1.106275e+09 | RJ5: =INDIRECT("ZS(-1)",0) / INDIRECT("Z7S(-1)",0) -> 0.70998198 | RK5: 233479552 | RL5: 502877744 | RM5: =INDIRECT("ZS(-1)",0) * 'Correction factor'!$C$13 -> 7.7831104e+08 | RN5: =INDIRECT("ZS(-1)",0) + INDIRECT("ZS(-3)",0) -> 1.0117906e+09 | RO5: =INDIRECT("ZS(-1)",0) / INDIRECT("Z7S(-1)",0) -> 0.70099178
A6: -1 | B6: 45468 | C6: Tuesday | D6: 1091900744 | E6: 64778654 | F6: =INDIRECT("ZS(-1)",0) * 'Correction factor'!$C$13 -> 1.0025884e+08 | G6: =INDIRECT("ZS(-1)",0) + INDIRECT("ZS(-3)",0) -> 1.1921596e+09 | H6: =INDIRECT("ZS(-1)",0) / INDIRECT("Z7S(-1)",0) -> 0.79749888 | I6: 1115614193 | J6: 64123668 | K6: =INDIRECT("ZS(-1)",0) * 'Correction factor'!$C$13 -> 99245114 | L6: =INDIRECT("ZS(-1)",0) + INDIRECT("ZS(-3)",0) -> 1.2148593e+09 | M6: =INDIRECT("ZS(-1)",0) / INDIRECT("Z7S(-1)",0) -> 0.88333229 | N6: 1143144370 | O6: 66478528 | P6: =INDIRECT("ZS(-1)",0) * 'Correction factor'!$C$13 -> 1.0288976e+08 | Q6: =INDIRECT("ZS(-1)",0) + INDIRECT("ZS(-3)",0) -> 1.2460341e+09 | R6: =INDIRECT("ZS(-1)",0) / INDIRECT("Z7S(-1)",0) -> 0.87086146 | S6: 958189579 | T6: 65017661 | U6: =INDIRECT("ZS(-1)",0) * 'Correction factor'!$C$13 -> 1.0062876e+08 | V6: =INDIRECT("ZS(-1)",0) + INDIRECT("ZS(-3)",0) -> 1.0588183e+09 | W6: =INDIRECT("ZS(-1)",0) / INDIRECT("Z7S(-1)",0) -> 0.7591237 | X6: 1042500765 | Y6: 67897055 | Z6: =INDIRECT("ZS(-1)",0) * 'Correction factor'!$C$13 -> 1.0508524e+08 | AA6: =INDIRECT("ZS(-1)",0) + INDIRECT("ZS(-3)",0) -> 1.147586e+09 | AB6: =INDIRECT("ZS(-1)",0) / INDIRECT("Z7S(-1)",0) -> 0.78753275 | AC6: 1010514132 | AD6: 66930101 | AE6: =INDIRECT("ZS(-1)",0) * 'Correction factor'!$C$13 -> 1.0358867e+08 | AF6: =INDIRECT("ZS(-1)",0) + INDIRECT("ZS(-3)",0) -> 1.1141028e+09 | AG6: =INDIRECT("ZS(-1)",0) / INDIRECT("Z7S(-1)",0) -> 0.75747472 | AH6: 1034271530 | AI6: 65160387 | AJ6: =INDIRECT("ZS(-1)",0) * 'Correction factor'!$C$13 -> 1.0084966e+08 | AK6: =INDIRECT("ZS(-1)",0) + INDIRECT("ZS(-3)",0) -> 1.1351212e+09 | AL6: =INDIRECT("ZS(-1)",0) / INDIRECT("Z7S(-1)",0) -> 0.84629737 | AM6: 1030122412 | AN6: 63520975 | AO6: =INDIRECT("ZS(-1)",0) * 'Correction factor'!$C$13 -> 98312317 | AP6: =INDIRECT("ZS(-1)",0) + INDIRECT("ZS(-3)",0) -> 1.1284347e+09 | AQ6: =INDIRECT("ZS(-1)",0) / INDIRECT("Z7S(-1)",0) -> 0.78912686 | AR6: 1063072889 | AS6: 67184099 | AT6: =INDIRECT("ZS(-1)",0) * 'Correction factor'!$C$13 -> 1.0398179e+08 | AU6: =INDIRECT("ZS(-1)",0) + INDIRECT("ZS(-3)",0) -> 1.1670547e+09 | AV6: =INDIRECT("ZS(-1)",0) / INDIRECT("Z7S(-1)",0) -> 0.78148802 | AW6: 1030263196 | AX6: 69676288 | AY6: =INDIRECT("ZS(-1)",0) * 'Correction factor'!$C$13 -> 1.0783898e+08 | AZ6: =INDIRECT("ZS(-1)",0) + INDIRECT("ZS(-3)",0) -> 1.1381022e+09 | BA6: =INDIRECT("ZS(-1)",0) / INDIRECT("Z7S(-1)",0) -> 0.84624748 | BB6: 980005197 | BC6: 64880020 | BD6: =INDIRECT("ZS(-1)",0) * 'Correction factor'!$C$13 -> 1.0041573e+08 | BE6: =INDIRECT("ZS(-1)",0) + INDIRECT("ZS(-3)",0) -> 1.0804209e+09 | BF6: =INDIRECT("ZS(-1)",0) / INDIRECT("Z7S(-1)",0) -> 0.80903993 | BG6: 1106105484 | BH6: 69047245 | BI6: =INDIRECT("ZS(-1)",0) * 'Correction factor'!$C$13 -> 1.068654e+08 | BJ6: =INDIRECT("ZS(-1)",0) + INDIRECT("ZS(-3)",0) -> 1.2129709e+09 | BK6: =INDIRECT("ZS(-1)",0) / INDIRECT("Z7S(-1)",0) -> 0.85439301 | BL6: 1015116880 | BM6: 65459021 | BN6: =INDIRECT("ZS(-1)",0) * 'Correction factor'!$C$13 -> 1.0131186e+08 | BO6: =INDIRECT("ZS(-1)",0) + INDIRECT("ZS(-3)",0) -> 1.1164287e+09 | BP6: =INDIRECT("ZS(-1)",0) / INDIRECT("Z7S(-1)",0) -> 0.81157017 | BQ6: 1065453920 | BR6: 63928200 | BS6: =INDIRECT("ZS(-1)",0) * 'Correction factor'!$C$13 -> 98942585 | BT6: =INDIRECT("ZS(-1)",0) + INDIRECT("ZS(-3)",0) -> 1.1643965e+09 | BU6: =INDIRECT("ZS(-1)",0) / INDIRECT("Z7S(-1)",0) -> 0.85842228 | BV6: 1067113243 | BW6: 66021812 | BX6: =INDIRECT("ZS(-1)",0) * 'Correction factor'!$C$13 -> 1.021829e+08 | BY6: =INDIRECT("ZS(-1)",0) + INDIRECT("ZS(-3)",0) -> 1.1692961e+09 | BZ6: =INDIRECT("ZS(-1)",0) / INDIRECT("Z7S(-1)",0) -> 0.86807292 | CA6: 1040032936 | CB6: 64268747 | CC6: =INDIRECT("ZS(-1)",0) * 'Correction factor'!$C$13 -> 99469654 | CD6: =INDIRECT("ZS(-1)",0) + INDIRECT("ZS(-3)",0) -> 1.1395026e+09 | CE6: =INDIRECT("ZS(-1)",0) / INDIRECT("Z7S(-1)",0) -> 0.81728096 | CF6: 1119141112 | CG6: 67951971 | CH6: =INDIRECT("ZS(-1)",0) * 'Correction factor'!$C$13 -> 1.0517023e+08 | CI6: =INDIRECT("ZS(-1)",0) + INDIRECT("ZS(-3)",0) -> 1.2243113e+09 | CJ6: =INDIRECT("ZS(-1)",0) / INDIRECT("Z7S(-1)",0) -> 0.84173657 | CK6: 1057994537 | CL6: 63922040 | CM6: =INDIRECT("ZS(-1)",0) * 'Correction factor'!$C$13 -> 98933051 | CN6: =INDIRECT("ZS(-1)",0) + INDIRECT("ZS(-3)",0) -> 1.1569276e+09 | CO6: =INDIRECT("ZS(-1)",0) / INDIRECT("Z7S(-1)",0) -> 0.87798704 | CP6: 1041360983 | CQ6: 66847788 | CR6: =INDIRECT("ZS(-1)",0) * 'Correction factor'!$C$13 -> 1.0346127e+08 | CS6: =INDIRECT("ZS(-1)",0) + INDIRECT("ZS(-3)",0) -> 1.1448223e+09 | CT6: =INDIRECT("ZS(-1)",0) / INDIRECT("Z7S(-1)",0) -> 0.84139211 | CU6: 1076366283 | CV6: 65674831 | CW6: =INDIRECT("ZS(-1)",0) * 'Correction factor'!$C$13 -> 1.0164587e+08 | CX6: =INDIRECT("ZS(-1)",0) + INDIRECT("ZS(-3)",0) -> 1.1780122e+09 | CY6: =INDIRECT("ZS(-1)",0) / INDIRECT("Z7S(-1)",0) -> 0.82339101 | CZ6: 988978984 | DA6: 67528482 | DB6: =INDIRECT("ZS(-1)",0) * 'Correction factor'!$C$13 -> 1.0451479e+08 | DC6: =INDIRECT("ZS(-1)",0) + INDIRECT("ZS(-3)",0) -> 1.0934938e+09 | DD6: =INDIRECT("ZS(-1)",0) / INDIRECT("Z7S(-1)",0) -> 0.76864889 | DE6: 1097172906 | DF6: 70061844 | DG6: =INDIRECT("ZS(-1)",0) * 'Correction factor'!$C$13 -> 1.0843571e+08 | DH6: =INDIRECT("ZS(-1)",0) + INDIRECT("ZS(-3)",0) -> 1.2056086e+09 | DI6: =INDIRECT("ZS(-1)",0) / INDIRECT("Z7S(-1)",0) -> 0.88551907 | DJ6: 1145179792 | DK6: 65428729 | DL6: =INDIRECT("ZS(-1)",0) * 'Correction factor'!$C$13 -> 1.0126498e+08 | DM6: =INDIRECT("ZS(-1)",0) + INDIRECT("ZS(-3)",0) -> 1.2464448e+09 | DN6: =INDIRECT("ZS(-1)",0) / INDIRECT("Z7S(-1)",0) -> 0.80996579 | DO6: 1029797154 | DP6: 66288579 | DQ6: =INDIRECT("ZS(-1)",0) * 'Correction factor'!$C$13 -> 1.0259578e+08 | DR6: =INDIRECT("ZS(-1)",0) + INDIRECT("ZS(-3)",0) -> 1.1323929e+09 | DS6: =INDIRECT("ZS(-1)",0) / INDIRECT("Z7S(-1)",0) -> 0.79140303 | DT6: 1046515831 | DU6: 65632665 | DV6: =INDIRECT("ZS(-1)",0) * 'Correction factor'!$C$13 -> 1.0158061e+08 | DW6: =INDIRECT("ZS(-1)",0) + INDIRECT("ZS(-3)",0) -> 1.1480964e+09 | DX6: =INDIRECT("ZS(-1)",0) / INDIRECT("Z7S(-1)",0) -> 0.85390631 | DY6: 988243116 | DZ6: 62239844 | EA6: =INDIRECT("ZS(-1)",0) * 'Correction factor'!$C$13 -> 96329492 | EB6: =INDIRECT("ZS(-1)",0) + INDIRECT("ZS(-3)",0) -> 1.0845726e+09 | EC6: =INDIRECT("ZS(-1)",0) / INDIRECT("Z7S(-1)",0) -> 0.84799064 | ED6: 1073100677 | EE6: 63560879 | EF6: =INDIRECT("ZS(-1)",0) * 'Correction factor'!$C$13 -> 98374077 | EG6: =INDIRECT("ZS(-1)",0) + INDIRECT("ZS(-3)",0) -> 1.1714748e+09 | EH6: =INDIRECT("ZS(-1)",0) / INDIRECT("Z7S(-1)",0) -> 0.83454043 | EI6: 974185234 | EJ6: 62910970 | EK6: =INDIRECT("ZS(-1)",0) * 'Correction factor'!$C$13 -> 97368204 | EL6: =INDIRECT("ZS(-1)",0) + INDIRECT("ZS(-3)",0) -> 1.0715534e+09 | EM6: =INDIRECT("ZS(-1)",0) / INDIRECT("Z7S(-1)",0) -> 0.84146338 | EN6: 1089606605 | EO6: 61986440 | EP6: =INDIRECT("ZS(-1)",0) * 'Correction factor'!$C$13 -> 95937295 | EQ6: =INDIRECT("ZS(-1)",0) + INDIRECT("ZS(-3)",0) -> 1.1855439e+09 | ER6: =INDIRECT("ZS(-1)",0) / INDIRECT("Z7S(-1)",0) -> 0.83699568 | ES6: 1117637092 | ET6: 59987978 | EU6: =INDIRECT("ZS(-1)",0) * 'Correction factor'!$C$13 -> 92844247 | EV6: =INDIRECT("ZS(-1)",0) + INDIRECT("ZS(-3)",0) -> 1.2104813e+09 | EW6: =INDIRECT("ZS(-1)",0) / INDIRECT("Z7S(-1)",0) -> 0.83985215 | EX6: 1011072547 | EY6: 63478594 | EZ6: =INDIRECT("ZS(-1)",0) * 'Correction factor'!$C$13 -> 98246723 | FA6: =INDIRECT("ZS(-1)",0) + INDIRECT("ZS(-3)",0) -> 1.1093193e+09 | FB6: =INDIRECT("ZS(-1)",0) / INDIRECT("Z7S(-1)",0) -> 0.80437054 | FC6: 1049709067 | FD6: 64530815 | FE6: =INDIRECT("ZS(-1)",0) * 'Correction factor'!$C$13 -> 99875261 | FF6: =INDIRECT("ZS(-1)",0) + INDIRECT("ZS(-3)",0) -> 1.1495843e+09 | FG6: =INDIRECT("ZS(-1)",0) / INDIRECT("Z7S(-1)",0) -> 0.87319263 | FH6: 1065635479 | FI6: 63232512 | FJ6: =INDIRECT("ZS(-1)",0) * 'Correction factor'!$C$13 -> 97865859 | FK6: =INDIRECT("ZS(-1)",0) + INDIRECT("ZS(-3)",0) -> 1.1635013e+09 | FL6: =INDIRECT("ZS(-1)",0) / INDIRECT("Z7S(-1)",0) -> 0.84635717 | FM6: 1115673188 | FN6: 63707732 | FO6: =INDIRECT("ZS(-1)",0) * 'Correction factor'!$C$13 -> 98601363 | FP6: =INDIRECT("ZS(-1)",0) + INDIRECT("ZS(-3)",0) -> 1.2142746e+09 | FQ6: =INDIRECT("ZS(-1)",0) / INDIRECT("Z7S(-1)",0) -> 0.87552021 | FR6: 1112448774 | FS6: 64894156 | FT6: =INDIRECT("ZS(-1)",0) * 'Correction factor'!$C$13 -> 1.0043761e+08 | FU6: =INDIRECT("ZS(-1)",0) + INDIRECT("ZS(-3)",0) -> 1.2128864e+09 | FV6: =INDIRECT("ZS(-1)",0) / INDIRECT("Z7S(-1)",0) -> 0.84065806 | FW6: 1055403641 | FX6: 66032980 | FY6: =INDIRECT("ZS(-1)",0) * 'Correction factor'!$C$13 -> 1.0220018e+08 | FZ6: =INDIRECT("ZS(-1)",0) + INDIRECT("ZS(-3)",0) -> 1.1576038e+09 | GA6: =INDIRECT("ZS(-1)",0) / INDIRECT("Z7S(-1)",0) -> 0.86478075 | GB6: 979458540 | GC6: 62947855 | GD6: =INDIRECT("ZS(-1)",0) * 'Correction factor'!$C$13 -> 97425291 | GE6: =INDIRECT("ZS(-1)",0) + INDIRECT("ZS(-3)",0) -> 1.0768838e+09 | GF6: =INDIRECT("ZS(-1)",0) / INDIRECT("Z7S(-1)",0) -> 0.78867086 | GG6: 1026970624 | GH6: 61226274 | GI6: =INDIRECT("ZS(-1)",0) * 'Correction factor'!$C$13 -> 94760776 | GJ6: =INDIRECT("ZS(-1)",0) + INDIRECT("ZS(-3)",0) -> 1.1217314e+09 | GK6: =INDIRECT("ZS(-1)",0) / INDIRECT("Z7S(-1)",0) -> 0.85476131 | GL6: 1041760879 | GM6: 62663700 | GN6: =INDIRECT("ZS(-1)",0) * 'Correction factor'!$C$13 -> 96985500 | GO6: =INDIRECT("ZS(-1)",0) + INDIRECT("ZS(-3)",0) -> 1.1387464e+09 | GP6: =INDIRECT("ZS(-1)",0) / INDIRECT("Z7S(-1)",0) -> 0.81827577 | GQ6: 1011618598 | GR6: 65654475 | GS6: =INDIRECT("ZS(-1)",0) * 'Correction factor'!$C$13 -> 1.0161437e+08 | GT6: =INDIRECT("ZS(-1)",0) + INDIRECT("ZS(-3)",0) -> 1.113233e+09 | GU6: =INDIRECT("ZS(-1)",0) / INDIRECT("Z7S(-1)",0) -> 0.86312886 | GV6: 1033278705 | GW6: 62220055 | GX6: =INDIRECT("ZS(-1)",0) * 'Correction factor'!$C$13 -> 96298865 | GY6: =INDIRECT("ZS(-1)",0) + INDIRECT("ZS(-3)",0) -> 1.1295776e+09 | GZ6: =INDIRECT("ZS(-1)",0) / INDIRECT("Z7S(-1)",0) -> 0.82785025 | HA6: 1054490134 | HB6: 63023944 | HC6: =INDIRECT("ZS(-1)",0) * 'Correction factor'!$C$13 -> 97543055 | HD6: =INDIRECT("ZS(-1)",0) + INDIRECT("ZS(-3)",0) -> 1.1520332e+09 | HE6: =INDIRECT("ZS(-1)",0) / INDIRECT("Z7S(-1)",0) -> 0.86602224 | HF6: 1020204228 | HG6: 63610056 | HH6: =INDIRECT("ZS(-1)",0) * 'Correction factor'!$C$13 -> 98450189 | HI6: =INDIRECT("ZS(-1)",0) + INDIRECT("ZS(-3)",0) -> 1.1186544e+09 | HJ6: =INDIRECT("ZS(-1)",0) / INDIRECT("Z7S(-1)",0) -> 0.80829428 | HK6: 1024915928 | HL6: 63694026 | HM6: =INDIRECT("ZS(-1)",0) * 'Correction factor'!$C$13 -> 98580151 | HN6: =INDIRECT("ZS(-1)",0) + INDIRECT("ZS(-3)",0) -> 1.1234961e+09 | HO6: =INDIRECT("ZS(-1)",0) / INDIRECT("Z7S(-1)",0) -> 0.83126364 | HP6: 991589976 | HQ6: 63349599 | HR6: =INDIRECT("ZS(-1)",0) * 'Correction factor'!$C$13 -> 98047076 | HS6: =INDIRECT("ZS(-1)",0) + INDIRECT("ZS(-3)",0) -> 1.0896371e+09 | HT6: =INDIRECT("ZS(-1)",0) / INDIRECT("Z7S(-1)",0) -> 0.82137779 | HU6: 1150099608 | HV6: 62823645 | HW6: =INDIRECT("ZS(-1)",0) * 'Correction factor'!$C$13 -> 97233049 | HX6: =INDIRECT("ZS(-1)",0) + INDIRECT("ZS(-3)",0) -> 1.2473327e+09 | HY6: =INDIRECT("ZS(-1)",0) / INDIRECT("Z7S(-1)",0) -> 0.84951462 | HZ6: 941008831 | IA6: 61221542 | IB6: =INDIRECT("ZS(-1)",0) * 'Correction factor'!$C$13 -> 94753452 | IC6: =INDIRECT("ZS(-1)",0) + INDIRECT("ZS(-3)",0) -> 1.0357623e+09 | ID6: =INDIRECT("ZS(-1)",0) / INDIRECT("Z7S(-1)",0) -> 0.80199653 | IE6: 999020070 | IF6: 62386312 | IG6: =INDIRECT("ZS(-1)",0) * 'Correction factor'!$C$13 -> 96556183 | IH6: =INDIRECT("ZS(-1)",0) + INDIRECT("ZS(-3)",0) -> 1.0955763e+09 | II6: =INDIRECT("ZS(-1)",0) / INDIRECT("Z7S(-1)",0) -> 0.78583385 | IJ6: 1014266711 | IK6: 62322575 | IL6: =INDIRECT("ZS(-1)",0) * 'Correction factor'!$C$13 -> 96457536 | IM6: =INDIRECT("ZS(-1)",0) + INDIRECT("ZS(-3)",0) -> 1.1107242e+09 | IN6: =INDIRECT("ZS(-1)",0) / INDIRECT("Z7S(-1)",0) -> 0.83176073 | IO6: 1049955618 | IP6: 63662742 | IQ6: =INDIRECT("ZS(-1)",0) * 'Correction factor'!$C$13 -> 98531732 | IR6: =INDIRECT("ZS(-1)",0) + INDIRECT("ZS(-3)",0) -> 1.1484873e+09 | IS6: =INDIRECT("ZS(-1)",0) / INDIRECT("Z7S(-1)",0) -> 0.85689629 | IT6: 989124028 | IU6: 62576482 | IV6: =INDIRECT("ZS(-1)",0) * 'Correction factor'!$C$13 -> 96850512 | IW6: =INDIRECT("ZS(-1)",0) + INDIRECT("ZS(-3)",0) -> 1.0859745e+09 | IX6: =INDIRECT("ZS(-1)",0) / INDIRECT("Z7S(-1)",0) -> 0.84776341 | IY6: 989202384 | IZ6: 63207778 | JA6: =INDIRECT("ZS(-1)",0) * 'Correction factor'!$C$13 -> 97827578 | JB6: =INDIRECT("ZS(-1)",0) + INDIRECT("ZS(-3)",0) -> 1.08703e+09 | JC6: =INDIRECT("ZS(-1)",0) / INDIRECT("Z7S(-1)",0) -> 0.81295323 | JD6: 996242509 | JE6: 62643788 | JF6: =INDIRECT("ZS(-1)",0) * 'Correction factor'!$C$13 -> 96954682 | JG6: =INDIRECT("ZS(-1)",0) + INDIRECT("ZS(-3)",0) -> 1.0931972e+09 | JH6: =INDIRECT("ZS(-1)",0) / INDIRECT("Z7S(-1)",0) -> 0.77836202 | JI6: 929374508 | JJ6: 63207617 | JK6: =INDIRECT("ZS(-1)",0) * 'Correction factor'!$C$13 -> 97827328 | JL6: =INDIRECT("ZS(-1)",0) + INDIRECT("ZS(-3)",0) -> 1.0272018e+09 | JM6: =INDIRECT("ZS(-1)",0) / INDIRECT("Z7S(-1)",0) -> 0.80016962 | JN6: 1016315612 | JO6: 62492598 | JP6: =INDIRECT("ZS(-1)",0) * 'Correction factor'!$C$13 -> 96720683 | JQ6: =INDIRECT("ZS(-1)",0) + INDIRECT("ZS(-3)",0) -> 1.1130363e+09 | JR6: =INDIRECT("ZS(-1)",0) / INDIRECT("Z7S(-1)",0) -> 0.84590616 | JS6: 961240711 | JT6: 64784384 | JU6: =INDIRECT("ZS(-1)",0) * 'Correction factor'!$C$13 -> 1.0026771e+08 | JV6: =INDIRECT("ZS(-1)",0) + INDIRECT("ZS(-3)",0) -> 1.0615084e+09 | JW6: =INDIRECT("ZS(-1)",0) / INDIRECT("Z7S(-1)",0) -> 0.80744826 | JX6: 1099601751 | JY6: 62971940 | JZ6: =INDIRECT("ZS(-1)",0) * 'Correction factor'!$C$13 -> 97462568 | KA6: =INDIRECT("ZS(-1)",0) + INDIRECT("ZS(-3)",0) -> 1.1970643e+09 | KB6: =INDIRECT("ZS(-1)",0) / INDIRECT("Z7S(-1)",0) -> 0.82005424 | KC6: 992356997 | KD6: 45031243 | KE6: =INDIRECT("ZS(-1)",0) * 'Correction factor'!$C$13 -> 69695496 | KF6: =INDIRECT("ZS(-1)",0) + INDIRECT("ZS(-3)",0) -> 1.0620525e+09 | KG6: =INDIRECT("ZS(-1)",0) / INDIRECT("Z7S(-1)",0) -> 0.76727325 | KH6: 1090319403 | KI6: 60363766 | KJ6: =INDIRECT("ZS(-1)",0) * 'Correction factor'!$C$13 -> 93425860 | KK6: =INDIRECT("ZS(-1)",0) + INDIRECT("ZS(-3)",0) -> 1.1837453e+09 | KL6: =INDIRECT("ZS(-1)",0) / INDIRECT("Z7S(-1)",0) -> 0.84096163 | KM6: 1064031797 | KN6: 62500626 | KO6: =INDIRECT("ZS(-1)",0) * 'Correction factor'!$C$13 -> 96733108 | KP6: =INDIRECT("ZS(-1)",0) + INDIRECT("ZS(-3)",0) -> 1.1607649e+09 | KQ6: =INDIRECT("ZS(-1)",0) / INDIRECT("Z7S(-1)",0) -> 0.90575656 | KR6: 1092622218 | KS6: 60526856 | KT6: =INDIRECT("ZS(-1)",0) * 'Correction factor'!$C$13 -> 93678276 | KU6: =INDIRECT("ZS(-1)",0) + INDIRECT("ZS(-3)",0) -> 1.1863005e+09 | KV6: =INDIRECT("ZS(-1)",0) / INDIRECT("Z7S(-1)",0) -> 0.82510705 | KW6: 1119082915 | KX6: 60543316 | KY6: =INDIRECT("ZS(-1)",0) * 'Correction factor'!$C$13 -> 93703752 | KZ6: =INDIRECT("ZS(-1)",0) + INDIRECT("ZS(-3)",0) -> 1.2127867e+09 | LA6: =INDIRECT("ZS(-1)",0) / INDIRECT("Z7S(-1)",0) -> 0.84242033 | LB6: 1040798318 | LC6: 64358554 | LD6: =INDIRECT("ZS(-1)",0) * 'Correction factor'!$C$13 -> 99608650 | LE6: =INDIRECT("ZS(-1)",0) + INDIRECT("ZS(-3)",0) -> 1.140407e+09 | LF6: =INDIRECT("ZS(-1)",0) / INDIRECT("Z7S(-1)",0) -> 0.85510504 | LG6: 1064138083 | LH6: 60409893 | LI6: =INDIRECT("ZS(-1)",0) * 'Correction factor'!$C$13 -> 93497251 | LJ6: =INDIRECT("ZS(-1)",0) + INDIRECT("ZS(-3)",0) -> 1.1576353e+09 | LK6: =INDIRECT("ZS(-1)",0) / INDIRECT("Z7S(-1)",0) -> 0.90872271 | LL6: 1008952056 | LM6: 59547133 | LN6: =INDIRECT("ZS(-1)",0) * 'Correction factor'!$C$13 -> 92161945 | LO6: =INDIRECT("ZS(-1)",0) + INDIRECT("ZS(-3)",0) -> 1.101114e+09 | LP6: =INDIRECT("ZS(-1)",0) / INDIRECT("Z7S(-1)",0) -> 0.78519778 | LQ6: 1059045968 | LR6: 62713308 | LS6: =INDIRECT("ZS(-1)",0) * 'Correction factor'!$C$13 -> 97062279 | LT6: =INDIRECT("ZS(-1)",0) + INDIRECT("ZS(-3)",0) -> 1.1561082e+09 | LU6: =INDIRECT("ZS(-1)",0) / INDIRECT("Z7S(-1)",0) -> 0.81772618 | LV6: 1017476022 | LW6: 63182213 | LX6: =INDIRECT("ZS(-1)",0) * 'Correction factor'!$C$13 -> 97788010 | LY6: =INDIRECT("ZS(-1)",0) + INDIRECT("ZS(-3)",0) -> 1.115264e+09 | LZ6: =INDIRECT("ZS(-1)",0) / INDIRECT("Z7S(-1)",0) -> 0.80833181 | MA6: 1126311852 | MB6: 66281015 | MC6: =INDIRECT("ZS(-1)",0) * 'Correction factor'!$C$13 -> 1.0258407e+08 | MD6: =INDIRECT("ZS(-1)",0) + INDIRECT("ZS(-3)",0) -> 1.2288959e+09 | ME6: =INDIRECT("ZS(-1)",0) / INDIRECT("Z7S(-1)",0) -> 0.87192716 | MF6: 1140239176 | MG6: 60813753 | MH6: =INDIRECT("ZS(-1)",0) * 'Correction factor'!$C$13 -> 94122311 | MI6: =INDIRECT("ZS(-1)",0) + INDIRECT("ZS(-3)",0) -> 1.2343615e+09 | MJ6: =INDIRECT("ZS(-1)",0) / INDIRECT("Z7S(-1)",0) -> 0.81821307 | MK6: 940435792 | ML6: 62514716 | MM6: =INDIRECT("ZS(-1)",0) * 'Correction factor'!$C$13 -> 96754916 | MN6: =INDIRECT("ZS(-1)",0) + INDIRECT("ZS(-3)",0) -> 1.0371907e+09 | MO6: =INDIRECT("ZS(-1)",0) / INDIRECT("Z7S(-1)",0) -> 0.80750618 | MP6: 1014173661 | MQ6: 65003302 | MR6: =INDIRECT("ZS(-1)",0) * 'Correction factor'!$C$13 -> 1.0060654e+08 | MS6: =INDIRECT("ZS(-1)",0) + INDIRECT("ZS(-3)",0) -> 1.1147802e+09 | MT6: =INDIRECT("ZS(-1)",0) / INDIRECT("Z7S(-1)",0) -> 0.81526084 | MU6: 1027515177 | MV6: 61683707 | MW6: =INDIRECT("ZS(-1)",0) * 'Correction factor'!$C$13 -> 95468751 | MX6: =INDIRECT("ZS(-1)",0) + INDIRECT("ZS(-3)",0) -> 1.1229839e+09 | MY6: =INDIRECT("ZS(-1)",0) / INDIRECT("Z7S(-1)",0) -> 0.81416516 | MZ6: 1042274634 | NA6: 61866586 | NB6: =INDIRECT("ZS(-1)",0) * 'Correction factor'!$C$13 -> 95751796 | NC6: =INDIRECT("ZS(-1)",0) + INDIRECT("ZS(-3)",0) -> 1.1380264e+09 | ND6: =INDIRECT("ZS(-1)",0) / INDIRECT("Z7S(-1)",0) -> 0.81272576 | NE6: 1003702827 | NF6: 63966469 | NG6: =INDIRECT("ZS(-1)",0) * 'Correction factor'!$C$13 -> 99001814 | NH6: =INDIRECT("ZS(-1)",0) + INDIRECT("ZS(-3)",0) -> 1.1027046e+09 | NI6: =INDIRECT("ZS(-1)",0) / INDIRECT("Z7S(-1)",0) -> 0.85854684 | NJ6: 1107942077 | NK6: 62074816 | NL6: =INDIRECT("ZS(-1)",0) * 'Correction factor'!$C$13 -> 96074076 | NM6: =INDIRECT("ZS(-1)",0) + INDIRECT("ZS(-3)",0) -> 1.2040162e+09 | NN6: =INDIRECT("ZS(-1)",0) / INDIRECT("Z7S(-1)",0) -> 0.83164139 | NO6: 1196497613 | NP6: 132541152 | NQ6: =INDIRECT("ZS(-1)",0) * 'Correction factor'!$C$13 -> 2.0513583e+08 | NR6: =INDIRECT("ZS(-1)",0) + INDIRECT("ZS(-3)",0) -> 1.4016334e+09 | NS6: =INDIRECT("ZS(-1)",0) / INDIRECT("Z7S(-1)",0) -> 0.99178992 | NT6: 1033278207 | NU6: 60349447 | NV6: =INDIRECT("ZS(-1)",0) * 'Correction factor'!$C$13 -> 93403698 | NW6: =INDIRECT("ZS(-1)",0) + INDIRECT("ZS(-3)",0) -> 1.1266819e+09 | NX6: =INDIRECT("ZS(-1)",0) / INDIRECT("Z7S(-1)",0) -> 0.83987536 | NY6: 1074417543 | NZ6: 59807670 | OA6: =INDIRECT("ZS(-1)",0) * 'Correction factor'!$C$13 -> 92565182 | OB6: =INDIRECT("ZS(-1)",0) + INDIRECT("ZS(-3)",0) -> 1.1669827e+09 | OC6: =INDIRECT("ZS(-1)",0) / INDIRECT("Z7S(-1)",0) -> 0.83121973 | OD6: 1092666193 | OE6: 68317381 | OF6: =INDIRECT("ZS(-1)",0) * 'Correction factor'!$C$13 -> 1.0573578e+08 | OG6: =INDIRECT("ZS(-1)",0) + INDIRECT("ZS(-3)",0) -> 1.198402e+09 | OH6: =INDIRECT("ZS(-1)",0) / INDIRECT("Z7S(-1)",0) -> 0.75816278 | OI6: 1055916517 | OJ6: 63467224 | OK6: =INDIRECT("ZS(-1)",0) * 'Correction factor'!$C$13 -> 98229126 | OL6: =INDIRECT("ZS(-1)",0) + INDIRECT("ZS(-3)",0) -> 1.1541456e+09 | OM6: =INDIRECT("ZS(-1)",0) / INDIRECT("Z7S(-1)",0) -> 0.79701468 | ON6: 1131379903 | OO6: 65240756 | OP6: =INDIRECT("ZS(-1)",0) * 'Correction factor'!$C$13 -> 1.0097405e+08 | OQ6: =INDIRECT("ZS(-1)",0) + INDIRECT("ZS(-3)",0) -> 1.2323539e+09 | OR6: =INDIRECT("ZS(-1)",0) / INDIRECT("Z7S(-1)",0) -> 0.85969115 | OS6: 1169499654 | OT6: 65043086 | OU6: =INDIRECT("ZS(-1)",0) * 'Correction factor'!$C$13 -> 1.0066811e+08 | OV6: =INDIRECT("ZS(-1)",0) + INDIRECT("ZS(-3)",0) -> 1.2701678e+09 | OW6: =INDIRECT("ZS(-1)",0) / INDIRECT("Z7S(-1)",0) -> 0.86607144 | OX6: 1186845270 | OY6: 64881991 | OZ6: =INDIRECT("ZS(-1)",0) * 'Correction factor'!$C$13 -> 1.0041878e+08 | PA6: =INDIRECT("ZS(-1)",0) + INDIRECT("ZS(-3)",0) -> 1.2872641e+09 | PB6: =INDIRECT("ZS(-1)",0) / INDIRECT("Z7S(-1)",0) -> 0.83443051 | PC6: 1086221573 | PD6: 64320637 | PE6: =INDIRECT("ZS(-1)",0) * 'Correction factor'!$C$13 -> 99549965 | PF6: =INDIRECT("ZS(-1)",0) + INDIRECT("ZS(-3)",0) -> 1.1857715e+09 | PG6: =INDIRECT("ZS(-1)",0) / INDIRECT("Z7S(-1)",0) -> 0.81577787 | PH6: 315048435 | PI6: 802519449 | PJ6: =INDIRECT("ZS(-1)",0) * 'Correction factor'!$C$13 -> 1.2420708e+09 | PK6: =INDIRECT("ZS(-1)",0) + INDIRECT("ZS(-3)",0) -> 1.5571192e+09 | PL6: =INDIRECT("ZS(-1)",0) / INDIRECT("Z7S(-1)",0) -> 0.95473039 | PM6: 297271173 | PN6: 781527372 | PO6: =INDIRECT("ZS(-1)",0) * 'Correction factor'!$C$13 -> 1.209581e+09 | PP6: =INDIRECT("ZS(-1)",0) + INDIRECT("ZS(-3)",0) -> 1.5068522e+09 | PQ6: =INDIRECT("ZS(-1)",0) / INDIRECT("Z7S(-1)",0) -> 0.96313463 | PR6: 302304293 | PS6: 727478325 | PT6: =INDIRECT("ZS(-1)",0) * 'Correction factor'!$C$13 -> 1.1259286e+09 | PU6: =INDIRECT("ZS(-1)",0) + INDIRECT("ZS(-3)",0) -> 1.4282328e+09 | PV6: =INDIRECT("ZS(-1)",0) / INDIRECT("Z7S(-1)",0) -> 0.91118204 | PW6: 271216853 | PX6: 665968393 | PY6: =INDIRECT("ZS(-1)",0) * 'Correction factor'!$C$13 -> 1.0307288e+09 | PZ6: =INDIRECT("ZS(-1)",0) + INDIRECT("ZS(-3)",0) -> 1.3019456e+09 | QA6: =INDIRECT("ZS(-1)",0) / INDIRECT("Z7S(-1)",0) -> 0.84556649 | QB6: 269872408 | QC6: 498094252 | QD6: =INDIRECT("ZS(-1)",0) * 'Correction factor'!$C$13 -> 7.7090756e+08 | QE6: =INDIRECT("ZS(-1)",0) + INDIRECT("ZS(-3)",0) -> 1.04078e+09 | QF6: =INDIRECT("ZS(-1)",0) / INDIRECT("Z7S(-1)",0) -> 0.87604374 | QG6: 272663657 | QH6: 640830759 | QI6: =INDIRECT("ZS(-1)",0) * 'Correction factor'!$C$13 -> 9.9182289e+08 | QJ6: =INDIRECT("ZS(-1)",0) + INDIRECT("ZS(-3)",0) -> 1.2644865e+09 | QK6: =INDIRECT("ZS(-1)",0) / INDIRECT("Z7S(-1)",0) -> 0.90806535 | QL6: 277591465 | QM6: 679350295 | QN6: =INDIRECT("ZS(-1)",0) * 'Correction factor'!$C$13 -> 1.0514401e+09 | QO6: =INDIRECT("ZS(-1)",0) + INDIRECT("ZS(-3)",0) -> 1.3290316e+09 | QP6: =INDIRECT("ZS(-1)",0) / INDIRECT("Z7S(-1)",0) -> 0.83847953 | QQ6: 275997594 | QR6: 726850019 | QS6: =INDIRECT("ZS(-1)",0) * 'Correction factor'!$C$13 -> 1.1249561e+09 | QT6: =INDIRECT("ZS(-1)",0) + INDIRECT("ZS(-3)",0) -> 1.4009537e+09 | QU6: =INDIRECT("ZS(-1)",0) / INDIRECT("Z7S(-1)",0) -> 0.92119188 | QV6: 291758799 | QW6: 751816332 | QX6: =INDIRECT("ZS(-1)",0) * 'Correction factor'!$C$13 -> 1.1635968e+09 | QY6: =INDIRECT("ZS(-1)",0) + INDIRECT("ZS(-3)",0) -> 1.4553556e+09 | QZ6: =INDIRECT("ZS(-1)",0) / INDIRECT("Z7S(-1)",0) -> 0.9052195 | RA6: 294521506 | RB6: 686936290 | RC6: =INDIRECT("ZS(-1)",0) * 'Correction factor'!$C$13 -> 1.0631811e+09 | RD6: =INDIRECT("ZS(-1)",0) + INDIRECT("ZS(-3)",0) -> 1.3577026e+09 | RE6: =INDIRECT("ZS(-1)",0) / INDIRECT("Z7S(-1)",0) -> 0.91123247 | RF6: 272316319 | RG6: 689893156 | RH6: =INDIRECT("ZS(-1)",0) * 'Correction factor'!$C$13 -> 1.0677575e+09 | RI6: =INDIRECT("ZS(-1)",0) + INDIRECT("ZS(-3)",0) -> 1.3400738e+09 | RJ6: =INDIRECT("ZS(-1)",0) / INDIRECT("Z7S(-1)",0) -> 0.8600287 | RK6: 277320937 | RL6: 613092188 | RM6: =INDIRECT("ZS(-1)",0) * 'Correction factor'!$C$13 -> 9.488915e+08 | RN6: =INDIRECT("ZS(-1)",0) + INDIRECT("ZS(-3)",0) -> 1.2262124e+09 | RO6: =INDIRECT("ZS(-1)",0) / INDIRECT("Z7S(-1)",0) -> 0.84954817
