Workbook
Name MethodPointer1: 18214176
Name MethodPointer2: 470

Sheet Calibration Plates
B3: Protokoll Calibration curve
B5: 1. Seed 50, 100, 200, 400, 800, 1600, 3200, 6400 cells in a 96 well plate on Monday (20.04.24)
C6: For a2
C7: For a3
C8: For a4
B9: 2. Add AlamarBlue on Tuesday morning
B10: 3. Wait 2h
B11: 4. Analyze in the plate reader
C13: a2 | D13: 1 | E13: 2 | F13: 3 | G13: 4 | H13: 5 | I13: 6 | J13: 7 | K13: 8 | L13: 9 | M13: 10 | N13: 11 | O13: 12 | S13: a3 | T13: 1 | U13: 2 | V13: 3 | W13: 4 | X13: 5 | Y13: 6 | Z13: 7 | AA13: 8 | AB13: 9 | AC13: 10 | AD13: 11 | AE13: 12 | AJ13: a4 | AK13: 1 | AL13: 2 | AM13: 3 | AN13: 4 | AO13: 5 | AP13: 6 | AQ13: 7 | AR13: 8 | AS13: 9 | AT13: 10 | AU13: 11 | AV13: 12
C14: A | S14: A | AJ14: A
C15: B | E15: 0 | F15: 50 | G15: 100 | H15: 200 | I15: 400 | J15: 800 | K15: 1600 | L15: 3200 | M15: 6400 | N15: Rho | S15: B | U15: 0 | V15: 50 | W15: 100 | X15: 200 | Y15: 400 | Z15: 800 | AA15: 1600 | AB15: 3200 | AC15: 6400 | AD15: Rho | AJ15: B | AL15: 0 | AM15: 50 | AN15: 100 | AO15: 200 | AP15: 400 | AQ15: 800 | AR15: 1600 | AS15: 3200 | AT15: 6400 | AU15: Rho
C16: C | E16: 0 | F16: 50 | G16: 100 | H16: 200 | I16: 400 | J16: 800 | K16: 1600 | L16: 3200 | M16: 6400 | N16: Rho | S16: C | U16: 0 | V16: 50 | W16: 100 | X16: 200 | Y16: 400 | Z16: 800 | AA16: 1600 | AB16: 3200 | AC16: 6400 | AD16: Rho | AJ16: C | AL16: 0 | AM16: 50 | AN16: 100 | AO16: 200 | AP16: 400 | AQ16: 800 | AR16: 1600 | AS16: 3200 | AT16: 6400 | AU16: Rho
C17: D | E17: 0 | F17: 50 | G17: 100 | H17: 200 | I17: 400 | J17: 800 | K17: 1600 | L17: 3200 | M17: 6400 | N17: Rho | S17: D | U17: 0 | V17: 50 | W17: 100 | X17: 200 | Y17: 400 | Z17: 800 | AA17: 1600 | AB17: 3200 | AC17: 6400 | AD17: Rho | AJ17: D | AL17: 0 | AM17: 50 | AN17: 100 | AO17: 200 | AP17: 400 | AQ17: 800 | AR17: 1600 | AS17: 3200 | AT17: 6400 | AU17: Rho
C18: E | E18: 0 | F18: 50 | G18: 100 | H18: 200 | I18: 400 | J18: 800 | K18: 1600 | L18: 3200 | M18: 6400 | N18: Rho | S18: E | U18: 0 | V18: 50 | W18: 100 | X18: 200 | Y18: 400 | Z18: 800 | AA18: 1600 | AB18: 3200 | AC18: 6400 | AD18: Rho | AJ18: E | AL18: 0 | AM18: 50 | AN18: 100 | AO18: 200 | AP18: 400 | AQ18: 800 | AR18: 1600 | AS18: 3200 | AT18: 6400 | AU18: Rho
C19: F | E19: 0 | F19: 50 | G19: 100 | H19: 200 | I19: 400 | J19: 800 | K19: 1600 | L19: 3200 | M19: 6400 | N19: Rho | S19: F | U19: 0 | V19: 50 | W19: 100 | X19: 200 | Y19: 400 | Z19: 800 | AA19: 1600 | AB19: 3200 | AC19: 6400 | AD19: Rho | AJ19: F | AL19: 0 | AM19: 50 | AN19: 100 | AO19: 200 | AP19: 400 | AQ19: 800 | AR19: 1600 | AS19: 3200 | AT19: 6400 | AU19: Rho
C20: G | E20: 0 | F20: 50 | G20: 100 | H20: 200 | I20: 400 | J20: 800 | K20: 1600 | L20: 3200 | M20: 6400 | N20: Rho | S20: G | U20: 0 | V20: 50 | W20: 100 | X20: 200 | Y20: 400 | Z20: 800 | AA20: 1600 | AB20: 3200 | AC20: 6400 | AD20: Rho | AJ20: G | AL20: 0 | AM20: 50 | AN20: 100 | AO20: 200 | AP20: 400 | AQ20: 800 | AR20: 1600 | AS20: 3200 | AT20: 6400 | AU20: Rho
C21: H | S21: H | AJ21: H
B24: Software Version | C24: 3.11.19 | R24: Software Version | S24: 3.11.19 | AI24: Software Version | AJ24: 3.11.19
B26: Experiment File Path: | C26: C:\Users\labadmin\Documents\Biotek Reader\Experiments\MaxE\2025_01_STEM_Preparation_experiments\2025_01_21_Calibration_plate_alpha2.xpt | R26: Experiment File Path: | S26: C:\Users\labadmin\Documents\Biotek Reader\Experiments\MaxE\2025_01_STEM_Preparation_experiments\2025_01_21_Calibration_plate_alpha2.xpt | AI26: Experiment File Path: | AJ26: C:\Users\labadmin\Documents\Biotek Reader\Experiments\MaxE\2025_01_STEM_Preparation_experiments\2025_01_21_Calibration_plate_alpha2.xpt
B27: Protocol File Path: | C27: C:\Users\labadmin\Documents\Biotek Reader\Protocols\Max\2025_01_21_calibration_plates\2025_01_21_calibration_plates.prt | R27: Protocol File Path: | S27: C:\Users\labadmin\Documents\Biotek Reader\Protocols\Max\2025_01_21_calibration_plates\2025_01_21_calibration_plates.prt | AI27: Protocol File Path: | AJ27: C:\Users\labadmin\Documents\Biotek Reader\Protocols\Max\2025_01_21_calibration_plates\2025_01_21_calibration_plates.prt
B28: Plate Number | C28: Plate 1 | R28: Plate Number | S28: Plate 2 | AI28: Plate Number | AJ28: Plate 3
B29: Date | C29: 45678 | R29: Date | S29: 45678 | AI29: Date | AJ29: 45678
B30: Time | C30: 0.56436343 | R30: Time | S30: 0.56777778 | AI30: Time | AJ30: 0.56951389
B31: Reader Type: | C31: Synergy H1 | R31: Reader Type: | S31: Synergy H1 | AI31: Reader Type: | AJ31: Synergy H1
B32: Reader Serial Number: | C32: 191202E | R32: Reader Serial Number: | S32: 191202E | AI32: Reader Serial Number: | AJ32: 191202E
B33: Reading Type | C33: Reader | R33: Reading Type | S33: Reader | AI33: Reading Type | AJ33: Reader
B35: Procedure Details | R35: Procedure Details | AI35: Procedure Details
B36: Plate Type | C36: 96 WELL PLATE | R36: Plate Type | S36: 96 WELL PLATE | AI36: Plate Type | AJ36: 96 WELL PLATE
B37: Eject plate on completion | R37: Eject plate on completion | AI37: Eject plate on completion
B38: Set Temperature | C38: Setpoint 37Â°C | R38: Set Temperature | S38: Setpoint 37Â°C | AI38: Set Temperature | AJ38: Setpoint 37Â°C
C39: Preheat before moving to next step | S39: Preheat before moving to next step | AJ39: Preheat before moving to next step
B40: Read | C40: Resazurin | R40: Read | S40: Resazurin | AI40: Read | AJ40: Resazurin
C41: Fluorescence Endpoint | S41: Fluorescence Endpoint | AJ41: Fluorescence Endpoint
C42: Full Plate | S42: Full Plate | AJ42: Full Plate
C43: Filter Set 1 | S43: Filter Set 1 | AJ43: Filter Set 1
C44: Excitation: 554, Emission: 593 | S44: Excitation: 554, Emission: 593 | AJ44: Excitation: 554, Emission: 593
C45: Optics: Bottom, Gain: 100 | S45: Optics: Bottom, Gain: 100 | AJ45: Optics: Bottom, Gain: 100
C46: Light Source: Xenon Flash, Lamp Energy: High | S46: Light Source: Xenon Flash, Lamp Energy: High | AJ46: Light Source: Xenon Flash, Lamp Energy: High
C47: Read Speed: Normal, Delay: 100 msec, Measurements/Data Point: 10 | S47: Read Speed: Normal, Delay: 100 msec, Measurements/Data Point: 10 | AJ47: Read Speed: Normal, Delay: 100 msec, Measurements/Data Point: 10
C48: Read Height: 7 mm | S48: Read Height: 7 mm | AJ48: Read Height: 7 mm
...

Sheet Drug Background Test
B2: Protokoll Drug Background
B4: 1. No cells, but different drug concentrations
B5: 2. Add AlamarBlue on Tuesday morning
B6: 3. Wait 2h
B7: 4. Analyze in the plate reader
D9: 1 | E9: 2 | F9: 3 | G9: 4 | H9: 5 | I9: 6 | J9: 7 | K9: 8 | L9: 9 | M9: 10 | N9: 11 | O9: 12
C10: A
C11: B | E11: 0 | F11: 64 | G11: 32 | H11: 16 | I11: 8 | J11: 5 | K11: 1 | L11: 0.2 | M11: 0.04 | N11: 0.008
C12: C | E12: 0 | F12: 64 | G12: 32 | H12: 16 | I12: 8 | J12: 5 | K12: 1 | L12: 0.2 | M12: 0.04 | N12: 0.008
C13: D | E13: 0 | F13: 64 | G13: 32 | H13: 16 | I13: 8 | J13: 5 | K13: 1 | L13: 0.2 | M13: 0.04 | N13: 0.008
C14: E | E14: 0 | F14: 64 | G14: 32 | H14: 16 | I14: 8 | J14: 5 | K14: 1 | L14: 0.2 | M14: 0.04 | N14: 0.008
C15: F | E15: 0 | F15: 64 | G15: 32 | H15: 16 | I15: 8 | J15: 5 | K15: 1 | L15: 0.2 | M15: 0.04 | N15: 0.008
C16: G | E16: 0 | F16: 64 | G16: 32 | H16: 16 | I16: 8 | J16: 5 | K16: 1 | L16: 0.2 | M16: 0.04 | N16: 0.008
C17: H
B19: Software Version | C19: 3.11.19
B21: Experiment File Path: | C21: C:\Users\labadmin\Documents\Biotek Reader\Experiments\MaxE\2025_01_STEM_Preparation_experiments\2025_01_23_test_0001.xpt
B22: Protocol File Path: | C22: C:\Users\labadmin\Documents\Biotek Reader\Protocols\Max\2025_01_22_G418_plates\2025_01_23_test.prt
B23: Plate Number | C23: Plate 1
B24: Date | C24: 45680
B25: Time | C25: 0.56650463
B26: Reader Type: | C26: Synergy H1
B27: Reader Serial Number: | C27: 191202E
B28: Reading Type | C28: Reader
B30: Procedure Details
B31: Plate Type | C31: 96 WELL PLATE
B32: Eject plate on completion
B33: Set Temperature | C33: Setpoint 37Â°C
C34: Preheat before moving to next step
B35: Read | C35: Resazurin
C36: Fluorescence Endpoint
C37: Full Plate
C38: Filter Set 1
C39: Excitation: 554, Emission: 593
C40: Optics: Bottom, Gain: 100
C41: Light Source: Xenon Flash, Lamp Energy: High
C42: Read Speed: Normal, Delay: 100 msec, Measurements/Data Point: 10
C43: Read Height: 7 mm
B45: Layout
D47: 1 | E47: 2 | F47: 3 | G47: 4 | H47: 5 | I47: 6 | J47: 7 | K47: 8 | L47: 9 | M47: 10 | N47: 11 | O47: 12
C48: A | P48: Well ID
...

Sheet G418 alpha-2
B2: Protokoll G418 Dose Response Curve
B4: 1. Seed 1000 cells in a 96 well plate on Monday (20.04.24)
C5: For a2
C6: For a3
C7: For a4
B8: 2. Add AlamarBlue on Tuesday morning
B9: 3. Wait 2h
B10: 4. Analyze in the plate reader
B12: 2025_01_22 | C12: a2 d2 | D12: 1 | E12: 2 | F12: 3 | G12: 4 | H12: 5 | I12: 6 | J12: 7 | K12: 8 | L12: 9 | M12: 10 | N12: 11 | O12: 12 | R12: a2 d2 | S12: 1 | T12: 2 | U12: 3 | V12: 4 | W12: 5 | X12: 6 | Y12: 7 | Z12: 8 | AA12: 9 | AB12: 10 | AC12: 11 | AD12: 12 | AH12: 2025_01_24 | AI12: a2 d2 | AJ12: 1 | AK12: 2 | AL12: 3 | AM12: 4 | AN12: 5 | AO12: 6 | AP12: 7 | AQ12: 8 | AR12: 9 | AS12: 10 | AT12: 11 | AU12: 12 | AX12: a2 d2 | AY12: 1 | AZ12: 2 | BA12: 3 | BB12: 4 | BC12: 5 | BD12: 6 | BE12: 7 | BF12: 8 | BG12: 9 | BH12: 10 | BI12: 11 | BJ12: 12 | BN12: 2025_01_27 | BO12: a2 d5 | BP12: 1 | BQ12: 2 | BR12: 3 | BS12: 4 | BT12: 5 | BU12: 6 | BV12: 7 | BW12: 8 | BX12: 9 | BY12: 10 | BZ12: 11 | CA12: 12 | CD12: a2 d5 | CE12: 1 | CF12: 2 | CG12: 3 | CH12: 4 | CI12: 5 | CJ12: 6 | CK12: 7 | CL12: 8 | CM12: 9 | CN12: 10 | CO12: 11 | CP12: 12 | CT12: 2025_01_29 | CU12: a2 d7 | CV12: 1 | CW12: 2 | CX12: 3 | CY12: 4 | CZ12: 5 | DA12: 6 | DB12: 7 | DC12: 8 | DD12: 9 | DE12: 10 | DF12: 11 | DG12: 12 | DJ12: a2 d7 | DK12: 1 | DL12: 2 | DM12: 3 | DN12: 4 | DO12: 5 | DP12: 6 | DQ12: 7 | DR12: 8 | DS12: 9 | DT12: 10 | DU12: 11 | DV12: 12
C13: A | R13: A | AI13: A | AX13: A | BO13: A | CD13: A | CU13: A | DJ13: A
C14: B | E14: BLANK | F14: Rho | G14: 0 | H14: 0 | I14: 0 | J14: 0 | K14: 0 | L14: 0 | M14: 0 | N14: 0 | R14: B | T14: BLANK | U14: Rho | V14: 0.4 | W14: 0.4 | X14: 0.4 | Y14: 0.4 | Z14: 0.4 | AA14: 0.4 | AB14: 0.4 | AC14: 0.4 | AI14: B | AK14: BLANK | AL14: Rho | AM14: 0 | AN14: 0 | AO14: 0 | AP14: 0 | AQ14: 0 | AR14: 0 | AS14: 0 | AT14: 0 | AX14: B | AZ14: BLANK | BA14: Rho | BB14: 0.4 | BC14: 0.4 | BD14: 0.4 | BE14: 0.4 | BF14: 0.4 | BG14: 0.4 | BH14: 0.4 | BI14: 0.4 | BO14: B | BQ14: BLANK | BR14: Rho | BS14: 0 | BT14: 0 | BU14: 0 | BV14: 0 | BW14: 0 | BX14: 0 | BY14: 0 | BZ14: 0 | CD14: B | CF14: BLANK | CG14: Rho | CH14: 0.4 | CI14: 0.4 | CJ14: 0.4 | CK14: 0.4 | CL14: 0.4 | CM14: 0.4 | CN14: 0.4 | CO14: 0.4 | CU14: B | CW14: BLANK | CX14: Rho | CY14: 0 | CZ14: 0 | DA14: 0 | DB14: 0 | DC14: 0 | DD14: 0 | DE14: 0 | DF14: 0 | DJ14: B | DL14: BLANK | DM14: Rho | DN14: 0.4 | DO14: 0.4 | DP14: 0.4 | DQ14: 0.4 | DR14: 0.4 | DS14: 0.4 | DT14: 0.4 | DU14: 0.4
C15: C | E15: BLANK | F15: Rho | G15: 0.025 | H15: 0.025 | I15: 0.025 | J15: 0.025 | K15: 0.025 | L15: 0.025 | M15: 0.025 | N15: 0.025 | R15: C | T15: BLANK | U15: Rho | V15: 0.6 | W15: 0.6 | X15: 0.6 | Y15: 0.6 | Z15: 0.6 | AA15: 0.6 | AB15: 0.6 | AC15: 0.6 | AI15: C | AK15: BLANK | AL15: Rho | AM15: 0.025 | AN15: 0.025 | AO15: 0.025 | AP15: 0.025 | AQ15: 0.025 | AR15: 0.025 | AS15: 0.025 | AT15: 0.025 | AX15: C | AZ15: BLANK | BA15: Rho | BB15: 0.6 | BC15: 0.6 | BD15: 0.6 | BE15: 0.6 | BF15: 0.6 | BG15: 0.6 | BH15: 0.6 | BI15: 0.6 | BO15: C | BQ15: BLANK | BR15: Rho | BS15: 0.025 | BT15: 0.025 | BU15: 0.025 | BV15: 0.025 | BW15: 0.025 | BX15: 0.025 | BY15: 0.025 | BZ15: 0.025 | CD15: C | CF15: BLANK | CG15: Rho | CH15: 0.6 | CI15: 0.6 | CJ15: 0.6 | CK15: 0.6 | CL15: 0.6 | CM15: 0.6 | CN15: 0.6 | CO15: 0.6 | CU15: C | CW15: BLANK | CX15: Rho | CY15: 0.025 | CZ15: 0.025 | DA15: 0.025 | DB15: 0.025 | DC15: 0.025 | DD15: 0.025 | DE15: 0.025 | DF15: 0.025 | DJ15: C | DL15: BLANK | DM15: Rho | DN15: 0.6 | DO15: 0.6 | DP15: 0.6 | DQ15: 0.6 | DR15: 0.6 | DS15: 0.6 | DT15: 0.6 | DU15: 0.6
C16: D | E16: BLANK | F16: Rho | G16: 0.05 | H16: 0.05 | I16: 0.05 | J16: 0.05 | K16: 0.05 | L16: 0.05 | M16: 0.05 | N16: 0.05 | R16: D | T16: BLANK | U16: Rho | V16: 0.8 | W16: 0.8 | X16: 0.8 | Y16: 0.8 | Z16: 0.8 | AA16: 0.8 | AB16: 0.8 | AC16: 0.8 | AI16: D | AK16: BLANK | AL16: Rho | AM16: 0.05 | AN16: 0.05 | AO16: 0.05 | AP16: 0.05 | AQ16: 0.05 | AR16: 0.05 | AS16: 0.05 | AT16: 0.05 | AX16: D | AZ16: BLANK | BA16: Rho | BB16: 0.8 | BC16: 0.8 | BD16: 0.8 | BE16: 0.8 | BF16: 0.8 | BG16: 0.8 | BH16: 0.8 | BI16: 0.8 | BO16: D | BQ16: BLANK | BR16: Rho | BS16: 0.05 | BT16: 0.05 | BU16: 0.05 | BV16: 0.05 | BW16: 0.05 | BX16: 0.05 | BY16: 0.05 | BZ16: 0.05 | CD16: D | CF16: BLANK | CG16: Rho | CH16: 0.8 | CI16: 0.8 | CJ16: 0.8 | CK16: 0.8 | CL16: 0.8 | CM16: 0.8 | CN16: 0.8 | CO16: 0.8 | CU16: D | CW16: BLANK | CX16: Rho | CY16: 0.05 | CZ16: 0.05 | DA16: 0.05 | DB16: 0.05 | DC16: 0.05 | DD16: 0.05 | DE16: 0.05 | DF16: 0.05 | DJ16: D | DL16: BLANK | DM16: Rho | DN16: 0.8 | DO16: 0.8 | DP16: 0.8 | DQ16: 0.8 | DR16: 0.8 | DS16: 0.8 | DT16: 0.8 | DU16: 0.8
C17: E | E17: BLANK | F17: Rho | G17: 0.1 | H17: 0.1 | I17: 0.1 | J17: 0.1 | K17: 0.1 | L17: 0.1 | M17: 0.1 | N17: 0.1 | R17: E | T17: BLANK | U17: Rho | V17: 1 | W17: 1 | X17: 1 | Y17: 1 | Z17: 1 | AA17: 1 | AB17: 1 | AC17: 1 | AI17: E | AK17: BLANK | AL17: Rho | AM17: 0.1 | AN17: 0.1 | AO17: 0.1 | AP17: 0.1 | AQ17: 0.1 | AR17: 0.1 | AS17: 0.1 | AT17: 0.1 | AX17: E | AZ17: BLANK | BA17: Rho | BB17: 1 | BC17: 1 | BD17: 1 | BE17: 1 | BF17: 1 | BG17: 1 | BH17: 1 | BI17: 1 | BO17: E | BQ17: BLANK | BR17: Rho | BS17: 0.1 | BT17: 0.1 | BU17: 0.1 | BV17: 0.1 | BW17: 0.1 | BX17: 0.1 | BY17: 0.1 | BZ17: 0.1 | CD17: E | CF17: BLANK | CG17: Rho | CH17: 1 | CI17: 1 | CJ17: 1 | CK17: 1 | CL17: 1 | CM17: 1 | CN17: 1 | CO17: 1 | CU17: E | CW17: BLANK | CX17: Rho | CY17: 0.1 | CZ17: 0.1 | DA17: 0.1 | DB17: 0.1 | DC17: 0.1 | DD17: 0.1 | DE17: 0.1 | DF17: 0.1 | DJ17: E | DL17: BLANK | DM17: Rho | DN17: 1 | DO17: 1 | DP17: 1 | DQ17: 1 | DR17: 1 | DS17: 1 | DT17: 1 | DU17: 1
C18: F | E18: BLANK | F18: Rho | G18: 0.2 | H18: 0.2 | I18: 0.2 | J18: 0.2 | K18: 0.2 | L18: 0.2 | M18: 0.2 | N18: 0.2 | R18: F | T18: BLANK | U18: Rho | V18: 2 | W18: 2 | X18: 2 | Y18: 2 | Z18: 2 | AA18: 2 | AB18: 2 | AC18: 2 | AI18: F | AK18: BLANK | AL18: Rho | AM18: 0.2 | AN18: 0.2 | AO18: 0.2 | AP18: 0.2 | AQ18: 0.2 | AR18: 0.2 | AS18: 0.2 | AT18: 0.2 | AX18: F | AZ18: BLANK | BA18: Rho | BB18: 2 | BC18: 2 | BD18: 2 | BE18: 2 | BF18: 2 | BG18: 2 | BH18: 2 | BI18: 2 | BO18: F | BQ18: BLANK | BR18: Rho | BS18: 0.2 | BT18: 0.2 | BU18: 0.2 | BV18: 0.2 | BW18: 0.2 | BX18: 0.2 | BY18: 0.2 | BZ18: 0.2 | CD18: F | CF18: BLANK | CG18: Rho | CH18: 2 | CI18: 2 | CJ18: 2 | CK18: 2 | CL18: 2 | CM18: 2 | CN18: 2 | CO18: 2 | CU18: F | CW18: BLANK | CX18: Rho | CY18: 0.2 | CZ18: 0.2 | DA18: 0.2 | DB18: 0.2 | DC18: 0.2 | DD18: 0.2 | DE18: 0.2 | DF18: 0.2 | DJ18: F | DL18: BLANK | DM18: Rho | DN18: 2 | DO18: 2 | DP18: 2 | DQ18: 2 | DR18: 2 | DS18: 2 | DT18: 2 | DU18: 2
C19: G | E19: BLANK | F19: Rho | G19: 0.3 | H19: 0.3 | I19: 0.3 | J19: 0.3 | K19: 0.3 | L19: 0.3 | M19: 0.3 | N19: 0.3 | R19: G | T19: BLANK | U19: Rho | V19: 5 | W19: 5 | X19: 5 | Y19: 5 | Z19: 5 | AA19: 5 | AB19: 5 | AC19: 5 | AI19: G | AK19: BLANK | AL19: Rho | AM19: 0.3 | AN19: 0.3 | AO19: 0.3 | AP19: 0.3 | AQ19: 0.3 | AR19: 0.3 | AS19: 0.3 | AT19: 0.3 | AX19: G | AZ19: BLANK | BA19: Rho | BB19: 5 | BC19: 5 | BD19: 5 | BE19: 5 | BF19: 5 | BG19: 5 | BH19: 5 | BI19: 5 | BO19: G | BQ19: BLANK | BR19: Rho | BS19: 0.3 | BT19: 0.3 | BU19: 0.3 | BV19: 0.3 | BW19: 0.3 | BX19: 0.3 | BY19: 0.3 | BZ19: 0.3 | CD19: G | CF19: BLANK | CG19: Rho | CH19: 5 | CI19: 5 | CJ19: 5 | CK19: 5 | CL19: 5 | CM19: 5 | CN19: 5 | CO19: 5 | CU19: G | CW19: BLANK | CX19: Rho | CY19: 0.3 | CZ19: 0.3 | DA19: 0.3 | DB19: 0.3 | DC19: 0.3 | DD19: 0.3 | DE19: 0.3 | DF19: 0.3 | DJ19: G | DL19: BLANK | DM19: Rho | DN19: 5 | DO19: 5 | DP19: 5 | DQ19: 5 | DR19: 5 | DS19: 5 | DT19: 5 | DU19: 5
C20: H | R20: H | AI20: H | AX20: H | BO20: H | CD20: H | CU20: H | DJ20: H
B22: Software Version | C22: 3.11.19 | R22: Software Version | S22: 3.11.19 | AH22: Software Version | AI22: 3.11.19 | AX22: Software Version | AY22: 3.11.19 | BN22: Software Version | BO22: 3.11.19 | CD22: Software Version | CE22: 3.11.19 | CT22: Software Version | CU22: 3.11.19 | DJ22: Software Version | DK22: 3.11.19
B24: Experiment File Path: | C24: C:\Users\labadmin\Documents\Biotek Reader\Experiments\MaxE\2025_01_STEM_Preparation_experiments\2025_01_22_d2_G418_plates_1.xpt | R24: Experiment File Path: | S24: C:\Users\labadmin\Documents\Biotek Reader\Experiments\MaxE\2025_01_STEM_Preparation_experiments\2025_01_22_d2_G418_plates_1.xpt | AH24: Experiment File Path: | AI24: C:\Users\labadmin\Documents\Biotek Reader\Experiments\MaxE\2025_01_STEM_Preparation_experiments\2025_01_24_d4_G418_plates_1.xpt | AX24: Experiment File Path: | AY24: C:\Users\labadmin\Documents\Biotek Reader\Experiments\MaxE\2025_01_STEM_Preparation_experiments\2025_01_24_d4_G418_plates_1.xpt | BN24: Experiment File Path: | BO24: C:\Users\labadmin\Documents\Biotek Reader\Experiments\MaxE\2025_01_STEM_Preparation_experiments\2025_01_27_d7_G418_plates_1.xpt | CD24: Experiment File Path: | CE24: C:\Users\labadmin\Documents\Biotek Reader\Experiments\MaxE\2025_01_STEM_Preparation_experiments\2025_01_27_d7_G418_plates_1.xpt | CT24: Experiment File Path: | CU24: C:\Users\labadmin\Documents\Biotek Reader\Experiments\MaxE\2025_01_STEM_Preparation_experiments\2025_01_29_d9_G418_plates_1.xpt | DJ24: Experiment File Path: | DK24: C:\Users\labadmin\Documents\Biotek Reader\Experiments\MaxE\2025_01_STEM_Preparation_experiments\2025_01_29_d9_G418_plates_1.xpt
B25: Protocol File Path: | C25: C:\Users\labadmin\Documents\Biotek Reader\Protocols\Max\2025_01_22_G418_plates\2025_01_22_d2_G418_plates.prt | R25: Protocol File Path: | S25: C:\Users\labadmin\Documents\Biotek Reader\Protocols\Max\2025_01_22_G418_plates\2025_01_22_d2_G418_plates.prt | AH25: Protocol File Path: | AI25: C:\Users\labadmin\Documents\Biotek Reader\Protocols\Max\2025_01_22_G418_plates\2025_01_22_d2_G418_plates.prt | AX25: Protocol File Path: | AY25: C:\Users\labadmin\Documents\Biotek Reader\Protocols\Max\2025_01_22_G418_plates\2025_01_22_d2_G418_plates.prt | BN25: Protocol File Path: | BO25: C:\Users\labadmin\Documents\Biotek Reader\Protocols\Max\2025_01_22_G418_plates\2025_01_22_d2_G418_plates.prt | CD25: Protocol File Path: | CE25: C:\Users\labadmin\Documents\Biotek Reader\Protocols\Max\2025_01_22_G418_plates\2025_01_22_d2_G418_plates.prt | CT25: Protocol File Path: | CU25: C:\Users\labadmin\Documents\Biotek Reader\Protocols\Max\2025_01_22_G418_plates\2025_01_22_d2_G418_plates.prt | DJ25: Protocol File Path: | DK25: C:\Users\labadmin\Documents\Biotek Reader\Protocols\Max\2025_01_22_G418_plates\2025_01_22_d2_G418_plates.prt
B26: Plate Number | C26: Plate 1 | R26: Plate Number | S26: Plate 4 | AH26: Plate Number | AI26: Plate 1 | AX26: Plate Number | AY26: Plate 4 | BN26: Plate Number | BO26: Plate 1 | CD26: Plate Number | CE26: Plate 4 | CT26: Plate Number | CU26: Plate 1 | DJ26: Plate Number | DK26: Plate 4
B27: Date | C27: 45679 | R27: Date | S27: 45679 | AH27: Date | AI27: 45681 | AX27: Date | AY27: 45681 | BN27: Date | BO27: 45684 | CD27: Date | CE27: 45684 | CT27: Date | CU27: 45686 | DJ27: Date | DK27: 45686
B28: Time | C28: 0.57074074 | R28: Time | S28: 0.5765625 | AH28: Time | AI28: 0.56630787 | AX28: Time | AY28: 0.57150463 | BN28: Time | BO28: 0.57375 | CD28: Time | CE28: 0.5855787 | CT28: Time | CU28: 0.57672454 | DJ28: Time | DK28: 0.5837963
B29: Reader Type: | C29: Synergy H1 | R29: Reader Type: | S29: Synergy H1 | AH29: Reader Type: | AI29: Synergy H1 | AX29: Reader Type: | AY29: Synergy H1 | BN29: Reader Type: | BO29: Synergy H1 | CD29: Reader Type: | CE29: Synergy H1 | CT29: Reader Type: | CU29: Synergy H1 | DJ29: Reader Type: | DK29: Synergy H1
B30: Reader Serial Number: | C30: 191202E | R30: Reader Serial Number: | S30: 191202E | AH30: Reader Serial Number: | AI30: 191202E | AX30: Reader Serial Number: | AY30: 191202E | BN30: Reader Serial Number: | BO30: 191202E | CD30: Reader Serial Number: | CE30: 191202E | CT30: Reader Serial Number: | CU30: 191202E | DJ30: Reader Serial Number: | DK30: 191202E
B31: Reading Type | C31: Reader | R31: Reading Type | S31: Reader | AH31: Reading Type | AI31: Reader | AX31: Reading Type | AY31: Reader | BN31: Reading Type | BO31: Reader | CD31: Reading Type | CE31: Reader | CT31: Reading Type | CU31: Reader | DJ31: Reading Type | DK31: Reader
B33: Procedure Details | R33: Procedure Details | AH33: Procedure Details | AX33: Procedure Details | BN33: Procedure Details | CD33: Procedure Details | CT33: Procedure Details | DJ33: Procedure Details
B34: Plate Type | C34: 96 WELL PLATE | R34: Plate Type | S34: 96 WELL PLATE | AH34: Plate Type | AI34: 96 WELL PLATE | AX34: Plate Type | AY34: 96 WELL PLATE | BN34: Plate Type | BO34: 96 WELL PLATE | CD34: Plate Type | CE34: 96 WELL PLATE | CT34: Plate Type | CU34: 96 WELL PLATE | DJ34: Plate Type | DK34: 96 WELL PLATE
B35: Eject plate on completion | R35: Eject plate on completion | AH35: Eject plate on completion | AX35: Eject plate on completion | BN35: Eject plate on completion | CD35: Eject plate on completion | CT35: Eject plate on completion | DJ35: Eject plate on completion
B36: Set Temperature | C36: Setpoint 37Â°C | R36: Set Temperature | S36: Setpoint 37Â°C | AH36: Set Temperature | AI36: Setpoint 37Â°C | AX36: Set Temperature | AY36: Setpoint 37Â°C | BN36: Set Temperature | BO36: Setpoint 37Â°C | CD36: Set Temperature | CE36: Setpoint 37Â°C | CT36: Set Temperature | CU36: Setpoint 37Â°C | DJ36: Set Temperature | DK36: Setpoint 37Â°C
C37: Preheat before moving to next step | S37: Preheat before moving to next step | AI37: Preheat before moving to next step | AY37: Preheat before moving to next step | BO37: Preheat before moving to next step | CE37: Preheat before moving to next step | CU37: Preheat before moving to next step | DK37: Preheat before moving to next step
B38: Read | C38: Resazurin | R38: Read | S38: Resazurin | AH38: Read | AI38: Resazurin | AX38: Read | AY38: Resazurin | BN38: Read | BO38: Resazurin | CD38: Read | CE38: Resazurin | CT38: Read | CU38: Resazurin | DJ38: Read | DK38: Resazurin
C39: Fluorescence Endpoint | S39: Fluorescence Endpoint | AI39: Fluorescence Endpoint | AY39: Fluorescence Endpoint | BO39: Fluorescence Endpoint | CE39: Fluorescence Endpoint | CU39: Fluorescence Endpoint | DK39: Fluorescence Endpoint
C40: Full Plate | S40: Full Plate | AI40: Full Plate | AY40: Full Plate | BO40: Full Plate | CE40: Full Plate | CU40: Full Plate | DK40: Full Plate
C41: Filter Set 1 | S41: Filter Set 1 | AI41: Filter Set 1 | AY41: Filter Set 1 | BO41: Filter Set 1 | CE41: Filter Set 1 | CU41: Filter Set 1 | DK41: Filter Set 1
C42: Excitation: 554, Emission: 593 | S42: Excitation: 554, Emission: 593 | AI42: Excitation: 554, Emission: 593 | AY42: Excitation: 554, Emission: 593 | BO42: Excitation: 554, Emission: 593 | CE42: Excitation: 554, Emission: 593 | CU42: Excitation: 554, Emission: 593 | DK42: Excitation: 554, Emission: 593
C43: Optics: Bottom, Gain: 100 | S43: Optics: Bottom, Gain: 100 | AI43: Optics: Bottom, Gain: 100 | AY43: Optics: Bottom, Gain: 100 | BO43: Optics: Bottom, Gain: 100 | CE43: Optics: Bottom, Gain: 100 | CU43: Optics: Bottom, Gain: 100 | DK43: Optics: Bottom, Gain: 100
C44: Light Source: Xenon Flash, Lamp Energy: High | S44: Light Source: Xenon Flash, Lamp Energy: High | AI44: Light Source: Xenon Flash, Lamp Energy: High | AY44: Light Source: Xenon Flash, Lamp Energy: High | BO44: Light Source: Xenon Flash, Lamp Energy: High | CE44: Light Source: Xenon Flash, Lamp Energy: High | CU44: Light Source: Xenon Flash, Lamp Energy: High | DK44: Light Source: Xenon Flash, Lamp Energy: High
C45: Read Speed: Normal, Delay: 100 msec, Measurements/Data Point: 10 | S45: Read Speed: Normal, Delay: 100 msec, Measurements/Data Point: 10 | AI45: Read Speed: Normal, Delay: 100 msec, Measurements/Data Point: 10 | AY45: Read Speed: Normal, Delay: 100 msec, Measurements/Data Point: 10 | BO45: Read Speed: Normal, Delay: 100 msec, Measurements/Data Point: 10 | CE45: Read Speed: Normal, Delay: 100 msec, Measurements/Data Point: 10 | CU45: Read Speed: Normal, Delay: 100 msec, Measurements/Data Point: 10 | DK45: Read Speed: Normal, Delay: 100 msec, Measurements/Data Point: 10
C46: Read Height: 7 mm | S46: Read Height: 7 mm | AI46: Read Height: 7 mm | AY46: Read Height: 7 mm | BO46: Read Height: 7 mm | CE46: Read Height: 7 mm | CU46: Read Height: 7 mm | DK46: Read Height: 7 mm
...

Sheet G418 alpha-3
B2: Protokoll G418 Dose Response Curve
B4: 1. Seed 1000 cells in a 96 well plate on Monday (20.04.24)
C5: For a2
C6: For a3
C7: For a4
B8: 2. Add AlamarBlue on Tuesday morning
B9: 3. Wait 2h
B10: 4. Analyze in the plate reader
B12: 2025_01_22 | C12: a3 d2 | D12: 1 | E12: 2 | F12: 3 | G12: 4 | H12: 5 | I12: 6 | J12: 7 | K12: 8 | L12: 9 | M12: 10 | N12: 11 | O12: 12 | R12: a3 d2 | S12: 1 | T12: 2 | U12: 3 | V12: 4 | W12: 5 | X12: 6 | Y12: 7 | Z12: 8 | AA12: 9 | AB12: 10 | AC12: 11 | AD12: 12 | AH12: 2025_01_24 | AI12: a3 d2 | AJ12: 1 | AK12: 2 | AL12: 3 | AM12: 4 | AN12: 5 | AO12: 6 | AP12: 7 | AQ12: 8 | AR12: 9 | AS12: 10 | AT12: 11 | AU12: 12 | AX12: a3 d2 | AY12: 1 | AZ12: 2 | BA12: 3 | BB12: 4 | BC12: 5 | BD12: 6 | BE12: 7 | BF12: 8 | BG12: 9 | BH12: 10 | BI12: 11 | BJ12: 12 | BN12: 2025_01_27 | BO12: a3 d5 | BP12: 1 | BQ12: 2 | BR12: 3 | BS12: 4 | BT12: 5 | BU12: 6 | BV12: 7 | BW12: 8 | BX12: 9 | BY12: 10 | BZ12: 11 | CA12: 12 | CD12: a3 d5 | CE12: 1 | CF12: 2 | CG12: 3 | CH12: 4 | CI12: 5 | CJ12: 6 | CK12: 7 | CL12: 8 | CM12: 9 | CN12: 10 | CO12: 11 | CP12: 12 | CT12: 2025_01_29 | CU12: a3 d7 | CV12: 1 | CW12: 2 | CX12: 3 | CY12: 4 | CZ12: 5 | DA12: 6 | DB12: 7 | DC12: 8 | DD12: 9 | DE12: 10 | DF12: 11 | DG12: 12 | DJ12: a3 d7 | DK12: 1 | DL12: 2 | DM12: 3 | DN12: 4 | DO12: 5 | DP12: 6 | DQ12: 7 | DR12: 8 | DS12: 9 | DT12: 10 | DU12: 11 | DV12: 12
C13: A | R13: A | AI13: A | AX13: A | BO13: A | CD13: A | CU13: A | DJ13: A
C14: B | E14: BLANK | F14: Rho | G14: 0 | H14: 0 | I14: 0 | J14: 0 | K14: 0 | L14: 0 | M14: 0 | N14: 0 | R14: B | T14: BLANK | U14: Rho | V14: 0.4 | W14: 0.4 | X14: 0.4 | Y14: 0.4 | Z14: 0.4 | AA14: 0.4 | AB14: 0.4 | AC14: 0.4 | AI14: B | AK14: BLANK | AL14: Rho | AM14: 0 | AN14: 0 | AO14: 0 | AP14: 0 | AQ14: 0 | AR14: 0 | AS14: 0 | AT14: 0 | AX14: B | AZ14: BLANK | BA14: Rho | BB14: 0.4 | BC14: 0.4 | BD14: 0.4 | BE14: 0.4 | BF14: 0.4 | BG14: 0.4 | BH14: 0.4 | BI14: 0.4 | BO14: B | BQ14: BLANK | BR14: Rho | BS14: 0 | BT14: 0 | BU14: 0 | BV14: 0 | BW14: 0 | BX14: 0 | BY14: 0 | BZ14: 0 | CD14: B | CF14: BLANK | CG14: Rho | CH14: 0.4 | CI14: 0.4 | CJ14: 0.4 | CK14: 0.4 | CL14: 0.4 | CM14: 0.4 | CN14: 0.4 | CO14: 0.4 | CU14: B | CW14: BLANK | CX14: Rho | CY14: 0 | CZ14: 0 | DA14: 0 | DB14: 0 | DC14: 0 | DD14: 0 | DE14: 0 | DF14: 0 | DJ14: B | DL14: BLANK | DM14: Rho | DN14: 0.4 | DO14: 0.4 | DP14: 0.4 | DQ14: 0.4 | DR14: 0.4 | DS14: 0.4 | DT14: 0.4 | DU14: 0.4
C15: C | E15: BLANK | F15: Rho | G15: 0.025 | H15: 0.025 | I15: 0.025 | J15: 0.025 | K15: 0.025 | L15: 0.025 | M15: 0.025 | N15: 0.025 | R15: C | T15: BLANK | U15: Rho | V15: 0.6 | W15: 0.6 | X15: 0.6 | Y15: 0.6 | Z15: 0.6 | AA15: 0.6 | AB15: 0.6 | AC15: 0.6 | AI15: C | AK15: BLANK | AL15: Rho | AM15: 0.025 | AN15: 0.025 | AO15: 0.025 | AP15: 0.025 | AQ15: 0.025 | AR15: 0.025 | AS15: 0.025 | AT15: 0.025 | AX15: C | AZ15: BLANK | BA15: Rho | BB15: 0.6 | BC15: 0.6 | BD15: 0.6 | BE15: 0.6 | BF15: 0.6 | BG15: 0.6 | BH15: 0.6 | BI15: 0.6 | BO15: C | BQ15: BLANK | BR15: Rho | BS15: 0.025 | BT15: 0.025 | BU15: 0.025 | BV15: 0.025 | BW15: 0.025 | BX15: 0.025 | BY15: 0.025 | BZ15: 0.025 | CD15: C | CF15: BLANK | CG15: Rho | CH15: 0.6 | CI15: 0.6 | CJ15: 0.6 | CK15: 0.6 | CL15: 0.6 | CM15: 0.6 | CN15: 0.6 | CO15: 0.6 | CU15: C | CW15: BLANK | CX15: Rho | CY15: 0.025 | CZ15: 0.025 | DA15: 0.025 | DB15: 0.025 | DC15: 0.025 | DD15: 0.025 | DE15: 0.025 | DF15: 0.025 | DJ15: C | DL15: BLANK | DM15: Rho | DN15: 0.6 | DO15: 0.6 | DP15: 0.6 | DQ15: 0.6 | DR15: 0.6 | DS15: 0.6 | DT15: 0.6 | DU15: 0.6
C16: D | E16: BLANK | F16: Rho | G16: 0.05 | H16: 0.05 | I16: 0.05 | J16: 0.05 | K16: 0.05 | L16: 0.05 | M16: 0.05 | N16: 0.05 | R16: D | T16: BLANK | U16: Rho | V16: 0.8 | W16: 0.8 | X16: 0.8 | Y16: 0.8 | Z16: 0.8 | AA16: 0.8 | AB16: 0.8 | AC16: 0.8 | AI16: D | AK16: BLANK | AL16: Rho | AM16: 0.05 | AN16: 0.05 | AO16: 0.05 | AP16: 0.05 | AQ16: 0.05 | AR16: 0.05 | AS16: 0.05 | AT16: 0.05 | AX16: D | AZ16: BLANK | BA16: Rho | BB16: 0.8 | BC16: 0.8 | BD16: 0.8 | BE16: 0.8 | BF16: 0.8 | BG16: 0.8 | BH16: 0.8 | BI16: 0.8 | BO16: D | BQ16: BLANK | BR16: Rho | BS16: 0.05 | BT16: 0.05 | BU16: 0.05 | BV16: 0.05 | BW16: 0.05 | BX16: 0.05 | BY16: 0.05 | BZ16: 0.05 | CD16: D | CF16: BLANK | CG16: Rho | CH16: 0.8 | CI16: 0.8 | CJ16: 0.8 | CK16: 0.8 | CL16: 0.8 | CM16: 0.8 | CN16: 0.8 | CO16: 0.8 | CU16: D | CW16: BLANK | CX16: Rho | CY16: 0.05 | CZ16: 0.05 | DA16: 0.05 | DB16: 0.05 | DC16: 0.05 | DD16: 0.05 | DE16: 0.05 | DF16: 0.05 | DJ16: D | DL16: BLANK | DM16: Rho | DN16: 0.8 | DO16: 0.8 | DP16: 0.8 | DQ16: 0.8 | DR16: 0.8 | DS16: 0.8 | DT16: 0.8 | DU16: 0.8
C17: E | E17: BLANK | F17: Rho | G17: 0.1 | H17: 0.1 | I17: 0.1 | J17: 0.1 | K17: 0.1 | L17: 0.1 | M17: 0.1 | N17: 0.1 | R17: E | T17: BLANK | U17: Rho | V17: 1 | W17: 1 | X17: 1 | Y17: 1 | Z17: 1 | AA17: 1 | AB17: 1 | AC17: 1 | AI17: E | AK17: BLANK | AL17: Rho | AM17: 0.1 | AN17: 0.1 | AO17: 0.1 | AP17: 0.1 | AQ17: 0.1 | AR17: 0.1 | AS17: 0.1 | AT17: 0.1 | AX17: E | AZ17: BLANK | BA17: Rho | BB17: 1 | BC17: 1 | BD17: 1 | BE17: 1 | BF17: 1 | BG17: 1 | BH17: 1 | BI17: 1 | BO17: E | BQ17: BLANK | BR17: Rho | BS17: 0.1 | BT17: 0.1 | BU17: 0.1 | BV17: 0.1 | BW17: 0.1 | BX17: 0.1 | BY17: 0.1 | BZ17: 0.1 | CD17: E | CF17: BLANK | CG17: Rho | CH17: 1 | CI17: 1 | CJ17: 1 | CK17: 1 | CL17: 1 | CM17: 1 | CN17: 1 | CO17: 1 | CU17: E | CW17: BLANK | CX17: Rho | CY17: 0.1 | CZ17: 0.1 | DA17: 0.1 | DB17: 0.1 | DC17: 0.1 | DD17: 0.1 | DE17: 0.1 | DF17: 0.1 | DJ17: E | DL17: BLANK | DM17: Rho | DN17: 1 | DO17: 1 | DP17: 1 | DQ17: 1 | DR17: 1 | DS17: 1 | DT17: 1 | DU17: 1
C18: F | E18: BLANK | F18: Rho | G18: 0.2 | H18: 0.2 | I18: 0.2 | J18: 0.2 | K18: 0.2 | L18: 0.2 | M18: 0.2 | N18: 0.2 | R18: F | T18: BLANK | U18: Rho | V18: 2 | W18: 2 | X18: 2 | Y18: 2 | Z18: 2 | AA18: 2 | AB18: 2 | AC18: 2 | AI18: F | AK18: BLANK | AL18: Rho | AM18: 0.2 | AN18: 0.2 | AO18: 0.2 | AP18: 0.2 | AQ18: 0.2 | AR18: 0.2 | AS18: 0.2 | AT18: 0.2 | AX18: F | AZ18: BLANK | BA18: Rho | BB18: 2 | BC18: 2 | BD18: 2 | BE18: 2 | BF18: 2 | BG18: 2 | BH18: 2 | BI18: 2 | BO18: F | BQ18: BLANK | BR18: Rho | BS18: 0.2 | BT18: 0.2 | BU18: 0.2 | BV18: 0.2 | BW18: 0.2 | BX18: 0.2 | BY18: 0.2 | BZ18: 0.2 | CD18: F | CF18: BLANK | CG18: Rho | CH18: 2 | CI18: 2 | CJ18: 2 | CK18: 2 | CL18: 2 | CM18: 2 | CN18: 2 | CO18: 2 | CU18: F | CW18: BLANK | CX18: Rho | CY18: 0.2 | CZ18: 0.2 | DA18: 0.2 | DB18: 0.2 | DC18: 0.2 | DD18: 0.2 | DE18: 0.2 | DF18: 0.2 | DJ18: F | DL18: BLANK | DM18: Rho | DN18: 2 | DO18: 2 | DP18: 2 | DQ18: 2 | DR18: 2 | DS18: 2 | DT18: 2 | DU18: 2
C19: G | E19: BLANK | F19: Rho | G19: 0.3 | H19: 0.3 | I19: 0.3 | J19: 0.3 | K19: 0.3 | L19: 0.3 | M19: 0.3 | N19: 0.3 | R19: G | T19: BLANK | U19: Rho | V19: 5 | W19: 5 | X19: 5 | Y19: 5 | Z19: 5 | AA19: 5 | AB19: 5 | AC19: 5 | AI19: G | AK19: BLANK | AL19: Rho | AM19: 0.3 | AN19: 0.3 | AO19: 0.3 | AP19: 0.3 | AQ19: 0.3 | AR19: 0.3 | AS19: 0.3 | AT19: 0.3 | AX19: G | AZ19: BLANK | BA19: Rho | BB19: 5 | BC19: 5 | BD19: 5 | BE19: 5 | BF19: 5 | BG19: 5 | BH19: 5 | BI19: 5 | BO19: G | BQ19: BLANK | BR19: Rho | BS19: 0.3 | BT19: 0.3 | BU19: 0.3 | BV19: 0.3 | BW19: 0.3 | BX19: 0.3 | BY19: 0.3 | BZ19: 0.3 | CD19: G | CF19: BLANK | CG19: Rho | CH19: 5 | CI19: 5 | CJ19: 5 | CK19: 5 | CL19: 5 | CM19: 5 | CN19: 5 | CO19: 5 | CU19: G | CW19: BLANK | CX19: Rho | CY19: 0.3 | CZ19: 0.3 | DA19: 0.3 | DB19: 0.3 | DC19: 0.3 | DD19: 0.3 | DE19: 0.3 | DF19: 0.3 | DJ19: G | DL19: BLANK | DM19: Rho | DN19: 5 | DO19: 5 | DP19: 5 | DQ19: 5 | DR19: 5 | DS19: 5 | DT19: 5 | DU19: 5
C20: H | R20: H | AI20: H | AX20: H | BO20: H | CD20: H | CU20: H | DJ20: H
B22: Software Version | C22: 3.11.19 | R22: Software Version | S22: 3.11.19 | AH22: Software Version | AI22: 3.11.19 | AX22: Software Version | AY22: 3.11.19 | BN22: Software Version | BO22: 3.11.19 | CD22: Software Version | CE22: 3.11.19 | CT22: Software Version | CU22: 3.11.19 | DJ22: Software Version | DK22: 3.11.19
B24: Experiment File Path: | C24: C:\Users\labadmin\Documents\Biotek Reader\Experiments\MaxE\2025_01_STEM_Preparation_experiments\2025_01_22_d2_G418_plates_1.xpt | R24: Experiment File Path: | S24: C:\Users\labadmin\Documents\Biotek Reader\Experiments\MaxE\2025_01_STEM_Preparation_experiments\2025_01_22_d2_G418_plates_1.xpt | AH24: Experiment File Path: | AI24: C:\Users\labadmin\Documents\Biotek Reader\Experiments\MaxE\2025_01_STEM_Preparation_experiments\2025_01_24_d4_G418_plates_1.xpt | AX24: Experiment File Path: | AY24: C:\Users\labadmin\Documents\Biotek Reader\Experiments\MaxE\2025_01_STEM_Preparation_experiments\2025_01_24_d4_G418_plates_1.xpt | BN24: Experiment File Path: | BO24: C:\Users\labadmin\Documents\Biotek Reader\Experiments\MaxE\2025_01_STEM_Preparation_experiments\2025_01_27_d7_G418_plates_1.xpt | CD24: Experiment File Path: | CE24: C:\Users\labadmin\Documents\Biotek Reader\Experiments\MaxE\2025_01_STEM_Preparation_experiments\2025_01_27_d7_G418_plates_1.xpt | CT24: Experiment File Path: | CU24: C:\Users\labadmin\Documents\Biotek Reader\Experiments\MaxE\2025_01_STEM_Preparation_experiments\2025_01_29_d9_G418_plates_1.xpt | DJ24: Experiment File Path: | DK24: C:\Users\labadmin\Documents\Biotek Reader\Experiments\MaxE\2025_01_STEM_Preparation_experiments\2025_01_29_d9_G418_plates_1.xpt
B25: Protocol File Path: | C25: C:\Users\labadmin\Documents\Biotek Reader\Protocols\Max\2025_01_22_G418_plates\2025_01_22_d2_G418_plates.prt | R25: Protocol File Path: | S25: C:\Users\labadmin\Documents\Biotek Reader\Protocols\Max\2025_01_22_G418_plates\2025_01_22_d2_G418_plates.prt | AH25: Protocol File Path: | AI25: C:\Users\labadmin\Documents\Biotek Reader\Protocols\Max\2025_01_22_G418_plates\2025_01_22_d2_G418_plates.prt | AX25: Protocol File Path: | AY25: C:\Users\labadmin\Documents\Biotek Reader\Protocols\Max\2025_01_22_G418_plates\2025_01_22_d2_G418_plates.prt | BN25: Protocol File Path: | BO25: C:\Users\labadmin\Documents\Biotek Reader\Protocols\Max\2025_01_22_G418_plates\2025_01_22_d2_G418_plates.prt | CD25: Protocol File Path: | CE25: C:\Users\labadmin\Documents\Biotek Reader\Protocols\Max\2025_01_22_G418_plates\2025_01_22_d2_G418_plates.prt | CT25: Protocol File Path: | CU25: C:\Users\labadmin\Documents\Biotek Reader\Protocols\Max\2025_01_22_G418_plates\2025_01_22_d2_G418_plates.prt | DJ25: Protocol File Path: | DK25: C:\Users\labadmin\Documents\Biotek Reader\Protocols\Max\2025_01_22_G418_plates\2025_01_22_d2_G418_plates.prt
B26: Plate Number | C26: Plate 2 | R26: Plate Number | S26: Plate 5 | AH26: Plate Number | AI26: Plate 2 | AX26: Plate Number | AY26: Plate 5 | BN26: Plate Number | BO26: Plate 2 | CD26: Plate Number | CE26: Plate 5 | CT26: Plate Number | CU26: Plate 2 | DJ26: Plate Number | DK26: Plate 5
B27: Date | C27: 45679 | R27: Date | S27: 45679 | AH27: Date | AI27: 45681 | AX27: Date | AY27: 45681 | BN27: Date | BO27: 45684 | CD27: Date | CE27: 45684 | CT27: Date | CU27: 45686 | DJ27: Date | DK27: 45686
B28: Time | C28: 0.57274306 | R28: Time | S28: 0.5780787 | AH28: Time | AI28: 0.56819444 | AX28: Time | AY28: 0.57340278 | BN28: Time | BO28: 0.58174769 | CD28: Time | CE28: 0.58708333 | CT28: Time | CU28: 0.58077546 | DJ28: Time | DK28: 0.58528935
B29: Reader Type: | C29: Synergy H1 | R29: Reader Type: | S29: Synergy H1 | AH29: Reader Type: | AI29: Synergy H1 | AX29: Reader Type: | AY29: Synergy H1 | BN29: Reader Type: | BO29: Synergy H1 | CD29: Reader Type: | CE29: Synergy H1 | CT29: Reader Type: | CU29: Synergy H1 | DJ29: Reader Type: | DK29: Synergy H1
B30: Reader Serial Number: | C30: 191202E | R30: Reader Serial Number: | S30: 191202E | AH30: Reader Serial Number: | AI30: 191202E | AX30: Reader Serial Number: | AY30: 191202E | BN30: Reader Serial Number: | BO30: 191202E | CD30: Reader Serial Number: | CE30: 191202E | CT30: Reader Serial Number: | CU30: 191202E | DJ30: Reader Serial Number: | DK30: 191202E
B31: Reading Type | C31: Reader | R31: Reading Type | S31: Reader | AH31: Reading Type | AI31: Reader | AX31: Reading Type | AY31: Reader | BN31: Reading Type | BO31: Reader | CD31: Reading Type | CE31: Reader | CT31: Reading Type | CU31: Reader | DJ31: Reading Type | DK31: Reader
AX32: Plate Type | AY32: 96 WELL PLATE
B33: Procedure Details | R33: Procedure Details | AH33: Procedure Details | AX33: Eject plate on completion | BN33: Procedure Details | CD33: Procedure Details | CT33: Procedure Details | DJ33: Procedure Details
B34: Plate Type | C34: 96 WELL PLATE | R34: Plate Type | S34: 96 WELL PLATE | AH34: Plate Type | AI34: 96 WELL PLATE | AX34: Set Temperature | AY34: Setpoint 37Â°C | BN34: Plate Type | BO34: 96 WELL PLATE | CD34: Plate Type | CE34: 96 WELL PLATE | CT34: Plate Type | CU34: 96 WELL PLATE | DJ34: Plate Type | DK34: 96 WELL PLATE
B35: Eject plate on completion | R35: Eject plate on completion | AH35: Eject plate on completion | AY35: Preheat before moving to next step | BN35: Eject plate on completion | CD35: Eject plate on completion | CT35: Eject plate on completion | DJ35: Eject plate on completion
B36: Set Temperature | C36: Setpoint 37Â°C | R36: Set Temperature | S36: Setpoint 37Â°C | AH36: Set Temperature | AI36: Setpoint 37Â°C | AX36: Read | AY36: Resazurin | BN36: Set Temperature | BO36: Setpoint 37Â°C | CD36: Set Temperature | CE36: Setpoint 37Â°C | CT36: Set Temperature | CU36: Setpoint 37Â°C | DJ36: Set Temperature | DK36: Setpoint 37Â°C
C37: Preheat before moving to next step | S37: Preheat before moving to next step | AI37: Preheat before moving to next step | AY37: Fluorescence Endpoint | BO37: Preheat before moving to next step | CE37: Preheat before moving to next step | CU37: Preheat before moving to next step | DK37: Preheat before moving to next step
B38: Read | C38: Resazurin | R38: Read | S38: Resazurin | AH38: Read | AI38: Resazurin | AY38: Full Plate | BN38: Read | BO38: Resazurin | CD38: Read | CE38: Resazurin | CT38: Read | CU38: Resazurin | DJ38: Read | DK38: Resazurin
C39: Fluorescence Endpoint | S39: Fluorescence Endpoint | AI39: Fluorescence Endpoint | AY39: Filter Set 1 | BO39: Fluorescence Endpoint | CE39: Fluorescence Endpoint | CU39: Fluorescence Endpoint | DK39: Fluorescence Endpoint
C40: Full Plate | S40: Full Plate | AI40: Full Plate | AY40: Excitation: 554, Emission: 593 | BO40: Full Plate | CE40: Full Plate | CU40: Full Plate | DK40: Full Plate
C41: Filter Set 1 | S41: Filter Set 1 | AI41: Filter Set 1 | AY41: Optics: Bottom, Gain: 100 | BO41: Filter Set 1 | CE41: Filter Set 1 | CU41: Filter Set 1 | DK41: Filter Set 1
C42: Excitation: 554, Emission: 593 | S42: Excitation: 554, Emission: 593 | AI42: Excitation: 554, Emission: 593 | AY42: Light Source: Xenon Flash, Lamp Energy: High | BO42: Excitation: 554, Emission: 593 | CE42: Excitation: 554, Emission: 593 | CU42: Excitation: 554, Emission: 593 | DK42: Excitation: 554, Emission: 593
C43: Optics: Bottom, Gain: 100 | S43: Optics: Bottom, Gain: 100 | AI43: Optics: Bottom, Gain: 100 | AY43: Read Speed: Normal, Delay: 100 msec, Measurements/Data Point: 10 | BO43: Optics: Bottom, Gain: 100 | CE43: Optics: Bottom, Gain: 100 | CU43: Optics: Bottom, Gain: 100 | DK43: Optics: Bottom, Gain: 100
C44: Light Source: Xenon Flash, Lamp Energy: High | S44: Light Source: Xenon Flash, Lamp Energy: High | AI44: Light Source: Xenon Flash, Lamp Energy: High | AY44: Read Height: 7 mm | BO44: Light Source: Xenon Flash, Lamp Energy: High | CE44: Light Source: Xenon Flash, Lamp Energy: High | CU44: Light Source: Xenon Flash, Lamp Energy: High | DK44: Light Source: Xenon Flash, Lamp Energy: High
C45: Read Speed: Normal, Delay: 100 msec, Measurements/Data Point: 10 | S45: Read Speed: Normal, Delay: 100 msec, Measurements/Data Point: 10 | AI45: Read Speed: Normal, Delay: 100 msec, Measurements/Data Point: 10 | BO45: Read Speed: Normal, Delay: 100 msec, Measurements/Data Point: 10 | CE45: Read Speed: Normal, Delay: 100 msec, Measurements/Data Point: 10 | CU45: Read Speed: Normal, Delay: 100 msec, Measurements/Data Point: 10 | DK45: Read Speed: Normal, Delay: 100 msec, Measurements/Data Point: 10
...

Sheet G418 alpha-4
B2: Protokoll G418 Dose Response Curve
B4: 1. Seed 1000 cells in a 96 well plate on Monday (20.04.24)
C5: For a2
C6: For a3
C7: For a4
B8: 2. Add AlamarBlue on Tuesday morning
B9: 3. Wait 2h
B10: 4. Analyze in the plate reader
B12: 2025_01_22 | C12: a4 d2 | D12: 1 | E12: 2 | F12: 3 | G12: 4 | H12: 5 | I12: 6 | J12: 7 | K12: 8 | L12: 9 | M12: 10 | N12: 11 | O12: 12 | R12: a4 d2 | S12: 1 | T12: 2 | U12: 3 | V12: 4 | W12: 5 | X12: 6 | Y12: 7 | Z12: 8 | AA12: 9 | AB12: 10 | AC12: 11 | AD12: 12 | AH12: 2025_01_24 | AI12: a4 d2 | AJ12: 1 | AK12: 2 | AL12: 3 | AM12: 4 | AN12: 5 | AO12: 6 | AP12: 7 | AQ12: 8 | AR12: 9 | AS12: 10 | AT12: 11 | AU12: 12 | AX12: a4 d2 | AY12: 1 | AZ12: 2 | BA12: 3 | BB12: 4 | BC12: 5 | BD12: 6 | BE12: 7 | BF12: 8 | BG12: 9 | BH12: 10 | BI12: 11 | BJ12: 12 | BN12: 2025_01_27 | BO12: a4 d5 | BP12: 1 | BQ12: 2 | BR12: 3 | BS12: 4 | BT12: 5 | BU12: 6 | BV12: 7 | BW12: 8 | BX12: 9 | BY12: 10 | BZ12: 11 | CA12: 12 | CD12: a4 d5 | CE12: 1 | CF12: 2 | CG12: 3 | CH12: 4 | CI12: 5 | CJ12: 6 | CK12: 7 | CL12: 8 | CM12: 9 | CN12: 10 | CO12: 11 | CP12: 12 | CT12: 2025_01_29 | CU12: a4 d7 | CV12: 1 | CW12: 2 | CX12: 3 | CY12: 4 | CZ12: 5 | DA12: 6 | DB12: 7 | DC12: 8 | DD12: 9 | DE12: 10 | DF12: 11 | DG12: 12 | DJ12: a4 d7 | DK12: 1 | DL12: 2 | DM12: 3 | DN12: 4 | DO12: 5 | DP12: 6 | DQ12: 7 | DR12: 8 | DS12: 9 | DT12: 10 | DU12: 11 | DV12: 12
C13: A | R13: A | AI13: A | AX13: A | BO13: A | CD13: A | CU13: A | DJ13: A
C14: B | E14: BLANK | F14: Rho | G14: 0 | H14: 0 | I14: 0 | J14: 0 | K14: 0 | L14: 0 | M14: 0 | N14: 0 | R14: B | T14: BLANK | U14: Rho | V14: 0.4 | W14: 0.4 | X14: 0.4 | Y14: 0.4 | Z14: 0.4 | AA14: 0.4 | AB14: 0.4 | AC14: 0.4 | AI14: B | AK14: BLANK | AL14: Rho | AM14: 0 | AN14: 0 | AO14: 0 | AP14: 0 | AQ14: 0 | AR14: 0 | AS14: 0 | AT14: 0 | AX14: B | AZ14: BLANK | BA14: Rho | BB14: 0.4 | BC14: 0.4 | BD14: 0.4 | BE14: 0.4 | BF14: 0.4 | BG14: 0.4 | BH14: 0.4 | BI14: 0.4 | BO14: B | BQ14: BLANK | BR14: Rho | BS14: 0 | BT14: 0 | BU14: 0 | BV14: 0 | BW14: 0 | BX14: 0 | BY14: 0 | BZ14: 0 | CD14: B | CF14: BLANK | CG14: Rho | CH14: 0.4 | CI14: 0.4 | CJ14: 0.4 | CK14: 0.4 | CL14: 0.4 | CM14: 0.4 | CN14: 0.4 | CO14: 0.4 | CU14: B | CW14: BLANK | CX14: Rho | CY14: 0 | CZ14: 0 | DA14: 0 | DB14: 0 | DC14: 0 | DD14: 0 | DE14: 0 | DF14: 0 | DJ14: B | DL14: BLANK | DM14: Rho | DN14: 0.4 | DO14: 0.4 | DP14: 0.4 | DQ14: 0.4 | DR14: 0.4 | DS14: 0.4 | DT14: 0.4 | DU14: 0.4
C15: C | E15: BLANK | F15: Rho | G15: 0.025 | H15: 0.025 | I15: 0.025 | J15: 0.025 | K15: 0.025 | L15: 0.025 | M15: 0.025 | N15: 0.025 | R15: C | T15: BLANK | U15: Rho | V15: 0.6 | W15: 0.6 | X15: 0.6 | Y15: 0.6 | Z15: 0.6 | AA15: 0.6 | AB15: 0.6 | AC15: 0.6 | AI15: C | AK15: BLANK | AL15: Rho | AM15: 0.025 | AN15: 0.025 | AO15: 0.025 | AP15: 0.025 | AQ15: 0.025 | AR15: 0.025 | AS15: 0.025 | AT15: 0.025 | AX15: C | AZ15: BLANK | BA15: Rho | BB15: 0.6 | BC15: 0.6 | BD15: 0.6 | BE15: 0.6 | BF15: 0.6 | BG15: 0.6 | BH15: 0.6 | BI15: 0.6 | BO15: C | BQ15: BLANK | BR15: Rho | BS15: 0.025 | BT15: 0.025 | BU15: 0.025 | BV15: 0.025 | BW15: 0.025 | BX15: 0.025 | BY15: 0.025 | BZ15: 0.025 | CD15: C | CF15: BLANK | CG15: Rho | CH15: 0.6 | CI15: 0.6 | CJ15: 0.6 | CK15: 0.6 | CL15: 0.6 | CM15: 0.6 | CN15: 0.6 | CO15: 0.6 | CU15: C | CW15: BLANK | CX15: Rho | CY15: 0.025 | CZ15: 0.025 | DA15: 0.025 | DB15: 0.025 | DC15: 0.025 | DD15: 0.025 | DE15: 0.025 | DF15: 0.025 | DJ15: C | DL15: BLANK | DM15: Rho | DN15: 0.6 | DO15: 0.6 | DP15: 0.6 | DQ15: 0.6 | DR15: 0.6 | DS15: 0.6 | DT15: 0.6 | DU15: 0.6
C16: D | E16: BLANK | F16: Rho | G16: 0.05 | H16: 0.05 | I16: 0.05 | J16: 0.05 | K16: 0.05 | L16: 0.05 | M16: 0.05 | N16: 0.05 | R16: D | T16: BLANK | U16: Rho | V16: 0.8 | W16: 0.8 | X16: 0.8 | Y16: 0.8 | Z16: 0.8 | AA16: 0.8 | AB16: 0.8 | AC16: 0.8 | AI16: D | AK16: BLANK | AL16: Rho | AM16: 0.05 | AN16: 0.05 | AO16: 0.05 | AP16: 0.05 | AQ16: 0.05 | AR16: 0.05 | AS16: 0.05 | AT16: 0.05 | AX16: D | AZ16: BLANK | BA16: Rho | BB16: 0.8 | BC16: 0.8 | BD16: 0.8 | BE16: 0.8 | BF16: 0.8 | BG16: 0.8 | BH16: 0.8 | BI16: 0.8 | BO16: D | BQ16: BLANK | BR16: Rho | BS16: 0.05 | BT16: 0.05 | BU16: 0.05 | BV16: 0.05 | BW16: 0.05 | BX16: 0.05 | BY16: 0.05 | BZ16: 0.05 | CD16: D | CF16: BLANK | CG16: Rho | CH16: 0.8 | CI16: 0.8 | CJ16: 0.8 | CK16: 0.8 | CL16: 0.8 | CM16: 0.8 | CN16: 0.8 | CO16: 0.8 | CU16: D | CW16: BLANK | CX16: Rho | CY16: 0.05 | CZ16: 0.05 | DA16: 0.05 | DB16: 0.05 | DC16: 0.05 | DD16: 0.05 | DE16: 0.05 | DF16: 0.05 | DJ16: D | DL16: BLANK | DM16: Rho | DN16: 0.8 | DO16: 0.8 | DP16: 0.8 | DQ16: 0.8 | DR16: 0.8 | DS16: 0.8 | DT16: 0.8 | DU16: 0.8
C17: E | E17: BLANK | F17: Rho | G17: 0.1 | H17: 0.1 | I17: 0.1 | J17: 0.1 | K17: 0.1 | L17: 0.1 | M17: 0.1 | N17: 0.1 | R17: E | T17: BLANK | U17: Rho | V17: 1 | W17: 1 | X17: 1 | Y17: 1 | Z17: 1 | AA17: 1 | AB17: 1 | AC17: 1 | AI17: E | AK17: BLANK | AL17: Rho | AM17: 0.1 | AN17: 0.1 | AO17: 0.1 | AP17: 0.1 | AQ17: 0.1 | AR17: 0.1 | AS17: 0.1 | AT17: 0.1 | AX17: E | AZ17: BLANK | BA17: Rho | BB17: 1 | BC17: 1 | BD17: 1 | BE17: 1 | BF17: 1 | BG17: 1 | BH17: 1 | BI17: 1 | BO17: E | BQ17: BLANK | BR17: Rho | BS17: 0.1 | BT17: 0.1 | BU17: 0.1 | BV17: 0.1 | BW17: 0.1 | BX17: 0.1 | BY17: 0.1 | BZ17: 0.1 | CD17: E | CF17: BLANK | CG17: Rho | CH17: 1 | CI17: 1 | CJ17: 1 | CK17: 1 | CL17: 1 | CM17: 1 | CN17: 1 | CO17: 1 | CU17: E | CW17: BLANK | CX17: Rho | CY17: 0.1 | CZ17: 0.1 | DA17: 0.1 | DB17: 0.1 | DC17: 0.1 | DD17: 0.1 | DE17: 0.1 | DF17: 0.1 | DJ17: E | DL17: BLANK | DM17: Rho | DN17: 1 | DO17: 1 | DP17: 1 | DQ17: 1 | DR17: 1 | DS17: 1 | DT17: 1 | DU17: 1
C18: F | E18: BLANK | F18: Rho | G18: 0.2 | H18: 0.2 | I18: 0.2 | J18: 0.2 | K18: 0.2 | L18: 0.2 | M18: 0.2 | N18: 0.2 | R18: F | T18: BLANK | U18: Rho | V18: 2 | W18: 2 | X18: 2 | Y18: 2 | Z18: 2 | AA18: 2 | AB18: 2 | AC18: 2 | AI18: F | AK18: BLANK | AL18: Rho | AM18: 0.2 | AN18: 0.2 | AO18: 0.2 | AP18: 0.2 | AQ18: 0.2 | AR18: 0.2 | AS18: 0.2 | AT18: 0.2 | AX18: F | AZ18: BLANK | BA18: Rho | BB18: 2 | BC18: 2 | BD18: 2 | BE18: 2 | BF18: 2 | BG18: 2 | BH18: 2 | BI18: 2 | BO18: F | BQ18: BLANK | BR18: Rho | BS18: 0.2 | BT18: 0.2 | BU18: 0.2 | BV18: 0.2 | BW18: 0.2 | BX18: 0.2 | BY18: 0.2 | BZ18: 0.2 | CD18: F | CF18: BLANK | CG18: Rho | CH18: 2 | CI18: 2 | CJ18: 2 | CK18: 2 | CL18: 2 | CM18: 2 | CN18: 2 | CO18: 2 | CU18: F | CW18: BLANK | CX18: Rho | CY18: 0.2 | CZ18: 0.2 | DA18: 0.2 | DB18: 0.2 | DC18: 0.2 | DD18: 0.2 | DE18: 0.2 | DF18: 0.2 | DJ18: F | DL18: BLANK | DM18: Rho | DN18: 2 | DO18: 2 | DP18: 2 | DQ18: 2 | DR18: 2 | DS18: 2 | DT18: 2 | DU18: 2
C19: G | E19: BLANK | F19: Rho | G19: 0.3 | H19: 0.3 | I19: 0.3 | J19: 0.3 | K19: 0.3 | L19: 0.3 | M19: 0.3 | N19: 0.3 | R19: G | T19: BLANK | U19: Rho | V19: 5 | W19: 5 | X19: 5 | Y19: 5 | Z19: 5 | AA19: 5 | AB19: 5 | AC19: 5 | AI19: G | AK19: BLANK | AL19: Rho | AM19: 0.3 | AN19: 0.3 | AO19: 0.3 | AP19: 0.3 | AQ19: 0.3 | AR19: 0.3 | AS19: 0.3 | AT19: 0.3 | AX19: G | AZ19: BLANK | BA19: Rho | BB19: 5 | BC19: 5 | BD19: 5 | BE19: 5 | BF19: 5 | BG19: 5 | BH19: 5 | BI19: 5 | BO19: G | BQ19: BLANK | BR19: Rho | BS19: 0.3 | BT19: 0.3 | BU19: 0.3 | BV19: 0.3 | BW19: 0.3 | BX19: 0.3 | BY19: 0.3 | BZ19: 0.3 | CD19: G | CF19: BLANK | CG19: Rho | CH19: 5 | CI19: 5 | CJ19: 5 | CK19: 5 | CL19: 5 | CM19: 5 | CN19: 5 | CO19: 5 | CU19: G | CW19: BLANK | CX19: Rho | CY19: 0.3 | CZ19: 0.3 | DA19: 0.3 | DB19: 0.3 | DC19: 0.3 | DD19: 0.3 | DE19: 0.3 | DF19: 0.3 | DJ19: G | DL19: BLANK | DM19: Rho | DN19: 5 | DO19: 5 | DP19: 5 | DQ19: 5 | DR19: 5 | DS19: 5 | DT19: 5 | DU19: 5
C20: H | R20: H | AI20: H | AX20: H | BO20: H | CD20: H | CU20: H | DJ20: H
B22: Software Version | C22: 3.11.19 | R22: Software Version | S22: 3.11.19 | AH22: Software Version | AI22: 3.11.19 | AX22: Software Version | AY22: 3.11.19 | BN22: Software Version | BO22: 3.11.19 | CD22: Software Version | CE22: 3.11.19 | CT22: Software Version | CU22: 3.11.19 | DJ22: Software Version | DK22: 3.11.19
B24: Experiment File Path: | C24: C:\Users\labadmin\Documents\Biotek Reader\Experiments\MaxE\2025_01_STEM_Preparation_experiments\2025_01_22_d2_G418_plates_1.xpt | R24: Experiment File Path: | S24: C:\Users\labadmin\Documents\Biotek Reader\Experiments\MaxE\2025_01_STEM_Preparation_experiments\2025_01_22_d2_G418_plates_1.xpt | AH24: Experiment File Path: | AI24: C:\Users\labadmin\Documents\Biotek Reader\Experiments\MaxE\2025_01_STEM_Preparation_experiments\2025_01_24_d4_G418_plates_1.xpt | AX24: Experiment File Path: | AY24: C:\Users\labadmin\Documents\Biotek Reader\Experiments\MaxE\2025_01_STEM_Preparation_experiments\2025_01_24_d4_G418_plates_1.xpt | BN24: Experiment File Path: | BO24: C:\Users\labadmin\Documents\Biotek Reader\Experiments\MaxE\2025_01_STEM_Preparation_experiments\2025_01_27_d7_G418_plates_1.xpt | CD24: Experiment File Path: | CE24: C:\Users\labadmin\Documents\Biotek Reader\Experiments\MaxE\2025_01_STEM_Preparation_experiments\2025_01_27_d7_G418_plates_1.xpt | CT24: Experiment File Path: | CU24: C:\Users\labadmin\Documents\Biotek Reader\Experiments\MaxE\2025_01_STEM_Preparation_experiments\2025_01_29_d9_G418_plates_1.xpt | DJ24: Experiment File Path: | DK24: C:\Users\labadmin\Documents\Biotek Reader\Experiments\MaxE\2025_01_STEM_Preparation_experiments\2025_01_29_d9_G418_plates_1.xpt
B25: Protocol File Path: | C25: C:\Users\labadmin\Documents\Biotek Reader\Protocols\Max\2025_01_22_G418_plates\2025_01_22_d2_G418_plates.prt | R25: Protocol File Path: | S25: C:\Users\labadmin\Documents\Biotek Reader\Protocols\Max\2025_01_22_G418_plates\2025_01_22_d2_G418_plates.prt | AH25: Protocol File Path: | AI25: C:\Users\labadmin\Documents\Biotek Reader\Protocols\Max\2025_01_22_G418_plates\2025_01_22_d2_G418_plates.prt | AX25: Protocol File Path: | AY25: C:\Users\labadmin\Documents\Biotek Reader\Protocols\Max\2025_01_22_G418_plates\2025_01_22_d2_G418_plates.prt | BN25: Protocol File Path: | BO25: C:\Users\labadmin\Documents\Biotek Reader\Protocols\Max\2025_01_22_G418_plates\2025_01_22_d2_G418_plates.prt | CD25: Protocol File Path: | CE25: C:\Users\labadmin\Documents\Biotek Reader\Protocols\Max\2025_01_22_G418_plates\2025_01_22_d2_G418_plates.prt | CT25: Protocol File Path: | CU25: C:\Users\labadmin\Documents\Biotek Reader\Protocols\Max\2025_01_22_G418_plates\2025_01_22_d2_G418_plates.prt | DJ25: Protocol File Path: | DK25: C:\Users\labadmin\Documents\Biotek Reader\Protocols\Max\2025_01_22_G418_plates\2025_01_22_d2_G418_plates.prt
B26: Plate Number | C26: Plate 3 | R26: Plate Number | S26: Plate 6 | AH26: Plate Number | AI26: Plate 3 | AX26: Plate Number | AY26: Plate 6 | BN26: Plate Number | BO26: Plate 3 | CD26: Plate Number | CE26: Plate 6 | CT26: Plate Number | CU26: Plate 3 | DJ26: Plate Number | DK26: Plate 6
B27: Date | C27: 45679 | R27: Date | S27: 45679 | AH27: Date | AI27: 45681 | AX27: Date | AY27: 45681 | BN27: Date | BO27: 45684 | CD27: Date | CE27: 45684 | CT27: Date | CU27: 45686 | DJ27: Date | DK27: 45686
B28: Time | C28: 0.57559028 | R28: Time | S28: 0.58071759 | AH28: Time | AI28: 0.56971065 | AX28: Time | AY28: 0.57553241 | BN28: Time | BO28: 0.58328704 | CD28: Time | CE28: 0.58857639 | CT28: Time | CU28: 0.58226852 | DJ28: Time | DK28: 0.58679398
B29: Reader Type: | C29: Synergy H1 | R29: Reader Type: | S29: Synergy H1 | AH29: Reader Type: | AI29: Synergy H1 | AX29: Reader Type: | AY29: Synergy H1 | BN29: Reader Type: | BO29: Synergy H1 | CD29: Reader Type: | CE29: Synergy H1 | CT29: Reader Type: | CU29: Synergy H1 | DJ29: Reader Type: | DK29: Synergy H1
B30: Reader Serial Number: | C30: 191202E | R30: Reader Serial Number: | S30: 191202E | AH30: Reader Serial Number: | AI30: 191202E | AX30: Reader Serial Number: | AY30: 191202E | BN30: Reader Serial Number: | BO30: 191202E | CD30: Reader Serial Number: | CE30: 191202E | CT30: Reader Serial Number: | CU30: 191202E | DJ30: Reader Serial Number: | DK30: 191202E
B31: Reading Type | C31: Reader | R31: Reading Type | S31: Reader | AH31: Reading Type | AI31: Reader | AX31: Reading Type | AY31: Reader | BN31: Reading Type | BO31: Reader | CD31: Reading Type | CE31: Reader | CT31: Reading Type | CU31: Reader | DJ31: Reading Type | DK31: Reader
B33: Procedure Details | R33: Procedure Details | AH33: Procedure Details | AX33: Procedure Details | BN33: Procedure Details | CD33: Procedure Details | CT33: Procedure Details | DJ33: Procedure Details
B34: Plate Type | C34: 96 WELL PLATE | R34: Plate Type | S34: 96 WELL PLATE | AH34: Plate Type | AI34: 96 WELL PLATE | AX34: Plate Type | AY34: 96 WELL PLATE | BN34: Plate Type | BO34: 96 WELL PLATE | CD34: Plate Type | CE34: 96 WELL PLATE | CT34: Plate Type | CU34: 96 WELL PLATE | DJ34: Plate Type | DK34: 96 WELL PLATE
B35: Eject plate on completion | R35: Eject plate on completion | AH35: Eject plate on completion | AX35: Eject plate on completion | BN35: Eject plate on completion | CD35: Eject plate on completion | CT35: Eject plate on completion | DJ35: Eject plate on completion
B36: Set Temperature | C36: Setpoint 37Â°C | R36: Set Temperature | S36: Setpoint 37Â°C | AH36: Set Temperature | AI36: Setpoint 37Â°C | AX36: Set Temperature | AY36: Setpoint 37Â°C | BN36: Set Temperature | BO36: Setpoint 37Â°C | CD36: Set Temperature | CE36: Setpoint 37Â°C | CT36: Set Temperature | CU36: Setpoint 37Â°C | DJ36: Set Temperature | DK36: Setpoint 37Â°C
C37: Preheat before moving to next step | S37: Preheat before moving to next step | AI37: Preheat before moving to next step | AY37: Preheat before moving to next step | BO37: Preheat before moving to next step | CE37: Preheat before moving to next step | CU37: Preheat before moving to next step | DK37: Preheat before moving to next step
B38: Read | C38: Resazurin | R38: Read | S38: Resazurin | AH38: Read | AI38: Resazurin | AX38: Read | AY38: Resazurin | BN38: Read | BO38: Resazurin | CD38: Read | CE38: Resazurin | CT38: Read | CU38: Resazurin | DJ38: Read | DK38: Resazurin
C39: Fluorescence Endpoint | S39: Fluorescence Endpoint | AI39: Fluorescence Endpoint | AY39: Fluorescence Endpoint | BO39: Fluorescence Endpoint | CE39: Fluorescence Endpoint | CU39: Fluorescence Endpoint | DK39: Fluorescence Endpoint
C40: Full Plate | S40: Full Plate | AI40: Full Plate | AY40: Full Plate | BO40: Full Plate | CE40: Full Plate | CU40: Full Plate | DK40: Full Plate
C41: Filter Set 1 | S41: Filter Set 1 | AI41: Filter Set 1 | AY41: Filter Set 1 | BO41: Filter Set 1 | CE41: Filter Set 1 | CU41: Filter Set 1 | DK41: Filter Set 1
C42: Excitation: 554, Emission: 593 | S42: Excitation: 554, Emission: 593 | AI42: Excitation: 554, Emission: 593 | AY42: Excitation: 554, Emission: 593 | BO42: Excitation: 554, Emission: 593 | CE42: Excitation: 554, Emission: 593 | CU42: Excitation: 554, Emission: 593 | DK42: Excitation: 554, Emission: 593
C43: Optics: Bottom, Gain: 100 | S43: Optics: Bottom, Gain: 100 | AI43: Optics: Bottom, Gain: 100 | AY43: Optics: Bottom, Gain: 100 | BO43: Optics: Bottom, Gain: 100 | CE43: Optics: Bottom, Gain: 100 | CU43: Optics: Bottom, Gain: 100 | DK43: Optics: Bottom, Gain: 100
C44: Light Source: Xenon Flash, Lamp Energy: High | S44: Light Source: Xenon Flash, Lamp Energy: High | AI44: Light Source: Xenon Flash, Lamp Energy: High | AY44: Light Source: Xenon Flash, Lamp Energy: High | BO44: Light Source: Xenon Flash, Lamp Energy: High | CE44: Light Source: Xenon Flash, Lamp Energy: High | CU44: Light Source: Xenon Flash, Lamp Energy: High | DK44: Light Source: Xenon Flash, Lamp Energy: High
C45: Read Speed: Normal, Delay: 100 msec, Measurements/Data Point: 10 | S45: Read Speed: Normal, Delay: 100 msec, Measurements/Data Point: 10 | AI45: Read Speed: Normal, Delay: 100 msec, Measurements/Data Point: 10 | AY45: Read Speed: Normal, Delay: 100 msec, Measurements/Data Point: 10 | BO45: Read Speed: Normal, Delay: 100 msec, Measurements/Data Point: 10 | CE45: Read Speed: Normal, Delay: 100 msec, Measurements/Data Point: 10 | CU45: Read Speed: Normal, Delay: 100 msec, Measurements/Data Point: 10 | DK45: Read Speed: Normal, Delay: 100 msec, Measurements/Data Point: 10
C46: Read Height: 7 mm | S46: Read Height: 7 mm | AI46: Read Height: 7 mm | AY46: Read Height: 7 mm | BO46: Read Height: 7 mm | CE46: Read Height: 7 mm | CU46: Read Height: 7 mm | DK46: Read Height: 7 mm
...

Sheet HygB alpha-3
B2: Protokoll G418 Dose Response Curve
B4: 1. Seed 1000 cells in a 96 well plate on Monday (20.04.24)
C5: For a2
C6: For a3
C7: For a4
B8: 2. Add AlamarBlue on Tuesday morning
B9: 3. Wait 2h
B10: 4. Analyze in the plate reader
B12: 2025_01_22 | C12: a3 d2 | D12: 1 | E12: 2 | F12: 3 | G12: 4 | H12: 5 | I12: 6 | J12: 7 | K12: 8 | L12: 9 | M12: 10 | N12: 11 | O12: 12 | R12: 2025_01_24 | S12: a3 d2 | T12: 1 | U12: 2 | V12: 3 | W12: 4 | X12: 5 | Y12: 6 | Z12: 7 | AA12: 8 | AB12: 9 | AC12: 10 | AD12: 11 | AE12: 12 | AH12: 2025_01_27 | AI12: a3 d5 | AJ12: 1 | AK12: 2 | AL12: 3 | AM12: 4 | AN12: 5 | AO12: 6 | AP12: 7 | AQ12: 8 | AR12: 9 | AS12: 10 | AT12: 11 | AU12: 12 | AX12: 2025_01_29 | AY12: a3 d7 | AZ12: 1 | BA12: 2 | BB12: 3 | BC12: 4 | BD12: 5 | BE12: 6 | BF12: 7 | BG12: 8 | BH12: 9 | BI12: 10 | BJ12: 11 | BK12: 12
C13: A | S13: A | AI13: A | AY13: A
C14: B | E14: BLANK | F14: BLANK | G14: BLANK | H14: BLANK | I14: BLANK | J14: Rho | K14: Rho | L14: Rho | M14: Rho | N14: Rho | S14: B | U14: BLANK | V14: BLANK | W14: BLANK | X14: BLANK | Y14: BLANK | Z14: Rho | AA14: Rho | AB14: Rho | AC14: Rho | AD14: Rho | AI14: B | AK14: BLANK | AL14: BLANK | AM14: BLANK | AN14: BLANK | AO14: BLANK | AP14: Rho | AQ14: Rho | AR14: Rho | AS14: Rho | AT14: Rho | AY14: B | BA14: BLANK | BB14: BLANK | BC14: BLANK | BD14: BLANK | BE14: BLANK | BF14: Rho | BG14: Rho | BH14: Rho | BI14: Rho | BJ14: Rho
C15: C | E15: 0 | F15: 0 | G15: 0 | H15: 0 | I15: 0 | J15: 0 | K15: 0 | L15: 0 | M15: 0 | N15: 0 | S15: C | U15: 0 | V15: 0 | W15: 0 | X15: 0 | Y15: 0 | Z15: 0 | AA15: 0 | AB15: 0 | AC15: 0 | AD15: 0 | AI15: C | AK15: 0 | AL15: 0 | AM15: 0 | AN15: 0 | AO15: 0 | AP15: 0 | AQ15: 0 | AR15: 0 | AS15: 0 | AT15: 0 | AY15: C | BA15: 0 | BB15: 0 | BC15: 0 | BD15: 0 | BE15: 0 | BF15: 0 | BG15: 0 | BH15: 0 | BI15: 0 | BJ15: 0
C16: D | E16: 8 | F16: 8 | G16: 8 | H16: 8 | I16: 8 | J16: 8 | K16: 8 | L16: 8 | M16: 8 | N16: 8 | S16: D | U16: 8 | V16: 8 | W16: 8 | X16: 8 | Y16: 8 | Z16: 8 | AA16: 8 | AB16: 8 | AC16: 8 | AD16: 8 | AI16: D | AK16: 8 | AL16: 8 | AM16: 8 | AN16: 8 | AO16: 8 | AP16: 8 | AQ16: 8 | AR16: 8 | AS16: 8 | AT16: 8 | AY16: D | BA16: 8 | BB16: 8 | BC16: 8 | BD16: 8 | BE16: 8 | BF16: 8 | BG16: 8 | BH16: 8 | BI16: 8 | BJ16: 8
C17: E | E17: 16 | F17: 16 | G17: 16 | H17: 16 | I17: 16 | J17: 16 | K17: 16 | L17: 16 | M17: 16 | N17: 16 | S17: E | U17: 16 | V17: 16 | W17: 16 | X17: 16 | Y17: 16 | Z17: 16 | AA17: 16 | AB17: 16 | AC17: 16 | AD17: 16 | AI17: E | AK17: 16 | AL17: 16 | AM17: 16 | AN17: 16 | AO17: 16 | AP17: 16 | AQ17: 16 | AR17: 16 | AS17: 16 | AT17: 16 | AY17: E | BA17: 16 | BB17: 16 | BC17: 16 | BD17: 16 | BE17: 16 | BF17: 16 | BG17: 16 | BH17: 16 | BI17: 16 | BJ17: 16
C18: F | E18: 32 | F18: 32 | G18: 32 | H18: 32 | I18: 32 | J18: 32 | K18: 32 | L18: 32 | M18: 32 | N18: 32 | S18: F | U18: 32 | V18: 32 | W18: 32 | X18: 32 | Y18: 32 | Z18: 32 | AA18: 32 | AB18: 32 | AC18: 32 | AD18: 32 | AI18: F | AK18: 32 | AL18: 32 | AM18: 32 | AN18: 32 | AO18: 32 | AP18: 32 | AQ18: 32 | AR18: 32 | AS18: 32 | AT18: 32 | AY18: F | BA18: 32 | BB18: 32 | BC18: 32 | BD18: 32 | BE18: 32 | BF18: 32 | BG18: 32 | BH18: 32 | BI18: 32 | BJ18: 32
